[2025-07-18T18:38:01.329+0000] {local_task_job_runner.py:123} INFO - ::group::Pre task execution logs
[2025-07-18T18:38:02.435+0000] {taskinstance.py:2614} INFO - Dependencies all met for dep_context=non-requeueable deps ti=<TaskInstance: bank_reviews_etl_and_analysis_pipeline.scrape_and_insert_data_to_json manual__2025-07-18T18:31:24.384829+00:00 [queued]>
[2025-07-18T18:38:02.527+0000] {taskinstance.py:2614} INFO - Dependencies all met for dep_context=requeueable deps ti=<TaskInstance: bank_reviews_etl_and_analysis_pipeline.scrape_and_insert_data_to_json manual__2025-07-18T18:31:24.384829+00:00 [queued]>
[2025-07-18T18:38:02.563+0000] {taskinstance.py:2867} INFO - Starting attempt 2 of 2
[2025-07-18T18:38:02.733+0000] {taskinstance.py:2890} INFO - Executing <Task(PythonOperator): scrape_and_insert_data_to_json> on 2025-07-18 18:31:24.384829+00:00
[2025-07-18T18:38:02.829+0000] {standard_task_runner.py:72} INFO - Started process 76 to run task
[2025-07-18T18:38:03.064+0000] {standard_task_runner.py:104} INFO - Running: ['***', 'tasks', 'run', 'bank_reviews_etl_and_analysis_pipeline', 'scrape_and_insert_data_to_json', 'manual__2025-07-18T18:31:24.384829+00:00', '--job-id', '124', '--raw', '--subdir', 'DAGS_FOLDER/dag_load_reviews.py', '--cfg-path', '/tmp/tmptcgbjbig']
[2025-07-18T18:38:03.077+0000] {standard_task_runner.py:105} INFO - Job 124: Subtask scrape_and_insert_data_to_json
[2025-07-18T18:38:05.208+0000] {task_command.py:467} INFO - Running <TaskInstance: bank_reviews_etl_and_analysis_pipeline.scrape_and_insert_data_to_json manual__2025-07-18T18:31:24.384829+00:00 [running]> on host 569ba507bc01
[2025-07-18T18:38:05.930+0000] {taskinstance.py:3134} INFO - Exporting env vars: AIRFLOW_CTX_DAG_OWNER='mohammed' AIRFLOW_CTX_DAG_ID='bank_reviews_etl_and_analysis_pipeline' AIRFLOW_CTX_TASK_ID='scrape_and_insert_data_to_json' AIRFLOW_CTX_EXECUTION_DATE='2025-07-18T18:31:24.384829+00:00' AIRFLOW_CTX_TRY_NUMBER='2' AIRFLOW_CTX_DAG_RUN_ID='manual__2025-07-18T18:31:24.384829+00:00'
[2025-07-18T18:38:05.944+0000] {logging_mixin.py:190} INFO - Task instance is in running state
[2025-07-18T18:38:05.946+0000] {logging_mixin.py:190} INFO -  Previous state of the Task instance: queued
[2025-07-18T18:38:05.950+0000] {logging_mixin.py:190} INFO - Current task name:scrape_and_insert_data_to_json state:running start_date:2025-07-18 18:38:02.450662+00:00
[2025-07-18T18:38:05.953+0000] {logging_mixin.py:190} INFO - Dag name:bank_reviews_etl_and_analysis_pipeline and current dag run status:running
[2025-07-18T18:38:05.957+0000] {taskinstance.py:732} INFO - ::endgroup::
[2025-07-18T18:38:05.964+0000] {logger.py:11} INFO - ====== WebDriver manager ======
[2025-07-18T18:38:07.058+0000] {logger.py:11} INFO - Get LATEST chromedriver version for google-chrome
[2025-07-18T18:38:08.257+0000] {logger.py:11} INFO - Get LATEST chromedriver version for google-chrome
[2025-07-18T18:38:08.617+0000] {logger.py:11} INFO - Get LATEST chromedriver version for google-chrome
[2025-07-18T18:38:10.844+0000] {logger.py:11} INFO - WebDriver version 138.0.7204.157 selected
[2025-07-18T18:38:10.855+0000] {logger.py:11} INFO - Modern chrome version https://storage.googleapis.com/chrome-for-testing-public/138.0.7204.157/linux64/chromedriver-linux64.zip
[2025-07-18T18:38:10.857+0000] {logger.py:11} INFO - About to download new driver from https://storage.googleapis.com/chrome-for-testing-public/138.0.7204.157/linux64/chromedriver-linux64.zip
[2025-07-18T18:38:11.176+0000] {logger.py:11} INFO - Driver downloading response is 200
[2025-07-18T18:38:24.888+0000] {logger.py:11} INFO - Get LATEST chromedriver version for google-chrome
[2025-07-18T18:38:28.958+0000] {logger.py:11} INFO - Driver has been saved in cache [/home/***/.wdm/drivers/chromedriver/linux64/138.0.7204.157]
[2025-07-18T18:38:50.980+0000] {scraper_banks.py:269} INFO - 
üìç Initialisation pour Casablanca...
[2025-07-18T18:39:38.998+0000] {job.py:239} ERROR - Job heartbeat failed with error
Traceback (most recent call last):
  File "/home/airflow/.local/lib/python3.11/site-packages/sqlalchemy/engine/base.py", line 3371, in _wrap_pool_connect
    return fn()
           ^^^^
  File "/home/airflow/.local/lib/python3.11/site-packages/sqlalchemy/pool/base.py", line 327, in connect
    return _ConnectionFairy._checkout(self)
           ^^^^^^^^^^^^^^^^^^^^^^^^^^^^^^^^
  File "/home/airflow/.local/lib/python3.11/site-packages/sqlalchemy/pool/base.py", line 894, in _checkout
    fairy = _ConnectionRecord.checkout(pool)
            ^^^^^^^^^^^^^^^^^^^^^^^^^^^^^^^^
  File "/home/airflow/.local/lib/python3.11/site-packages/sqlalchemy/pool/base.py", line 493, in checkout
    rec = pool._do_get()
          ^^^^^^^^^^^^^^
  File "/home/airflow/.local/lib/python3.11/site-packages/sqlalchemy/pool/impl.py", line 256, in _do_get
    return self._create_connection()
           ^^^^^^^^^^^^^^^^^^^^^^^^^
  File "/home/airflow/.local/lib/python3.11/site-packages/sqlalchemy/pool/base.py", line 273, in _create_connection
    return _ConnectionRecord(self)
           ^^^^^^^^^^^^^^^^^^^^^^^
  File "/home/airflow/.local/lib/python3.11/site-packages/sqlalchemy/pool/base.py", line 388, in __init__
    self.__connect()
  File "/home/airflow/.local/lib/python3.11/site-packages/sqlalchemy/pool/base.py", line 690, in __connect
    with util.safe_reraise():
  File "/home/airflow/.local/lib/python3.11/site-packages/sqlalchemy/util/langhelpers.py", line 70, in __exit__
    compat.raise_(
  File "/home/airflow/.local/lib/python3.11/site-packages/sqlalchemy/util/compat.py", line 211, in raise_
    raise exception
  File "/home/airflow/.local/lib/python3.11/site-packages/sqlalchemy/pool/base.py", line 686, in __connect
    self.dbapi_connection = connection = pool._invoke_creator(self)
                                         ^^^^^^^^^^^^^^^^^^^^^^^^^^
  File "/home/airflow/.local/lib/python3.11/site-packages/sqlalchemy/engine/create.py", line 574, in connect
    return dialect.connect(*cargs, **cparams)
           ^^^^^^^^^^^^^^^^^^^^^^^^^^^^^^^^^^
  File "/home/airflow/.local/lib/python3.11/site-packages/sqlalchemy/engine/default.py", line 598, in connect
    return self.dbapi.connect(*cargs, **cparams)
           ^^^^^^^^^^^^^^^^^^^^^^^^^^^^^^^^^^^^^
  File "/home/airflow/venv/lib/python3.11/site-packages/psycopg2/__init__.py", line 122, in connect
    conn = _connect(dsn, connection_factory=connection_factory, **kwasync)
           ^^^^^^^^^^^^^^^^^^^^^^^^^^^^^^^^^^^^^^^^^^^^^^^^^^^^^^^^^^^^^^^
psycopg2.OperationalError: could not translate host name "postgres" to address: Temporary failure in name resolution


The above exception was the direct cause of the following exception:

Traceback (most recent call last):
  File "/home/airflow/.local/lib/python3.11/site-packages/airflow/jobs/job.py", line 207, in heartbeat
    self._merge_from(Job._fetch_from_db(self, session))
                     ^^^^^^^^^^^^^^^^^^^^^^^^^^^^^^^^^
  File "/home/airflow/.local/lib/python3.11/site-packages/airflow/api_internal/internal_api_call.py", line 166, in wrapper
    return func(*args, **kwargs)
           ^^^^^^^^^^^^^^^^^^^^^
  File "/home/airflow/.local/lib/python3.11/site-packages/airflow/utils/session.py", line 94, in wrapper
    return func(*args, **kwargs)
           ^^^^^^^^^^^^^^^^^^^^^
  File "/home/airflow/.local/lib/python3.11/site-packages/airflow/utils/retries.py", line 93, in wrapped_function
    for attempt in run_with_db_retries(max_retries=retries, logger=logger, **retry_kwargs):
  File "/home/airflow/.local/lib/python3.11/site-packages/tenacity/__init__.py", line 443, in __iter__
    do = self.iter(retry_state=retry_state)
         ^^^^^^^^^^^^^^^^^^^^^^^^^^^^^^^^^^
  File "/home/airflow/.local/lib/python3.11/site-packages/tenacity/__init__.py", line 376, in iter
    result = action(retry_state)
             ^^^^^^^^^^^^^^^^^^^
  File "/home/airflow/.local/lib/python3.11/site-packages/tenacity/__init__.py", line 418, in exc_check
    raise retry_exc.reraise()
          ^^^^^^^^^^^^^^^^^^^
  File "/home/airflow/.local/lib/python3.11/site-packages/tenacity/__init__.py", line 185, in reraise
    raise self.last_attempt.result()
          ^^^^^^^^^^^^^^^^^^^^^^^^^^
  File "/usr/local/lib/python3.11/concurrent/futures/_base.py", line 449, in result
    return self.__get_result()
           ^^^^^^^^^^^^^^^^^^^
  File "/usr/local/lib/python3.11/concurrent/futures/_base.py", line 401, in __get_result
    raise self._exception
  File "/home/airflow/.local/lib/python3.11/site-packages/airflow/utils/retries.py", line 102, in wrapped_function
    return func(*args, **kwargs)
           ^^^^^^^^^^^^^^^^^^^^^
  File "/home/airflow/.local/lib/python3.11/site-packages/airflow/jobs/job.py", line 335, in _fetch_from_db
    session.merge(job)
  File "/home/airflow/.local/lib/python3.11/site-packages/sqlalchemy/orm/session.py", line 3056, in merge
    return self._merge(
           ^^^^^^^^^^^^
  File "/home/airflow/.local/lib/python3.11/site-packages/sqlalchemy/orm/session.py", line 3136, in _merge
    merged = self.get(
             ^^^^^^^^^
  File "/home/airflow/.local/lib/python3.11/site-packages/sqlalchemy/orm/session.py", line 2853, in get
    return self._get_impl(
           ^^^^^^^^^^^^^^^
  File "/home/airflow/.local/lib/python3.11/site-packages/sqlalchemy/orm/session.py", line 2975, in _get_impl
    return db_load_fn(
           ^^^^^^^^^^^
  File "/home/airflow/.local/lib/python3.11/site-packages/sqlalchemy/orm/loading.py", line 530, in load_on_pk_identity
    session.execute(
  File "/home/airflow/.local/lib/python3.11/site-packages/sqlalchemy/orm/session.py", line 1716, in execute
    conn = self._connection_for_bind(bind)
           ^^^^^^^^^^^^^^^^^^^^^^^^^^^^^^^
  File "/home/airflow/.local/lib/python3.11/site-packages/sqlalchemy/orm/session.py", line 1555, in _connection_for_bind
    return self._transaction._connection_for_bind(
           ^^^^^^^^^^^^^^^^^^^^^^^^^^^^^^^^^^^^^^^
  File "/home/airflow/.local/lib/python3.11/site-packages/sqlalchemy/orm/session.py", line 750, in _connection_for_bind
    conn = bind.connect()
           ^^^^^^^^^^^^^^
  File "/home/airflow/.local/lib/python3.11/site-packages/sqlalchemy/future/engine.py", line 412, in connect
    return super(Engine, self).connect()
           ^^^^^^^^^^^^^^^^^^^^^^^^^^^^^
  File "/home/airflow/.local/lib/python3.11/site-packages/sqlalchemy/engine/base.py", line 3325, in connect
    return self._connection_cls(self, close_with_result=close_with_result)
           ^^^^^^^^^^^^^^^^^^^^^^^^^^^^^^^^^^^^^^^^^^^^^^^^^^^^^^^^^^^^^^^
  File "/home/airflow/.local/lib/python3.11/site-packages/sqlalchemy/engine/base.py", line 96, in __init__
    else engine.raw_connection()
         ^^^^^^^^^^^^^^^^^^^^^^^
  File "/home/airflow/.local/lib/python3.11/site-packages/sqlalchemy/engine/base.py", line 3404, in raw_connection
    return self._wrap_pool_connect(self.pool.connect, _connection)
           ^^^^^^^^^^^^^^^^^^^^^^^^^^^^^^^^^^^^^^^^^^^^^^^^^^^^^^^
  File "/home/airflow/.local/lib/python3.11/site-packages/sqlalchemy/engine/base.py", line 3374, in _wrap_pool_connect
    Connection._handle_dbapi_exception_noconnection(
  File "/home/airflow/.local/lib/python3.11/site-packages/sqlalchemy/engine/base.py", line 2208, in _handle_dbapi_exception_noconnection
    util.raise_(
  File "/home/airflow/.local/lib/python3.11/site-packages/sqlalchemy/util/compat.py", line 211, in raise_
    raise exception
  File "/home/airflow/.local/lib/python3.11/site-packages/sqlalchemy/engine/base.py", line 3371, in _wrap_pool_connect
    return fn()
           ^^^^
  File "/home/airflow/.local/lib/python3.11/site-packages/sqlalchemy/pool/base.py", line 327, in connect
    return _ConnectionFairy._checkout(self)
           ^^^^^^^^^^^^^^^^^^^^^^^^^^^^^^^^
  File "/home/airflow/.local/lib/python3.11/site-packages/sqlalchemy/pool/base.py", line 894, in _checkout
    fairy = _ConnectionRecord.checkout(pool)
            ^^^^^^^^^^^^^^^^^^^^^^^^^^^^^^^^
  File "/home/airflow/.local/lib/python3.11/site-packages/sqlalchemy/pool/base.py", line 493, in checkout
    rec = pool._do_get()
          ^^^^^^^^^^^^^^
  File "/home/airflow/.local/lib/python3.11/site-packages/sqlalchemy/pool/impl.py", line 256, in _do_get
    return self._create_connection()
           ^^^^^^^^^^^^^^^^^^^^^^^^^
  File "/home/airflow/.local/lib/python3.11/site-packages/sqlalchemy/pool/base.py", line 273, in _create_connection
    return _ConnectionRecord(self)
           ^^^^^^^^^^^^^^^^^^^^^^^
  File "/home/airflow/.local/lib/python3.11/site-packages/sqlalchemy/pool/base.py", line 388, in __init__
    self.__connect()
  File "/home/airflow/.local/lib/python3.11/site-packages/sqlalchemy/pool/base.py", line 690, in __connect
    with util.safe_reraise():
  File "/home/airflow/.local/lib/python3.11/site-packages/sqlalchemy/util/langhelpers.py", line 70, in __exit__
    compat.raise_(
  File "/home/airflow/.local/lib/python3.11/site-packages/sqlalchemy/util/compat.py", line 211, in raise_
    raise exception
  File "/home/airflow/.local/lib/python3.11/site-packages/sqlalchemy/pool/base.py", line 686, in __connect
    self.dbapi_connection = connection = pool._invoke_creator(self)
                                         ^^^^^^^^^^^^^^^^^^^^^^^^^^
  File "/home/airflow/.local/lib/python3.11/site-packages/sqlalchemy/engine/create.py", line 574, in connect
    return dialect.connect(*cargs, **cparams)
           ^^^^^^^^^^^^^^^^^^^^^^^^^^^^^^^^^^
  File "/home/airflow/.local/lib/python3.11/site-packages/sqlalchemy/engine/default.py", line 598, in connect
    return self.dbapi.connect(*cargs, **cparams)
           ^^^^^^^^^^^^^^^^^^^^^^^^^^^^^^^^^^^^^
  File "/home/airflow/venv/lib/python3.11/site-packages/psycopg2/__init__.py", line 122, in connect
    conn = _connect(dsn, connection_factory=connection_factory, **kwasync)
           ^^^^^^^^^^^^^^^^^^^^^^^^^^^^^^^^^^^^^^^^^^^^^^^^^^^^^^^^^^^^^^^
sqlalchemy.exc.OperationalError: (psycopg2.OperationalError) could not translate host name "postgres" to address: Temporary failure in name resolution

(Background on this error at: https://sqlalche.me/e/14/e3q8)
[2025-07-18T18:39:39.239+0000] {job.py:254} ERROR - Job heartbeat failed with error. Scheduler is in unhealthy state
[2025-07-18T18:39:44.639+0000] {job.py:229} INFO - Heartbeat recovered after 42.53 seconds
[2025-07-18T18:42:32.197+0000] {scraper_banks.py:198} INFO - ‚úÖ Fin du scrolling
[2025-07-18T18:42:33.419+0000] {scraper_banks.py:289} INFO - [Casablanca] 120 r√©sultats trouv√©s
[2025-07-18T18:42:34.866+0000] {scraper_banks.py:370} INFO - ‚úÖ BANK OF AFRICA (agence Bank of Africa J95G+6MR Bd Sidi Mohamed Ben Abdellah)
[2025-07-18T18:42:36.077+0000] {scraper_banks.py:370} INFO - ‚úÖ Bank Al Maghrib (agence Al Barid Bank 115 Bd de Paris)
[2025-07-18T18:42:37.032+0000] {scraper_banks.py:370} INFO - ‚úÖ Banque Populaire Moulay Driss 1er (agence Banque Populaire 108 bd Moulay Idriss 1er ang rue Ibn Jaljal)
[2025-07-18T18:42:38.499+0000] {scraper_banks.py:370} INFO - ‚úÖ Banque Populaire El Khatabi (agence Banque Populaire 2 Avenue Moulay Rachid Casablanca)
[2025-07-18T18:42:39.633+0000] {scraper_banks.py:370} INFO - ‚úÖ Banque Populaire El Fida (agence Banque Populaire Bd El Fida)
[2025-07-18T18:42:41.083+0000] {scraper_banks.py:370} INFO - ‚úÖ Si√®ge Social Banque Soci√©t√© G√©n√©rale (agence Soci√©t√© G√©n√©rale Banque Offshore 55 Bd Abdelmoumen)
[2025-07-18T18:42:42.615+0000] {scraper_banks.py:370} INFO - ‚úÖ Arab Bank Plc (agence Arab Bank Maroc 174 Bd Mohammed V)
[2025-07-18T18:42:43.825+0000] {scraper_banks.py:370} INFO - ‚úÖ Banque Centrale Populaire (agence Banque Populaire 101 Bd Mohammed Zerktouni)
[2025-07-18T18:42:44.431+0000] {scraper_banks.py:370} INFO - ‚úÖ Banque Populaire (agence Banque Populaire H9PW+W6G Bd de la R√©sistance)
[2025-07-18T18:42:44.989+0000] {scraper_banks.py:370} INFO - ‚úÖ Banque Populaire Cit√© Djemaa (agence Banque Populaire 364 avenue Docteur Moulasim Bouafi Quartier: Ben M'Sik)
[2025-07-18T18:42:45.474+0000] {scraper_banks.py:370} INFO - ‚úÖ Banque Populaire (agence Banque Populaire H9QQ+286 Bd Lahcen Ou Ider)
[2025-07-18T18:42:46.010+0000] {scraper_banks.py:370} INFO - ‚úÖ Banque Populaire (agence Banque Populaire H9JP+73J Av 2 Mars)
[2025-07-18T18:42:46.737+0000] {scraper_banks.py:370} INFO - ‚úÖ CaixaBank Casablanca (agence Casablanca Finance Group 179 Bd d'Anfa)
[2025-07-18T18:42:47.405+0000] {scraper_banks.py:370} INFO - ‚úÖ Cr√©dit du Maroc (agence Cr√©dit du Maroc H9QW+49P Bd de la R√©sistance)
[2025-07-18T18:42:47.972+0000] {scraper_banks.py:370} INFO - ‚úÖ Banque UMB (agence Banque Populaire 36 Rue Tahar Sebti)
[2025-07-18T18:42:48.474+0000] {scraper_banks.py:370} INFO - ‚úÖ Cr√©dit Agricole du Maroc (agence Cr√©dit Agricole du Maroc HCW7+5F5 Bd Ba Hmad)
[2025-07-18T18:42:49.175+0000] {scraper_banks.py:370} INFO - ‚úÖ BANK OF AFRICA Si√®ge Social (agence Bank of Africa 140 Bd Hassan II)
[2025-07-18T18:42:50.159+0000] {scraper_banks.py:370} INFO - ‚úÖ Si√®ge C - BANK OF AFRICA (agence Bank of Africa H9MG+WHX)
[2025-07-18T18:42:50.810+0000] {scraper_banks.py:370} INFO - ‚úÖ Banque Populaire Moussa Bnou Noussair (agence Banque Populaire 44 Rue Jean Jaures Casablanca)
[2025-07-18T18:42:51.918+0000] {scraper_banks.py:370} INFO - ‚úÖ Dar Al Amane Bank (agence Al Barid Bank Angle Rue de Rome et Rue Abou Fariss)
[2025-07-18T18:42:53.041+0000] {scraper_banks.py:370} INFO - ‚úÖ Banque Populaire Yacoub El Mansour (agence Banque Populaire 2 Ang Yel Mansour & Rue Acacias)
[2025-07-18T18:42:53.897+0000] {scraper_banks.py:370} INFO - ‚úÖ Banque Populaire Hay Masjid (Banque Populaire Hay Masjid)
[2025-07-18T18:42:54.521+0000] {scraper_banks.py:370} INFO - ‚úÖ banque populaire (agence Banque Populaire 314 Bd Mekdad Lahrizi)
[2025-07-18T18:42:55.162+0000] {scraper_banks.py:372} INFO - üö´ Doublon ou donn√©es incompl√®tes : Si√®ge C - BANK OF AFRICA
[2025-07-18T18:42:55.820+0000] {scraper_banks.py:372} INFO - üö´ Doublon ou donn√©es incompl√®tes : Banque Populaire El Fida
[2025-07-18T18:42:56.549+0000] {scraper_banks.py:372} INFO - üö´ Doublon ou donn√©es incompl√®tes : Banque Populaire
[2025-07-18T18:42:57.061+0000] {scraper_banks.py:372} INFO - üö´ Doublon ou donn√©es incompl√®tes : Banque Populaire Cit√© Djemaa
[2025-07-18T18:42:57.594+0000] {scraper_banks.py:372} INFO - üö´ Doublon ou donn√©es incompl√®tes : Si√®ge Social Banque Soci√©t√© G√©n√©rale
[2025-07-18T18:42:58.054+0000] {scraper_banks.py:370} INFO - ‚úÖ Banco Sabadell Maroc (agence Cr√©dit du Maroc 191 bd Mohamed Zerktouni Twin Center Tour Ouest)
[2025-07-18T18:42:58.486+0000] {scraper_banks.py:370} INFO - ‚úÖ Citibank (agence Citibank Morocco G9R5+C6J Bd de Fes)
[2025-07-18T18:42:58.964+0000] {scraper_banks.py:370} INFO - ‚úÖ Banque Populaire (agence Banque Populaire 3 bd Oued Sebou rue 152)
[2025-07-18T18:42:59.759+0000] {scraper_banks.py:372} INFO - üö´ Doublon ou donn√©es incompl√®tes : Banque Populaire
[2025-07-18T18:43:00.787+0000] {scraper_banks.py:370} INFO - ‚úÖ Banque populaire agence cil (agence Banque Populaire Angle rue de Restinga et Rue De Dades)
[2025-07-18T18:43:02.121+0000] {scraper_banks.py:370} INFO - ‚úÖ Banque Populaire ÿßŸÑÿ®ŸÜŸÉ ÿßŸÑÿ¥ÿπÿ®Ÿä (agence Banque Populaire G9H2+769 P3007)
[2025-07-18T18:43:03.887+0000] {scraper_banks.py:370} INFO - ‚úÖ CIH BANK (agence CIH Bank Av des FAR Avenue Hassan II 187)
[2025-07-18T18:43:04.819+0000] {scraper_banks.py:370} INFO - ‚úÖ Bank Al Amal (agence Al Barid Bank H9MF+H38 Bd Mohammed Zerktouni)
[2025-07-18T18:43:05.530+0000] {scraper_banks.py:370} INFO - ‚úÖ Banque populaire beaus√©jour (agence Banque Populaire 245 Bd Yacoub El Mansour)
[2025-07-18T18:43:06.209+0000] {scraper_banks.py:370} INFO - ‚úÖ Banque Populaire Hay Sadri (Banque Populaire Hay Sadri)
[2025-07-18T18:43:06.971+0000] {scraper_banks.py:370} INFO - ‚úÖ Banque populaire Hay Hassani (Banque populaire Hay Hassani)
[2025-07-18T18:43:07.818+0000] {scraper_banks.py:370} INFO - ‚úÖ Banque Populaire (agence Banque Populaire 921 bd El Fida Prolong√© hay Farah)
[2025-07-18T18:43:08.567+0000] {scraper_banks.py:370} INFO - ‚úÖ Bank chaabi (agence Chaabi International Bank H99H+V2G Bd Anoual)
[2025-07-18T18:43:09.698+0000] {scraper_banks.py:370} INFO - ‚úÖ CFG Bank - Agence Oasis (agence CFG Bank Angle Bd Abderrahim Bouabid et rue Brahim Allamtouni quartier)
[2025-07-18T18:43:11.382+0000] {scraper_banks.py:370} INFO - ‚úÖ Banque Populaire Moulay Youssef (agence Banque Populaire 54 Res My Youssef bd My Youssef)
[2025-07-18T18:43:12.423+0000] {scraper_banks.py:370} INFO - ‚úÖ CFG Bank - Agence Casa Racine (agence CFG Bank 5 Av Mohamed Sijilmassi)
[2025-07-18T18:43:13.643+0000] {scraper_banks.py:370} INFO - ‚úÖ Umnia Bank (agence Umnia Bank Ôïä)
[2025-07-18T18:43:14.591+0000] {scraper_banks.py:370} INFO - ‚úÖ CFG Bank - Agence Casa Massira (agence CFG Bank 101 Bd Al Massira Al Khadra)
[2025-07-18T18:43:15.036+0000] {scraper_banks.py:370} INFO - ‚úÖ Attijariwafa bank Casa Rue de Sebta (Attijariwafa bank Casa Rue de Sebta)
[2025-07-18T18:43:15.711+0000] {scraper_banks.py:370} INFO - ‚úÖ Banque Populaire Romandie (agence Banque Populaire 305 Boulevard Bir Anzarane)
[2025-07-18T18:43:16.470+0000] {scraper_banks.py:370} INFO - ‚úÖ Banque Populaire Moulay Rachid (agence Banque Populaire 64 Av Joudar Med Hay Rahma Casablanca)
[2025-07-18T18:43:17.328+0000] {scraper_banks.py:370} INFO - ‚úÖ Banque Populaire, Agence AL √éRFANE, Casablanca. (agence Banque Populaire HFX7+R27)
[2025-07-18T18:43:18.456+0000] {scraper_banks.py:370} INFO - ‚úÖ Banque Populaire (agence Banque Populaire H97V+4MQ Bd Modibo Keita)
[2025-07-18T18:43:19.090+0000] {scraper_banks.py:370} INFO - ‚úÖ Bank of Africa la Gironde (agence Bank of Africa H9QW+8XF Rue Barathon)
[2025-07-18T18:43:19.717+0000] {scraper_banks.py:370} INFO - ‚úÖ Attijariwafa Bank (agence Attijariwafa Bank ang rue Ibnu alhakam 101 Bd de Bourgogne)
[2025-07-18T18:43:20.360+0000] {scraper_banks.py:370} INFO - ‚úÖ Banque Populaire, Agence Majd, Casablanca (agence Banque Populaire HC77+V5V Bd de la Grande Ceinture)
[2025-07-18T18:43:21.099+0000] {scraper_banks.py:370} INFO - ‚úÖ Banque Populaire (agence Banque Populaire H9VM+V9R)
[2025-07-18T18:43:21.708+0000] {scraper_banks.py:370} INFO - ‚úÖ AttijariWafa Bank Place la Victoire (agence Attijariwafa Bank H9QR+JQ2 Rue Abdelkarim Al Khattabi)
[2025-07-18T18:43:22.796+0000] {scraper_banks.py:370} INFO - ‚úÖ Banque populaire Agence Goulmima (agence Banque Populaire Etage 1 Num√©ro 1 et Rue Beni Amir R√©sidence Haidar Jassim 1 Angle Rue de Goulmima)
[2025-07-18T18:43:23.492+0000] {scraper_banks.py:370} INFO - ‚úÖ Umnia Bank Casablanca Sidi Maarouf (agence Umnia Bank GH2 Imm R√©s Panorama 2 Av Abou Bakr el Kadiri)
[2025-07-18T18:43:24.544+0000] {scraper_banks.py:370} INFO - ‚úÖ Bank Assafa (agence Bank Assafa G9J2+9H9 Av Abou Bakr el Kadiri)
[2025-07-18T18:43:25.625+0000] {scraper_banks.py:370} INFO - ‚úÖ BANK OF AFRICA, Agence Abdelmoumen, Casablanca. (BANK OF AFRICA, Agence Abdelmoumen, Casablanca.)
[2025-07-18T18:43:26.659+0000] {scraper_banks.py:370} INFO - ‚úÖ Banque Populaire, Agence Bouchentouf, Casablanca. (agence Banque Populaire H99W+CG4 Bd El Fida)
[2025-07-18T18:43:27.623+0000] {scraper_banks.py:370} INFO - ‚úÖ AttijariWafa Banque (agence Attijariwafa Bank G9PX+F6M)
[2025-07-18T18:43:28.478+0000] {scraper_banks.py:370} INFO - ‚úÖ Bank Al Yousr (agence Bank Al Yousr H9C2+QXX)
[2025-07-18T18:43:29.811+0000] {scraper_banks.py:370} INFO - ‚úÖ Banque Populaire Ain Borja (agence Banque Populaire 60 Bd Ibn Tachfine)
[2025-07-18T18:43:30.481+0000] {scraper_banks.py:370} INFO - ‚úÖ BANK OF AFRICA (agence Bank of Africa 650 Boulevard Mohamed V)
[2025-07-18T18:43:30.993+0000] {scraper_banks.py:370} INFO - ‚úÖ Banque Populaire Panoramique (agence Banque Populaire 350 Bd Panoramique)
[2025-07-18T18:43:31.497+0000] {scraper_banks.py:370} INFO - ‚úÖ Soci√©t√© G√©n√©rale (agence Soci√©t√© G√©n√©rale Maroc G9G5+2GQ)
[2025-07-18T18:43:31.947+0000] {scraper_banks.py:370} INFO - ‚úÖ Banque Populaire Al Manar (agence Banque Populaire 105 Bd Ibn Baraka Residence Arrajaa Quartier El Hank Casa)
[2025-07-18T18:43:32.369+0000] {scraper_banks.py:370} INFO - ‚úÖ Bank of Africa (agence Bank of Africa LOT 134 LOTISSEMENT ENNASSIM CASABLANCA)
[2025-07-18T18:43:32.899+0000] {scraper_banks.py:370} INFO - ‚úÖ Bank of Africa (agence Bank of Africa H983+CCG)
[2025-07-18T18:43:33.393+0000] {scraper_banks.py:370} INFO - ‚úÖ Bank Of Africa, Agence Al Massira, Maarif. (agence Bank of Africa Rue Abou Abdellah Nafii)
[2025-07-18T18:43:33.955+0000] {scraper_banks.py:370} INFO - ‚úÖ Credit Populaire Du Maroc (agence Cr√©dit du Maroc 101 Bd Mohammed Zerktouni)
[2025-07-18T18:43:34.648+0000] {scraper_banks.py:370} INFO - ‚úÖ Societe Generale Maroc (SGMA) - SG Securities Services (agence Cr√©dit du Maroc 55 Bd Abdelmoumen)
[2025-07-18T18:43:35.078+0000] {scraper_banks.py:370} INFO - ‚úÖ Umnia Bank Casablanca Souna (agence Umnia Bank 586 Bd Modibo Keita)
[2025-07-18T18:43:35.783+0000] {scraper_banks.py:370} INFO - ‚úÖ Banque Populaire Ouled Ziane (agence Banque Populaire rue Ahmed Sebbagh and rue 71 derb El Kabir)
[2025-07-18T18:43:36.513+0000] {scraper_banks.py:370} INFO - ‚úÖ Banque Populaire (agence Banque Populaire HC2C+XH3)
[2025-07-18T18:43:37.112+0000] {scraper_banks.py:370} INFO - ‚úÖ Banque Populaire, Agence Cit√© Plateau, Maarif. (agence Banque Populaire H9F6+3PC Angrue Francois Ponsard Et Rue Al Moubarid Cite Plateau Casa)
[2025-07-18T18:43:38.055+0000] {scraper_banks.py:370} INFO - ‚úÖ CIH Bank (agence CIH Bank Boulevard Omar Al Khiam Boulevard Atlas)
[2025-07-18T18:43:38.533+0000] {scraper_banks.py:370} INFO - ‚úÖ CFG Bank - Agence Palmiers (agence CFG Bank 5 Rue Ibnou Toufail)
[2025-07-18T18:43:39.012+0000] {scraper_banks.py:370} INFO - ‚úÖ CFG Bank Agence Casa 2 Mars (agence CFG Bank 108 Av 2 Mars)
[2025-07-18T18:43:39.566+0000] {scraper_banks.py:370} INFO - ‚úÖ Banque Populaire Agence Hassan Seghir (agence Banque Populaire H9WR+M5R Angle Bd Hassan Seghir et Rue Hmida)
[2025-07-18T18:43:40.376+0000] {scraper_banks.py:370} INFO - ‚úÖ Banque Populaire Smara (agence Banque Populaire 4 bd Smara rue 170 Quartier: A√Øn Chok)
[2025-07-18T18:43:41.258+0000] {scraper_banks.py:370} INFO - ‚úÖ ATTIJARIWAFA BANK Sidi Abderrahmane (ATTIJARIWAFA BANK Sidi Abderrahmane)
[2025-07-18T18:43:42.205+0000] {scraper_banks.py:370} INFO - ‚úÖ BANK OF AFRICA (agence Bank of Africa 153 Bd Moulay Idriss I)
[2025-07-18T18:43:43.157+0000] {scraper_banks.py:370} INFO - ‚úÖ Attijariwafa Bank (agence Attijariwafa Bank G7XX+8QJ)
[2025-07-18T18:43:44.180+0000] {scraper_banks.py:370} INFO - ‚úÖ Banque Populaire Agence Lalla Yacout (agence Banque Populaire 39 Av Lalla Yacout)
[2025-07-18T18:43:45.309+0000] {scraper_banks.py:370} INFO - ‚úÖ Attijariwafa Bank (Si√®ge Social) (agence Attijariwafa Bank 2 Bd Moulay Youssef)
[2025-07-18T18:43:45.923+0000] {scraper_banks.py:370} INFO - ‚úÖ Sgmb TC - Yacoub El Mansour (agence BMCI - Banque Offshore 178 Bd Yacoub El Mansour)
[2025-07-18T18:43:46.593+0000] {scraper_banks.py:370} INFO - ‚úÖ Umnia Bank Casablanca Derb Ghalef (agence Umnia Bank 5 Boulevard Bir Anzarane)
[2025-07-18T18:43:47.456+0000] {scraper_banks.py:370} INFO - ‚úÖ Bank Assafa (agence Bank Assafa H983+64V Rue Al Oukhouane)
[2025-07-18T18:43:48.619+0000] {scraper_banks.py:370} INFO - ‚úÖ CFG Bank - Agence Casa Gauthier (agence CFG Bank Av Hassan Souktani)
[2025-07-18T18:43:49.129+0000] {scraper_banks.py:370} INFO - ‚úÖ BMCE Bank of Africa - Agence Bourgogne (agence Bank of Africa H9W3+VMG bd de Bourgogne ang rue Abou AlWaqt Khalaf)
[2025-07-18T18:43:50.102+0000] {scraper_banks.py:370} INFO - ‚úÖ Cr√©dit du Maroc (agence Cr√©dit du Maroc 38 Rue Atlas Hay Assalam - CIL-)
[2025-07-18T18:43:51.034+0000] {scraper_banks.py:370} INFO - ‚úÖ Attijariwafa Bank (agence Attijariwafa Bank Kelaa Mgouna 20100)
[2025-07-18T18:43:51.738+0000] {scraper_banks.py:370} INFO - ‚úÖ Banque Populaire, Agence Hay Mohammadi, Casablanca. (Banque Populaire, Agence Hay Mohammadi, Casablanca.)
[2025-07-18T18:43:52.796+0000] {scraper_banks.py:370} INFO - ‚úÖ BMCE (agence BMCE Bank H7GV+CH4)
[2025-07-18T18:43:53.489+0000] {scraper_banks.py:370} INFO - ‚úÖ Banque Populaire Oum Rabii (agence Banque Populaire 152 Bd Oued Oum Rabia)
[2025-07-18T18:43:54.253+0000] {scraper_banks.py:370} INFO - ‚úÖ Bank Al Karam_Si√®ge Social (agence Al Barid Bank 157 Bd Hassan II)
[2025-07-18T18:43:55.130+0000] {scraper_banks.py:370} INFO - ‚úÖ Centre National De Formation de la Banque Populaire (agence Banque Populaire ANFA)
[2025-07-18T18:43:55.930+0000] {scraper_banks.py:370} INFO - ‚úÖ Attijariwafa bank (agence Attijariwafa Bank H9F4+XXC Bd Yacoub El Mansour)
[2025-07-18T18:43:56.955+0000] {scraper_banks.py:370} INFO - ‚úÖ Cr√©dit du Maroc (agence Cr√©dit du Maroc HCV3+HHC)
[2025-07-18T18:43:58.013+0000] {scraper_banks.py:370} INFO - ‚úÖ Umnia Bank Casablanca Oulfa (agence Umnia Bank Rond-point George Bd Oued Oum Rabia)
[2025-07-18T18:43:58.668+0000] {scraper_banks.py:370} INFO - ‚úÖ Attijariwafa Bank (agence Attijariwafa Bank G8GQ+4R2 Unnamed Road)
[2025-07-18T18:43:59.967+0000] {scraper_banks.py:370} INFO - ‚úÖ Attijariwafa Bank (agence Attijariwafa Bank H97R+372 Av 2 Mars)
[2025-07-18T18:44:00.718+0000] {scraper_banks.py:370} INFO - ‚úÖ Banque Populaire Sahraoui (agence Banque Populaire H9VJ+M9X Rue Abderrahman Sahraoui)
[2025-07-18T18:44:07.326+0000] {scraper_banks.py:370} INFO - ‚úÖ Umnia Bank Casablanca Ain Sebaa. (agence Umnia Bank Bd Chefchaouni)
[2025-07-18T18:44:15.023+0000] {scraper_banks.py:370} INFO - ‚úÖ Bank of Africa (agence Bank of Africa 458 bd Oued Sebou 20220 Casablanca Bd Oued Sebou)
[2025-07-18T18:44:20.571+0000] {scraper_banks.py:370} INFO - ‚úÖ Banque Populaire (agence Banque Populaire H9FX+CQ4 Rue Maamora)
[2025-07-18T18:44:21.516+0000] {scraper_banks.py:370} INFO - ‚úÖ Banque Populaire, Agence Ibnou Nafis, Maarif. (agence Banque Populaire 62 Ibnou Nafis)
[2025-07-18T18:44:21.277+0000] {job.py:229} INFO - Heartbeat recovered after 25.25 seconds
[2025-07-18T18:44:22.966+0000] {scraper_banks.py:370} INFO - ‚úÖ Attijariwafa Bank (agence Attijariwafa Bank H8WP+8PX)
[2025-07-18T18:44:24.400+0000] {scraper_banks.py:370} INFO - ‚úÖ EBRD Casablanca RO (agence Casablanca Finance Group Immeuble Zevaco d'Azemmour Rue 46)
[2025-07-18T18:44:25.163+0000] {scraper_banks.py:370} INFO - ‚úÖ Attijariwafa Bank (agence Attijariwafa Bank H9RX+HCJ Bd Emile Zola)
[2025-07-18T18:44:26.019+0000] {scraper_banks.py:370} INFO - ‚úÖ CIH Bank Sidi Maarouf (agence CIH Bank G8GX+4P3ÿå Av Abou Bakr el Kadiri Route Principale 1029 Al Mostakbalgh 4 Rdpt Al Moustakbal)
[2025-07-18T18:44:27.053+0000] {scraper_banks.py:370} INFO - ‚úÖ Al Akhdar Bank (agence Al Akhdar Bank 6 Rue Moli√®re)
[2025-07-18T18:44:28.046+0000] {scraper_banks.py:370} INFO - ‚úÖ Bank of Africa (agence Bank of Africa HCF2+C38 Rue Maamora)
[2025-07-18T18:44:29.314+0000] {scraper_banks.py:370} INFO - ‚úÖ BANK OF AFRICA LALLA YACOUT PART/PRO (agence Bank of Africa Av Lalla Yacout)
[2025-07-18T18:44:29.985+0000] {scraper_banks.py:370} INFO - ‚úÖ CIH Bank Yaacoub Al Mansour (agence CIH Bank H8CX+284)
[2025-07-18T18:44:30.723+0000] {scraper_banks.py:370} INFO - ‚úÖ Banque Populaire - Al Baida (agence Banque Populaire Angle Bd 9 Avril Et Rue Mansart)
[2025-07-18T18:44:31.502+0000] {scraper_banks.py:370} INFO - ‚úÖ Attijariwafa Bank (agence Attijariwafa Bank HC3F+85G Av Reda Guedira)
[2025-07-18T18:44:32.354+0000] {scraper_banks.py:370} INFO - ‚úÖ Banque Populaire (agence Banque Populaire H8C6+WW2)
[2025-07-18T18:44:32.364+0000] {scraper_banks.py:378} INFO - [Casablanca] 114 banques enregistr√©es
[2025-07-18T18:44:32.370+0000] {scraper_banks.py:379} INFO - ‚úÖ [Casablanca] Extraction termin√©e
[2025-07-18T18:44:34.232+0000] {logger.py:11} INFO - ====== WebDriver manager ======
[2025-07-18T18:44:36.269+0000] {logger.py:11} INFO - Get LATEST chromedriver version for google-chrome
[2025-07-18T18:44:38.635+0000] {logger.py:11} INFO - Get LATEST chromedriver version for google-chrome
[2025-07-18T18:44:40.329+0000] {logger.py:11} INFO - Driver [/home/***/.wdm/drivers/chromedriver/linux64/138.0.7204.157/chromedriver-linux64/chromedriver] found in cache
[2025-07-18T18:45:16.524+0000] {job.py:229} INFO - Heartbeat recovered after 34.25 seconds
[2025-07-18T18:45:19.302+0000] {scraper_banks.py:269} INFO - 
üìç Initialisation pour Casablanca...
[2025-07-18T18:46:38.318+0000] {job.py:229} INFO - Heartbeat recovered after 10.62 seconds
[2025-07-18T18:47:12.493+0000] {job.py:229} INFO - Heartbeat recovered after 12.54 seconds
[2025-07-18T18:48:19.439+0000] {job.py:239} ERROR - Job heartbeat failed with error
Traceback (most recent call last):
  File "/home/airflow/.local/lib/python3.11/site-packages/sqlalchemy/engine/base.py", line 3371, in _wrap_pool_connect
    return fn()
           ^^^^
  File "/home/airflow/.local/lib/python3.11/site-packages/sqlalchemy/pool/base.py", line 327, in connect
    return _ConnectionFairy._checkout(self)
           ^^^^^^^^^^^^^^^^^^^^^^^^^^^^^^^^
  File "/home/airflow/.local/lib/python3.11/site-packages/sqlalchemy/pool/base.py", line 894, in _checkout
    fairy = _ConnectionRecord.checkout(pool)
            ^^^^^^^^^^^^^^^^^^^^^^^^^^^^^^^^
  File "/home/airflow/.local/lib/python3.11/site-packages/sqlalchemy/pool/base.py", line 493, in checkout
    rec = pool._do_get()
          ^^^^^^^^^^^^^^
  File "/home/airflow/.local/lib/python3.11/site-packages/sqlalchemy/pool/impl.py", line 256, in _do_get
    return self._create_connection()
           ^^^^^^^^^^^^^^^^^^^^^^^^^
  File "/home/airflow/.local/lib/python3.11/site-packages/sqlalchemy/pool/base.py", line 273, in _create_connection
    return _ConnectionRecord(self)
           ^^^^^^^^^^^^^^^^^^^^^^^
  File "/home/airflow/.local/lib/python3.11/site-packages/sqlalchemy/pool/base.py", line 388, in __init__
    self.__connect()
  File "/home/airflow/.local/lib/python3.11/site-packages/sqlalchemy/pool/base.py", line 690, in __connect
    with util.safe_reraise():
  File "/home/airflow/.local/lib/python3.11/site-packages/sqlalchemy/util/langhelpers.py", line 70, in __exit__
    compat.raise_(
  File "/home/airflow/.local/lib/python3.11/site-packages/sqlalchemy/util/compat.py", line 211, in raise_
    raise exception
  File "/home/airflow/.local/lib/python3.11/site-packages/sqlalchemy/pool/base.py", line 686, in __connect
    self.dbapi_connection = connection = pool._invoke_creator(self)
                                         ^^^^^^^^^^^^^^^^^^^^^^^^^^
  File "/home/airflow/.local/lib/python3.11/site-packages/sqlalchemy/engine/create.py", line 574, in connect
    return dialect.connect(*cargs, **cparams)
           ^^^^^^^^^^^^^^^^^^^^^^^^^^^^^^^^^^
  File "/home/airflow/.local/lib/python3.11/site-packages/sqlalchemy/engine/default.py", line 598, in connect
    return self.dbapi.connect(*cargs, **cparams)
           ^^^^^^^^^^^^^^^^^^^^^^^^^^^^^^^^^^^^^
  File "/home/airflow/venv/lib/python3.11/site-packages/psycopg2/__init__.py", line 122, in connect
    conn = _connect(dsn, connection_factory=connection_factory, **kwasync)
           ^^^^^^^^^^^^^^^^^^^^^^^^^^^^^^^^^^^^^^^^^^^^^^^^^^^^^^^^^^^^^^^
psycopg2.OperationalError: could not translate host name "postgres" to address: Temporary failure in name resolution


The above exception was the direct cause of the following exception:

Traceback (most recent call last):
  File "/home/airflow/.local/lib/python3.11/site-packages/airflow/jobs/job.py", line 207, in heartbeat
    self._merge_from(Job._fetch_from_db(self, session))
                     ^^^^^^^^^^^^^^^^^^^^^^^^^^^^^^^^^
  File "/home/airflow/.local/lib/python3.11/site-packages/airflow/api_internal/internal_api_call.py", line 166, in wrapper
    return func(*args, **kwargs)
           ^^^^^^^^^^^^^^^^^^^^^
  File "/home/airflow/.local/lib/python3.11/site-packages/airflow/utils/session.py", line 94, in wrapper
    return func(*args, **kwargs)
           ^^^^^^^^^^^^^^^^^^^^^
  File "/home/airflow/.local/lib/python3.11/site-packages/airflow/utils/retries.py", line 93, in wrapped_function
    for attempt in run_with_db_retries(max_retries=retries, logger=logger, **retry_kwargs):
  File "/home/airflow/.local/lib/python3.11/site-packages/tenacity/__init__.py", line 443, in __iter__
    do = self.iter(retry_state=retry_state)
         ^^^^^^^^^^^^^^^^^^^^^^^^^^^^^^^^^^
  File "/home/airflow/.local/lib/python3.11/site-packages/tenacity/__init__.py", line 376, in iter
    result = action(retry_state)
             ^^^^^^^^^^^^^^^^^^^
  File "/home/airflow/.local/lib/python3.11/site-packages/tenacity/__init__.py", line 418, in exc_check
    raise retry_exc.reraise()
          ^^^^^^^^^^^^^^^^^^^
  File "/home/airflow/.local/lib/python3.11/site-packages/tenacity/__init__.py", line 185, in reraise
    raise self.last_attempt.result()
          ^^^^^^^^^^^^^^^^^^^^^^^^^^
  File "/usr/local/lib/python3.11/concurrent/futures/_base.py", line 449, in result
    return self.__get_result()
           ^^^^^^^^^^^^^^^^^^^
  File "/usr/local/lib/python3.11/concurrent/futures/_base.py", line 401, in __get_result
    raise self._exception
  File "/home/airflow/.local/lib/python3.11/site-packages/airflow/utils/retries.py", line 102, in wrapped_function
    return func(*args, **kwargs)
           ^^^^^^^^^^^^^^^^^^^^^
  File "/home/airflow/.local/lib/python3.11/site-packages/airflow/jobs/job.py", line 335, in _fetch_from_db
    session.merge(job)
  File "/home/airflow/.local/lib/python3.11/site-packages/sqlalchemy/orm/session.py", line 3056, in merge
    return self._merge(
           ^^^^^^^^^^^^
  File "/home/airflow/.local/lib/python3.11/site-packages/sqlalchemy/orm/session.py", line 3136, in _merge
    merged = self.get(
             ^^^^^^^^^
  File "/home/airflow/.local/lib/python3.11/site-packages/sqlalchemy/orm/session.py", line 2853, in get
    return self._get_impl(
           ^^^^^^^^^^^^^^^
  File "/home/airflow/.local/lib/python3.11/site-packages/sqlalchemy/orm/session.py", line 2975, in _get_impl
    return db_load_fn(
           ^^^^^^^^^^^
  File "/home/airflow/.local/lib/python3.11/site-packages/sqlalchemy/orm/loading.py", line 530, in load_on_pk_identity
    session.execute(
  File "/home/airflow/.local/lib/python3.11/site-packages/sqlalchemy/orm/session.py", line 1716, in execute
    conn = self._connection_for_bind(bind)
           ^^^^^^^^^^^^^^^^^^^^^^^^^^^^^^^
  File "/home/airflow/.local/lib/python3.11/site-packages/sqlalchemy/orm/session.py", line 1555, in _connection_for_bind
    return self._transaction._connection_for_bind(
           ^^^^^^^^^^^^^^^^^^^^^^^^^^^^^^^^^^^^^^^
  File "/home/airflow/.local/lib/python3.11/site-packages/sqlalchemy/orm/session.py", line 750, in _connection_for_bind
    conn = bind.connect()
           ^^^^^^^^^^^^^^
  File "/home/airflow/.local/lib/python3.11/site-packages/sqlalchemy/future/engine.py", line 412, in connect
    return super(Engine, self).connect()
           ^^^^^^^^^^^^^^^^^^^^^^^^^^^^^
  File "/home/airflow/.local/lib/python3.11/site-packages/sqlalchemy/engine/base.py", line 3325, in connect
    return self._connection_cls(self, close_with_result=close_with_result)
           ^^^^^^^^^^^^^^^^^^^^^^^^^^^^^^^^^^^^^^^^^^^^^^^^^^^^^^^^^^^^^^^
  File "/home/airflow/.local/lib/python3.11/site-packages/sqlalchemy/engine/base.py", line 96, in __init__
    else engine.raw_connection()
         ^^^^^^^^^^^^^^^^^^^^^^^
  File "/home/airflow/.local/lib/python3.11/site-packages/sqlalchemy/engine/base.py", line 3404, in raw_connection
    return self._wrap_pool_connect(self.pool.connect, _connection)
           ^^^^^^^^^^^^^^^^^^^^^^^^^^^^^^^^^^^^^^^^^^^^^^^^^^^^^^^
  File "/home/airflow/.local/lib/python3.11/site-packages/sqlalchemy/engine/base.py", line 3374, in _wrap_pool_connect
    Connection._handle_dbapi_exception_noconnection(
  File "/home/airflow/.local/lib/python3.11/site-packages/sqlalchemy/engine/base.py", line 2208, in _handle_dbapi_exception_noconnection
    util.raise_(
  File "/home/airflow/.local/lib/python3.11/site-packages/sqlalchemy/util/compat.py", line 211, in raise_
    raise exception
  File "/home/airflow/.local/lib/python3.11/site-packages/sqlalchemy/engine/base.py", line 3371, in _wrap_pool_connect
    return fn()
           ^^^^
  File "/home/airflow/.local/lib/python3.11/site-packages/sqlalchemy/pool/base.py", line 327, in connect
    return _ConnectionFairy._checkout(self)
           ^^^^^^^^^^^^^^^^^^^^^^^^^^^^^^^^
  File "/home/airflow/.local/lib/python3.11/site-packages/sqlalchemy/pool/base.py", line 894, in _checkout
    fairy = _ConnectionRecord.checkout(pool)
            ^^^^^^^^^^^^^^^^^^^^^^^^^^^^^^^^
  File "/home/airflow/.local/lib/python3.11/site-packages/sqlalchemy/pool/base.py", line 493, in checkout
    rec = pool._do_get()
          ^^^^^^^^^^^^^^
  File "/home/airflow/.local/lib/python3.11/site-packages/sqlalchemy/pool/impl.py", line 256, in _do_get
    return self._create_connection()
           ^^^^^^^^^^^^^^^^^^^^^^^^^
  File "/home/airflow/.local/lib/python3.11/site-packages/sqlalchemy/pool/base.py", line 273, in _create_connection
    return _ConnectionRecord(self)
           ^^^^^^^^^^^^^^^^^^^^^^^
  File "/home/airflow/.local/lib/python3.11/site-packages/sqlalchemy/pool/base.py", line 388, in __init__
    self.__connect()
  File "/home/airflow/.local/lib/python3.11/site-packages/sqlalchemy/pool/base.py", line 690, in __connect
    with util.safe_reraise():
  File "/home/airflow/.local/lib/python3.11/site-packages/sqlalchemy/util/langhelpers.py", line 70, in __exit__
    compat.raise_(
  File "/home/airflow/.local/lib/python3.11/site-packages/sqlalchemy/util/compat.py", line 211, in raise_
    raise exception
  File "/home/airflow/.local/lib/python3.11/site-packages/sqlalchemy/pool/base.py", line 686, in __connect
    self.dbapi_connection = connection = pool._invoke_creator(self)
                                         ^^^^^^^^^^^^^^^^^^^^^^^^^^
  File "/home/airflow/.local/lib/python3.11/site-packages/sqlalchemy/engine/create.py", line 574, in connect
    return dialect.connect(*cargs, **cparams)
           ^^^^^^^^^^^^^^^^^^^^^^^^^^^^^^^^^^
  File "/home/airflow/.local/lib/python3.11/site-packages/sqlalchemy/engine/default.py", line 598, in connect
    return self.dbapi.connect(*cargs, **cparams)
           ^^^^^^^^^^^^^^^^^^^^^^^^^^^^^^^^^^^^^
  File "/home/airflow/venv/lib/python3.11/site-packages/psycopg2/__init__.py", line 122, in connect
    conn = _connect(dsn, connection_factory=connection_factory, **kwasync)
           ^^^^^^^^^^^^^^^^^^^^^^^^^^^^^^^^^^^^^^^^^^^^^^^^^^^^^^^^^^^^^^^
sqlalchemy.exc.OperationalError: (psycopg2.OperationalError) could not translate host name "postgres" to address: Temporary failure in name resolution

(Background on this error at: https://sqlalche.me/e/14/e3q8)
[2025-07-18T18:48:20.711+0000] {job.py:254} ERROR - Job heartbeat failed with error. Scheduler is in unhealthy state
[2025-07-18T18:48:28.162+0000] {job.py:229} INFO - Heartbeat recovered after 47.11 seconds
[2025-07-18T18:49:22.573+0000] {scraper_banks.py:198} INFO - ‚úÖ Fin du scrolling
[2025-07-18T18:49:23.052+0000] {scraper_banks.py:289} INFO - [Casablanca] 120 r√©sultats trouv√©s
[2025-07-18T18:49:23.948+0000] {scraper_banks.py:372} INFO - üö´ Doublon ou donn√©es incompl√®tes : BANK OF AFRICA
[2025-07-18T18:49:24.356+0000] {scraper_banks.py:372} INFO - üö´ Doublon ou donn√©es incompl√®tes : Bank Al Maghrib
[2025-07-18T18:49:24.679+0000] {scraper_banks.py:372} INFO - üö´ Doublon ou donn√©es incompl√®tes : Banque Populaire Moulay Driss 1er
[2025-07-18T18:49:25.494+0000] {scraper_banks.py:370} INFO - ‚úÖ Banque Populaire (agence Banque Populaire 6GW3+6MW Av Mohamed VI)
[2025-07-18T18:49:26.104+0000] {scraper_banks.py:372} INFO - üö´ Doublon ou donn√©es incompl√®tes : Banque Populaire El Khatabi
[2025-07-18T18:49:26.419+0000] {scraper_banks.py:372} INFO - üö´ Doublon ou donn√©es incompl√®tes : Banque Populaire El Fida
[2025-07-18T18:49:26.892+0000] {scraper_banks.py:372} INFO - üö´ Doublon ou donn√©es incompl√®tes : Si√®ge Social Banque Soci√©t√© G√©n√©rale
[2025-07-18T18:49:27.524+0000] {scraper_banks.py:372} INFO - üö´ Doublon ou donn√©es incompl√®tes : Arab Bank Plc
[2025-07-18T18:49:27.938+0000] {scraper_banks.py:372} INFO - üö´ Doublon ou donn√©es incompl√®tes : Banque Centrale Populaire
[2025-07-18T18:49:28.264+0000] {scraper_banks.py:372} INFO - üö´ Doublon ou donn√©es incompl√®tes : Banque Populaire
[2025-07-18T18:49:28.585+0000] {scraper_banks.py:372} INFO - üö´ Doublon ou donn√©es incompl√®tes : Banque Populaire Cit√© Djemaa
[2025-07-18T18:49:28.975+0000] {scraper_banks.py:372} INFO - üö´ Doublon ou donn√©es incompl√®tes : Banque Populaire
[2025-07-18T18:49:29.339+0000] {scraper_banks.py:372} INFO - üö´ Doublon ou donn√©es incompl√®tes : Banque Populaire
[2025-07-18T18:49:29.635+0000] {scraper_banks.py:372} INFO - üö´ Doublon ou donn√©es incompl√®tes : CaixaBank Casablanca
[2025-07-18T18:49:30.004+0000] {scraper_banks.py:372} INFO - üö´ Doublon ou donn√©es incompl√®tes : Cr√©dit du Maroc
[2025-07-18T18:49:30.380+0000] {scraper_banks.py:372} INFO - üö´ Doublon ou donn√©es incompl√®tes : Banque UMB
[2025-07-18T18:49:30.727+0000] {scraper_banks.py:372} INFO - üö´ Doublon ou donn√©es incompl√®tes : Cr√©dit Agricole du Maroc
[2025-07-18T18:49:31.258+0000] {scraper_banks.py:372} INFO - üö´ Doublon ou donn√©es incompl√®tes : BANK OF AFRICA Si√®ge Social
[2025-07-18T18:49:31.787+0000] {scraper_banks.py:372} INFO - üö´ Doublon ou donn√©es incompl√®tes : Si√®ge C - BANK OF AFRICA
[2025-07-18T18:49:32.153+0000] {scraper_banks.py:372} INFO - üö´ Doublon ou donn√©es incompl√®tes : Banque Populaire Moussa Bnou Noussair
[2025-07-18T18:49:32.862+0000] {scraper_banks.py:372} INFO - üö´ Doublon ou donn√©es incompl√®tes : Banque Populaire El Fida
[2025-07-18T18:49:33.338+0000] {scraper_banks.py:372} INFO - üö´ Doublon ou donn√©es incompl√®tes : AttijariWafa Bank Place la Victoire
[2025-07-18T18:49:34.409+0000] {scraper_banks.py:370} INFO - ‚úÖ Banque Populaire, Agence MOHAMMED V, Casablanca. (agence Banque Populaire 353 Ang Bd Mohammed 5 Et Bd La R√©sistance 2√®me √âtg N¬∞ 2)
[2025-07-18T18:49:34.819+0000] {scraper_banks.py:370} INFO - ‚úÖ Soci√©t√© G√©n√©rale (agence Soci√©t√© G√©n√©rale Maroc HCF2+RQX R315)
[2025-07-18T18:49:35.488+0000] {scraper_banks.py:370} INFO - ‚úÖ Attijariwafa bank Casa Rue De Rome (Attijariwafa bank Casa Rue De Rome)
[2025-07-18T18:49:36.210+0000] {scraper_banks.py:370} INFO - ‚úÖ Bank of Africa (agence Bank of Africa H99V+3P2 Bd El Fida)
[2025-07-18T18:49:36.521+0000] {scraper_banks.py:372} INFO - üö´ Doublon ou donn√©es incompl√®tes : Banque Populaire
[2025-07-18T18:49:36.844+0000] {scraper_banks.py:372} INFO - üö´ Doublon ou donn√©es incompl√®tes : Umnia Bank Casablanca Souna
[2025-07-18T18:49:37.160+0000] {scraper_banks.py:370} INFO - ‚úÖ BANK OF AFRICA (agence Bank of Africa 33 Rue Ali Bnou Abi Taleb)
[2025-07-18T18:49:37.477+0000] {scraper_banks.py:372} INFO - üö´ Doublon ou donn√©es incompl√®tes : Banque Populaire, Agence Majd, Casablanca
[2025-07-18T18:49:37.894+0000] {scraper_banks.py:372} INFO - üö´ Doublon ou donn√©es incompl√®tes : Banque Populaire Cit√© Djemaa
[2025-07-18T18:49:38.231+0000] {scraper_banks.py:372} INFO - üö´ Doublon ou donn√©es incompl√®tes : Banque populaire beaus√©jour
[2025-07-18T18:49:38.544+0000] {scraper_banks.py:372} INFO - üö´ Doublon ou donn√©es incompl√®tes : Banque Populaire Panoramique
[2025-07-18T18:49:38.888+0000] {scraper_banks.py:370} INFO - ‚úÖ Banque populaire al fouarat (agence Banque Populaire HCGJ+86X Bd du Fouarat)
[2025-07-18T18:49:39.198+0000] {scraper_banks.py:370} INFO - ‚úÖ Banque Populaire Des Forces Arm√©es Royales (agence Banque Populaire 48 Bd Des Far Casablanca)
[2025-07-18T18:49:39.526+0000] {scraper_banks.py:372} INFO - üö´ Doublon ou donn√©es incompl√®tes : BANK OF AFRICA
[2025-07-18T18:49:39.879+0000] {scraper_banks.py:372} INFO - üö´ Doublon ou donn√©es incompl√®tes : Agence Attijariwafabank
[2025-07-18T18:49:40.191+0000] {scraper_banks.py:370} INFO - ‚úÖ Attijariwafa bank Bd La Grande Ceinture (Attijariwafa bank Bd La Grande Ceinture)
[2025-07-18T18:49:40.659+0000] {scraper_banks.py:372} INFO - üö´ Doublon ou donn√©es incompl√®tes : BANK OF AFRICA, Agence Abdelmoumen, Casablanca.
[2025-07-18T18:49:41.057+0000] {scraper_banks.py:372} INFO - üö´ Doublon ou donn√©es incompl√®tes : Bank Al Amal
[2025-07-18T18:49:41.507+0000] {scraper_banks.py:372} INFO - üö´ Doublon ou donn√©es incompl√®tes : Banque Populaire
[2025-07-18T18:49:42.002+0000] {scraper_banks.py:370} INFO - ‚úÖ Banque Marocaine Du Commerce Et de l'Industrie Gestion (agence Union Marocaine de Banques Hill Subdivision (Sidi Maarouf) Hill II Lot 3)
[2025-07-18T18:49:43.027+0000] {scraper_banks.py:372} INFO - üö´ Doublon ou donn√©es incompl√®tes : Umnia Bank Casablanca Derb Ghalef
[2025-07-18T18:49:44.196+0000] {scraper_banks.py:372} INFO - üö´ Doublon ou donn√©es incompl√®tes : Banque Populaire, Agence Hay Mohammadi, Casablanca.
[2025-07-18T18:49:45.230+0000] {scraper_banks.py:370} INFO - ‚úÖ Banque Populaire Hay Chrifa (Banque Populaire Hay Chrifa)
[2025-07-18T18:49:45.809+0000] {scraper_banks.py:372} INFO - üö´ Doublon ou donn√©es incompl√®tes : CFG Bank Agence Casa 2 Mars
[2025-07-18T18:49:46.400+0000] {scraper_banks.py:370} INFO - ‚úÖ BANK OF AFRICA (agence Bank of Africa HC47+MMP Av Al Wahda Al Ifriquia)
[2025-07-18T18:49:46.941+0000] {scraper_banks.py:370} INFO - ‚úÖ Attijariwafa bank Belv√©d√®re (agence Attijariwafa Bank Unnamed Road Casablanca)
[2025-07-18T18:49:47.828+0000] {scraper_banks.py:372} INFO - üö´ Doublon ou donn√©es incompl√®tes : Credit Populaire Du Maroc
[2025-07-18T18:49:49.035+0000] {scraper_banks.py:372} INFO - üö´ Doublon ou donn√©es incompl√®tes : CFG Bank - Agence Casa Massira
[2025-07-18T18:49:49.777+0000] {scraper_banks.py:372} INFO - üö´ Doublon ou donn√©es incompl√®tes : Umnia Bank
[2025-07-18T18:49:50.170+0000] {scraper_banks.py:370} INFO - ‚úÖ Agence Banque Populaire (agence Banque Populaire HCCQ+CFR)
[2025-07-18T18:49:50.557+0000] {scraper_banks.py:370} INFO - ‚úÖ Banque Marocaine Pour l'Afrique Et l'Orient Agence Lalla Yacout (agence Banque Populaire H9RP+6X4 Av Lalla Yacout)
[2025-07-18T18:49:51.092+0000] {scraper_banks.py:372} INFO - üö´ Doublon ou donn√©es incompl√®tes : Banque Populaire, Agence Bouchentouf, Casablanca.
[2025-07-18T18:49:51.652+0000] {scraper_banks.py:372} INFO - üö´ Doublon ou donn√©es incompl√®tes : BANK OF AFRICA
[2025-07-18T18:49:52.708+0000] {scraper_banks.py:372} INFO - üö´ Doublon ou donn√©es incompl√®tes : Si√®ge Social Banque Soci√©t√© G√©n√©rale
[2025-07-18T18:49:54.143+0000] {scraper_banks.py:370} INFO - ‚úÖ Cr√©dit du Maroc (agence Cr√©dit du Maroc 19 Bd 2 Mars Hay Al Masjid)
[2025-07-18T18:49:55.259+0000] {scraper_banks.py:370} INFO - ‚úÖ Umnia Bank Casablanca Hay Sadri (Umnia Bank Casablanca Hay Sadri)
[2025-07-18T18:49:56.012+0000] {scraper_banks.py:372} INFO - üö´ Doublon ou donn√©es incompl√®tes : Bank chaabi
[2025-07-18T18:49:56.978+0000] {scraper_banks.py:372} INFO - üö´ Doublon ou donn√©es incompl√®tes : CFG Bank - Agence Casa Gauthier
[2025-07-18T18:49:57.599+0000] {scraper_banks.py:372} INFO - üö´ Doublon ou donn√©es incompl√®tes : Bank of Africa la Gironde
[2025-07-18T18:49:58.275+0000] {scraper_banks.py:372} INFO - üö´ Doublon ou donn√©es incompl√®tes : Banque Populaire
[2025-07-18T18:50:14.218+0000] {scraper_banks.py:372} INFO - üö´ Doublon ou donn√©es incompl√®tes : CFG Bank - Agence Oasis
[2025-07-18T18:50:24.435+0000] {job.py:239} ERROR - Job heartbeat failed with error
Traceback (most recent call last):
  File "/home/airflow/.local/lib/python3.11/site-packages/sqlalchemy/engine/base.py", line 3371, in _wrap_pool_connect
    return fn()
           ^^^^
  File "/home/airflow/.local/lib/python3.11/site-packages/sqlalchemy/pool/base.py", line 327, in connect
    return _ConnectionFairy._checkout(self)
           ^^^^^^^^^^^^^^^^^^^^^^^^^^^^^^^^
  File "/home/airflow/.local/lib/python3.11/site-packages/sqlalchemy/pool/base.py", line 894, in _checkout
    fairy = _ConnectionRecord.checkout(pool)
            ^^^^^^^^^^^^^^^^^^^^^^^^^^^^^^^^
  File "/home/airflow/.local/lib/python3.11/site-packages/sqlalchemy/pool/base.py", line 493, in checkout
    rec = pool._do_get()
          ^^^^^^^^^^^^^^
  File "/home/airflow/.local/lib/python3.11/site-packages/sqlalchemy/pool/impl.py", line 256, in _do_get
    return self._create_connection()
           ^^^^^^^^^^^^^^^^^^^^^^^^^
  File "/home/airflow/.local/lib/python3.11/site-packages/sqlalchemy/pool/base.py", line 273, in _create_connection
    return _ConnectionRecord(self)
           ^^^^^^^^^^^^^^^^^^^^^^^
  File "/home/airflow/.local/lib/python3.11/site-packages/sqlalchemy/pool/base.py", line 388, in __init__
    self.__connect()
  File "/home/airflow/.local/lib/python3.11/site-packages/sqlalchemy/pool/base.py", line 690, in __connect
    with util.safe_reraise():
  File "/home/airflow/.local/lib/python3.11/site-packages/sqlalchemy/util/langhelpers.py", line 70, in __exit__
    compat.raise_(
  File "/home/airflow/.local/lib/python3.11/site-packages/sqlalchemy/util/compat.py", line 211, in raise_
    raise exception
  File "/home/airflow/.local/lib/python3.11/site-packages/sqlalchemy/pool/base.py", line 686, in __connect
    self.dbapi_connection = connection = pool._invoke_creator(self)
                                         ^^^^^^^^^^^^^^^^^^^^^^^^^^
  File "/home/airflow/.local/lib/python3.11/site-packages/sqlalchemy/engine/create.py", line 574, in connect
    return dialect.connect(*cargs, **cparams)
           ^^^^^^^^^^^^^^^^^^^^^^^^^^^^^^^^^^
  File "/home/airflow/.local/lib/python3.11/site-packages/sqlalchemy/engine/default.py", line 598, in connect
    return self.dbapi.connect(*cargs, **cparams)
           ^^^^^^^^^^^^^^^^^^^^^^^^^^^^^^^^^^^^^
  File "/home/airflow/venv/lib/python3.11/site-packages/psycopg2/__init__.py", line 122, in connect
    conn = _connect(dsn, connection_factory=connection_factory, **kwasync)
           ^^^^^^^^^^^^^^^^^^^^^^^^^^^^^^^^^^^^^^^^^^^^^^^^^^^^^^^^^^^^^^^
psycopg2.OperationalError: could not translate host name "postgres" to address: Temporary failure in name resolution


The above exception was the direct cause of the following exception:

Traceback (most recent call last):
  File "/home/airflow/.local/lib/python3.11/site-packages/airflow/jobs/job.py", line 207, in heartbeat
    self._merge_from(Job._fetch_from_db(self, session))
                     ^^^^^^^^^^^^^^^^^^^^^^^^^^^^^^^^^
  File "/home/airflow/.local/lib/python3.11/site-packages/airflow/api_internal/internal_api_call.py", line 166, in wrapper
    return func(*args, **kwargs)
           ^^^^^^^^^^^^^^^^^^^^^
  File "/home/airflow/.local/lib/python3.11/site-packages/airflow/utils/session.py", line 94, in wrapper
    return func(*args, **kwargs)
           ^^^^^^^^^^^^^^^^^^^^^
  File "/home/airflow/.local/lib/python3.11/site-packages/airflow/utils/retries.py", line 93, in wrapped_function
    for attempt in run_with_db_retries(max_retries=retries, logger=logger, **retry_kwargs):
  File "/home/airflow/.local/lib/python3.11/site-packages/tenacity/__init__.py", line 443, in __iter__
    do = self.iter(retry_state=retry_state)
         ^^^^^^^^^^^^^^^^^^^^^^^^^^^^^^^^^^
  File "/home/airflow/.local/lib/python3.11/site-packages/tenacity/__init__.py", line 376, in iter
    result = action(retry_state)
             ^^^^^^^^^^^^^^^^^^^
  File "/home/airflow/.local/lib/python3.11/site-packages/tenacity/__init__.py", line 418, in exc_check
    raise retry_exc.reraise()
          ^^^^^^^^^^^^^^^^^^^
  File "/home/airflow/.local/lib/python3.11/site-packages/tenacity/__init__.py", line 185, in reraise
    raise self.last_attempt.result()
          ^^^^^^^^^^^^^^^^^^^^^^^^^^
  File "/usr/local/lib/python3.11/concurrent/futures/_base.py", line 449, in result
    return self.__get_result()
           ^^^^^^^^^^^^^^^^^^^
  File "/usr/local/lib/python3.11/concurrent/futures/_base.py", line 401, in __get_result
    raise self._exception
  File "/home/airflow/.local/lib/python3.11/site-packages/airflow/utils/retries.py", line 102, in wrapped_function
    return func(*args, **kwargs)
           ^^^^^^^^^^^^^^^^^^^^^
  File "/home/airflow/.local/lib/python3.11/site-packages/airflow/jobs/job.py", line 335, in _fetch_from_db
    session.merge(job)
  File "/home/airflow/.local/lib/python3.11/site-packages/sqlalchemy/orm/session.py", line 3056, in merge
    return self._merge(
           ^^^^^^^^^^^^
  File "/home/airflow/.local/lib/python3.11/site-packages/sqlalchemy/orm/session.py", line 3136, in _merge
    merged = self.get(
             ^^^^^^^^^
  File "/home/airflow/.local/lib/python3.11/site-packages/sqlalchemy/orm/session.py", line 2853, in get
    return self._get_impl(
           ^^^^^^^^^^^^^^^
  File "/home/airflow/.local/lib/python3.11/site-packages/sqlalchemy/orm/session.py", line 2975, in _get_impl
    return db_load_fn(
           ^^^^^^^^^^^
  File "/home/airflow/.local/lib/python3.11/site-packages/sqlalchemy/orm/loading.py", line 530, in load_on_pk_identity
    session.execute(
  File "/home/airflow/.local/lib/python3.11/site-packages/sqlalchemy/orm/session.py", line 1716, in execute
    conn = self._connection_for_bind(bind)
           ^^^^^^^^^^^^^^^^^^^^^^^^^^^^^^^
  File "/home/airflow/.local/lib/python3.11/site-packages/sqlalchemy/orm/session.py", line 1555, in _connection_for_bind
    return self._transaction._connection_for_bind(
           ^^^^^^^^^^^^^^^^^^^^^^^^^^^^^^^^^^^^^^^
  File "/home/airflow/.local/lib/python3.11/site-packages/sqlalchemy/orm/session.py", line 750, in _connection_for_bind
    conn = bind.connect()
           ^^^^^^^^^^^^^^
  File "/home/airflow/.local/lib/python3.11/site-packages/sqlalchemy/future/engine.py", line 412, in connect
    return super(Engine, self).connect()
           ^^^^^^^^^^^^^^^^^^^^^^^^^^^^^
  File "/home/airflow/.local/lib/python3.11/site-packages/sqlalchemy/engine/base.py", line 3325, in connect
    return self._connection_cls(self, close_with_result=close_with_result)
           ^^^^^^^^^^^^^^^^^^^^^^^^^^^^^^^^^^^^^^^^^^^^^^^^^^^^^^^^^^^^^^^
  File "/home/airflow/.local/lib/python3.11/site-packages/sqlalchemy/engine/base.py", line 96, in __init__
    else engine.raw_connection()
         ^^^^^^^^^^^^^^^^^^^^^^^
  File "/home/airflow/.local/lib/python3.11/site-packages/sqlalchemy/engine/base.py", line 3404, in raw_connection
    return self._wrap_pool_connect(self.pool.connect, _connection)
           ^^^^^^^^^^^^^^^^^^^^^^^^^^^^^^^^^^^^^^^^^^^^^^^^^^^^^^^
  File "/home/airflow/.local/lib/python3.11/site-packages/sqlalchemy/engine/base.py", line 3374, in _wrap_pool_connect
    Connection._handle_dbapi_exception_noconnection(
  File "/home/airflow/.local/lib/python3.11/site-packages/sqlalchemy/engine/base.py", line 2208, in _handle_dbapi_exception_noconnection
    util.raise_(
  File "/home/airflow/.local/lib/python3.11/site-packages/sqlalchemy/util/compat.py", line 211, in raise_
    raise exception
  File "/home/airflow/.local/lib/python3.11/site-packages/sqlalchemy/engine/base.py", line 3371, in _wrap_pool_connect
    return fn()
           ^^^^
  File "/home/airflow/.local/lib/python3.11/site-packages/sqlalchemy/pool/base.py", line 327, in connect
    return _ConnectionFairy._checkout(self)
           ^^^^^^^^^^^^^^^^^^^^^^^^^^^^^^^^
  File "/home/airflow/.local/lib/python3.11/site-packages/sqlalchemy/pool/base.py", line 894, in _checkout
    fairy = _ConnectionRecord.checkout(pool)
            ^^^^^^^^^^^^^^^^^^^^^^^^^^^^^^^^
  File "/home/airflow/.local/lib/python3.11/site-packages/sqlalchemy/pool/base.py", line 493, in checkout
    rec = pool._do_get()
          ^^^^^^^^^^^^^^
  File "/home/airflow/.local/lib/python3.11/site-packages/sqlalchemy/pool/impl.py", line 256, in _do_get
    return self._create_connection()
           ^^^^^^^^^^^^^^^^^^^^^^^^^
  File "/home/airflow/.local/lib/python3.11/site-packages/sqlalchemy/pool/base.py", line 273, in _create_connection
    return _ConnectionRecord(self)
           ^^^^^^^^^^^^^^^^^^^^^^^
  File "/home/airflow/.local/lib/python3.11/site-packages/sqlalchemy/pool/base.py", line 388, in __init__
    self.__connect()
  File "/home/airflow/.local/lib/python3.11/site-packages/sqlalchemy/pool/base.py", line 690, in __connect
    with util.safe_reraise():
  File "/home/airflow/.local/lib/python3.11/site-packages/sqlalchemy/util/langhelpers.py", line 70, in __exit__
    compat.raise_(
  File "/home/airflow/.local/lib/python3.11/site-packages/sqlalchemy/util/compat.py", line 211, in raise_
    raise exception
  File "/home/airflow/.local/lib/python3.11/site-packages/sqlalchemy/pool/base.py", line 686, in __connect
    self.dbapi_connection = connection = pool._invoke_creator(self)
                                         ^^^^^^^^^^^^^^^^^^^^^^^^^^
  File "/home/airflow/.local/lib/python3.11/site-packages/sqlalchemy/engine/create.py", line 574, in connect
    return dialect.connect(*cargs, **cparams)
           ^^^^^^^^^^^^^^^^^^^^^^^^^^^^^^^^^^
  File "/home/airflow/.local/lib/python3.11/site-packages/sqlalchemy/engine/default.py", line 598, in connect
    return self.dbapi.connect(*cargs, **cparams)
           ^^^^^^^^^^^^^^^^^^^^^^^^^^^^^^^^^^^^^
  File "/home/airflow/venv/lib/python3.11/site-packages/psycopg2/__init__.py", line 122, in connect
    conn = _connect(dsn, connection_factory=connection_factory, **kwasync)
           ^^^^^^^^^^^^^^^^^^^^^^^^^^^^^^^^^^^^^^^^^^^^^^^^^^^^^^^^^^^^^^^
sqlalchemy.exc.OperationalError: (psycopg2.OperationalError) could not translate host name "postgres" to address: Temporary failure in name resolution

(Background on this error at: https://sqlalche.me/e/14/e3q8)
[2025-07-18T18:50:25.112+0000] {job.py:254} ERROR - Job heartbeat failed with error. Scheduler is in unhealthy state
[2025-07-18T18:50:32.960+0000] {scraper_banks.py:370} INFO - ‚úÖ Cr√©dit du Maroc (agence Cr√©dit du Maroc 40 Rue 18)
[2025-07-18T18:50:34.512+0000] {scraper_banks.py:370} INFO - ‚úÖ Soci√©t√© G√©n√©rale, Agence Casablanca, El Fida. (agence Soci√©t√© G√©n√©rale Maroc 321 Bd El Fida)
[2025-07-18T18:50:36.357+0000] {scraper_banks.py:372} INFO - üö´ Doublon ou donn√©es incompl√®tes : Banque Populaire Agence Hassan Seghir
[2025-07-18T18:50:37.819+0000] {scraper_banks.py:370} INFO - ‚úÖ Attijariwafa Bank Oued Eddahab Expansion (agence Attijariwafa Bank 352 avenue Makdad Lahrizi)
[2025-07-18T18:50:38.271+0000] {job.py:229} INFO - Heartbeat recovered after 51.22 seconds
[2025-07-18T18:50:39.240+0000] {scraper_banks.py:370} INFO - ‚úÖ Attijari Wafabank (agence Attijari Finances Corp. HCV6+J97 Rue Planquette)
[2025-07-18T18:50:40.700+0000] {scraper_banks.py:372} INFO - üö´ Doublon ou donn√©es incompl√®tes : CFG Bank - Agence Casa Racine
[2025-07-18T18:50:42.209+0000] {scraper_banks.py:370} INFO - ‚úÖ Banque Populaire Mabrouka (agence Banque Populaire Sothmane 37 Bd du Nil)
[2025-07-18T18:50:43.258+0000] {scraper_banks.py:370} INFO - ‚úÖ Banque Populaire (agence Banque Populaire HCH2+62M R315)
[2025-07-18T18:50:58.105+0000] {scraper_banks.py:370} INFO - ‚úÖ Attijari wafa bank (agence Attijari International Bank HC6Q+499 20670 Av du 10 Mars 1982)
[2025-07-18T18:51:11.274+0000] {scraper_banks.py:372} INFO - üö´ Doublon ou donn√©es incompl√®tes : Attijariwafa Bank (Si√®ge Social)
[2025-07-18T18:51:16.507+0000] {job.py:239} ERROR - Job heartbeat failed with error
Traceback (most recent call last):
  File "/home/airflow/.local/lib/python3.11/site-packages/sqlalchemy/engine/base.py", line 3371, in _wrap_pool_connect
    return fn()
           ^^^^
  File "/home/airflow/.local/lib/python3.11/site-packages/sqlalchemy/pool/base.py", line 327, in connect
    return _ConnectionFairy._checkout(self)
           ^^^^^^^^^^^^^^^^^^^^^^^^^^^^^^^^
  File "/home/airflow/.local/lib/python3.11/site-packages/sqlalchemy/pool/base.py", line 894, in _checkout
    fairy = _ConnectionRecord.checkout(pool)
            ^^^^^^^^^^^^^^^^^^^^^^^^^^^^^^^^
  File "/home/airflow/.local/lib/python3.11/site-packages/sqlalchemy/pool/base.py", line 493, in checkout
    rec = pool._do_get()
          ^^^^^^^^^^^^^^
  File "/home/airflow/.local/lib/python3.11/site-packages/sqlalchemy/pool/impl.py", line 256, in _do_get
    return self._create_connection()
           ^^^^^^^^^^^^^^^^^^^^^^^^^
  File "/home/airflow/.local/lib/python3.11/site-packages/sqlalchemy/pool/base.py", line 273, in _create_connection
    return _ConnectionRecord(self)
           ^^^^^^^^^^^^^^^^^^^^^^^
  File "/home/airflow/.local/lib/python3.11/site-packages/sqlalchemy/pool/base.py", line 388, in __init__
    self.__connect()
  File "/home/airflow/.local/lib/python3.11/site-packages/sqlalchemy/pool/base.py", line 690, in __connect
    with util.safe_reraise():
  File "/home/airflow/.local/lib/python3.11/site-packages/sqlalchemy/util/langhelpers.py", line 70, in __exit__
    compat.raise_(
  File "/home/airflow/.local/lib/python3.11/site-packages/sqlalchemy/util/compat.py", line 211, in raise_
    raise exception
  File "/home/airflow/.local/lib/python3.11/site-packages/sqlalchemy/pool/base.py", line 686, in __connect
    self.dbapi_connection = connection = pool._invoke_creator(self)
                                         ^^^^^^^^^^^^^^^^^^^^^^^^^^
  File "/home/airflow/.local/lib/python3.11/site-packages/sqlalchemy/engine/create.py", line 574, in connect
    return dialect.connect(*cargs, **cparams)
           ^^^^^^^^^^^^^^^^^^^^^^^^^^^^^^^^^^
  File "/home/airflow/.local/lib/python3.11/site-packages/sqlalchemy/engine/default.py", line 598, in connect
    return self.dbapi.connect(*cargs, **cparams)
           ^^^^^^^^^^^^^^^^^^^^^^^^^^^^^^^^^^^^^
  File "/home/airflow/venv/lib/python3.11/site-packages/psycopg2/__init__.py", line 122, in connect
    conn = _connect(dsn, connection_factory=connection_factory, **kwasync)
           ^^^^^^^^^^^^^^^^^^^^^^^^^^^^^^^^^^^^^^^^^^^^^^^^^^^^^^^^^^^^^^^
psycopg2.OperationalError: could not translate host name "postgres" to address: Temporary failure in name resolution


The above exception was the direct cause of the following exception:

Traceback (most recent call last):
  File "/home/airflow/.local/lib/python3.11/site-packages/airflow/jobs/job.py", line 207, in heartbeat
    self._merge_from(Job._fetch_from_db(self, session))
                     ^^^^^^^^^^^^^^^^^^^^^^^^^^^^^^^^^
  File "/home/airflow/.local/lib/python3.11/site-packages/airflow/api_internal/internal_api_call.py", line 166, in wrapper
    return func(*args, **kwargs)
           ^^^^^^^^^^^^^^^^^^^^^
  File "/home/airflow/.local/lib/python3.11/site-packages/airflow/utils/session.py", line 94, in wrapper
    return func(*args, **kwargs)
           ^^^^^^^^^^^^^^^^^^^^^
  File "/home/airflow/.local/lib/python3.11/site-packages/airflow/utils/retries.py", line 93, in wrapped_function
    for attempt in run_with_db_retries(max_retries=retries, logger=logger, **retry_kwargs):
  File "/home/airflow/.local/lib/python3.11/site-packages/tenacity/__init__.py", line 443, in __iter__
    do = self.iter(retry_state=retry_state)
         ^^^^^^^^^^^^^^^^^^^^^^^^^^^^^^^^^^
  File "/home/airflow/.local/lib/python3.11/site-packages/tenacity/__init__.py", line 376, in iter
    result = action(retry_state)
             ^^^^^^^^^^^^^^^^^^^
  File "/home/airflow/.local/lib/python3.11/site-packages/tenacity/__init__.py", line 418, in exc_check
    raise retry_exc.reraise()
          ^^^^^^^^^^^^^^^^^^^
  File "/home/airflow/.local/lib/python3.11/site-packages/tenacity/__init__.py", line 185, in reraise
    raise self.last_attempt.result()
          ^^^^^^^^^^^^^^^^^^^^^^^^^^
  File "/usr/local/lib/python3.11/concurrent/futures/_base.py", line 449, in result
    return self.__get_result()
           ^^^^^^^^^^^^^^^^^^^
  File "/usr/local/lib/python3.11/concurrent/futures/_base.py", line 401, in __get_result
    raise self._exception
  File "/home/airflow/.local/lib/python3.11/site-packages/airflow/utils/retries.py", line 102, in wrapped_function
    return func(*args, **kwargs)
           ^^^^^^^^^^^^^^^^^^^^^
  File "/home/airflow/.local/lib/python3.11/site-packages/airflow/jobs/job.py", line 335, in _fetch_from_db
    session.merge(job)
  File "/home/airflow/.local/lib/python3.11/site-packages/sqlalchemy/orm/session.py", line 3056, in merge
    return self._merge(
           ^^^^^^^^^^^^
  File "/home/airflow/.local/lib/python3.11/site-packages/sqlalchemy/orm/session.py", line 3136, in _merge
    merged = self.get(
             ^^^^^^^^^
  File "/home/airflow/.local/lib/python3.11/site-packages/sqlalchemy/orm/session.py", line 2853, in get
    return self._get_impl(
           ^^^^^^^^^^^^^^^
  File "/home/airflow/.local/lib/python3.11/site-packages/sqlalchemy/orm/session.py", line 2975, in _get_impl
    return db_load_fn(
           ^^^^^^^^^^^
  File "/home/airflow/.local/lib/python3.11/site-packages/sqlalchemy/orm/loading.py", line 530, in load_on_pk_identity
    session.execute(
  File "/home/airflow/.local/lib/python3.11/site-packages/sqlalchemy/orm/session.py", line 1716, in execute
    conn = self._connection_for_bind(bind)
           ^^^^^^^^^^^^^^^^^^^^^^^^^^^^^^^
  File "/home/airflow/.local/lib/python3.11/site-packages/sqlalchemy/orm/session.py", line 1555, in _connection_for_bind
    return self._transaction._connection_for_bind(
           ^^^^^^^^^^^^^^^^^^^^^^^^^^^^^^^^^^^^^^^
  File "/home/airflow/.local/lib/python3.11/site-packages/sqlalchemy/orm/session.py", line 750, in _connection_for_bind
    conn = bind.connect()
           ^^^^^^^^^^^^^^
  File "/home/airflow/.local/lib/python3.11/site-packages/sqlalchemy/future/engine.py", line 412, in connect
    return super(Engine, self).connect()
           ^^^^^^^^^^^^^^^^^^^^^^^^^^^^^
  File "/home/airflow/.local/lib/python3.11/site-packages/sqlalchemy/engine/base.py", line 3325, in connect
    return self._connection_cls(self, close_with_result=close_with_result)
           ^^^^^^^^^^^^^^^^^^^^^^^^^^^^^^^^^^^^^^^^^^^^^^^^^^^^^^^^^^^^^^^
  File "/home/airflow/.local/lib/python3.11/site-packages/sqlalchemy/engine/base.py", line 96, in __init__
    else engine.raw_connection()
         ^^^^^^^^^^^^^^^^^^^^^^^
  File "/home/airflow/.local/lib/python3.11/site-packages/sqlalchemy/engine/base.py", line 3404, in raw_connection
    return self._wrap_pool_connect(self.pool.connect, _connection)
           ^^^^^^^^^^^^^^^^^^^^^^^^^^^^^^^^^^^^^^^^^^^^^^^^^^^^^^^
  File "/home/airflow/.local/lib/python3.11/site-packages/sqlalchemy/engine/base.py", line 3374, in _wrap_pool_connect
    Connection._handle_dbapi_exception_noconnection(
  File "/home/airflow/.local/lib/python3.11/site-packages/sqlalchemy/engine/base.py", line 2208, in _handle_dbapi_exception_noconnection
    util.raise_(
  File "/home/airflow/.local/lib/python3.11/site-packages/sqlalchemy/util/compat.py", line 211, in raise_
    raise exception
  File "/home/airflow/.local/lib/python3.11/site-packages/sqlalchemy/engine/base.py", line 3371, in _wrap_pool_connect
    return fn()
           ^^^^
  File "/home/airflow/.local/lib/python3.11/site-packages/sqlalchemy/pool/base.py", line 327, in connect
    return _ConnectionFairy._checkout(self)
           ^^^^^^^^^^^^^^^^^^^^^^^^^^^^^^^^
  File "/home/airflow/.local/lib/python3.11/site-packages/sqlalchemy/pool/base.py", line 894, in _checkout
    fairy = _ConnectionRecord.checkout(pool)
            ^^^^^^^^^^^^^^^^^^^^^^^^^^^^^^^^
  File "/home/airflow/.local/lib/python3.11/site-packages/sqlalchemy/pool/base.py", line 493, in checkout
    rec = pool._do_get()
          ^^^^^^^^^^^^^^
  File "/home/airflow/.local/lib/python3.11/site-packages/sqlalchemy/pool/impl.py", line 256, in _do_get
    return self._create_connection()
           ^^^^^^^^^^^^^^^^^^^^^^^^^
  File "/home/airflow/.local/lib/python3.11/site-packages/sqlalchemy/pool/base.py", line 273, in _create_connection
    return _ConnectionRecord(self)
           ^^^^^^^^^^^^^^^^^^^^^^^
  File "/home/airflow/.local/lib/python3.11/site-packages/sqlalchemy/pool/base.py", line 388, in __init__
    self.__connect()
  File "/home/airflow/.local/lib/python3.11/site-packages/sqlalchemy/pool/base.py", line 690, in __connect
    with util.safe_reraise():
  File "/home/airflow/.local/lib/python3.11/site-packages/sqlalchemy/util/langhelpers.py", line 70, in __exit__
    compat.raise_(
  File "/home/airflow/.local/lib/python3.11/site-packages/sqlalchemy/util/compat.py", line 211, in raise_
    raise exception
  File "/home/airflow/.local/lib/python3.11/site-packages/sqlalchemy/pool/base.py", line 686, in __connect
    self.dbapi_connection = connection = pool._invoke_creator(self)
                                         ^^^^^^^^^^^^^^^^^^^^^^^^^^
  File "/home/airflow/.local/lib/python3.11/site-packages/sqlalchemy/engine/create.py", line 574, in connect
    return dialect.connect(*cargs, **cparams)
           ^^^^^^^^^^^^^^^^^^^^^^^^^^^^^^^^^^
  File "/home/airflow/.local/lib/python3.11/site-packages/sqlalchemy/engine/default.py", line 598, in connect
    return self.dbapi.connect(*cargs, **cparams)
           ^^^^^^^^^^^^^^^^^^^^^^^^^^^^^^^^^^^^^
  File "/home/airflow/venv/lib/python3.11/site-packages/psycopg2/__init__.py", line 122, in connect
    conn = _connect(dsn, connection_factory=connection_factory, **kwasync)
           ^^^^^^^^^^^^^^^^^^^^^^^^^^^^^^^^^^^^^^^^^^^^^^^^^^^^^^^^^^^^^^^
sqlalchemy.exc.OperationalError: (psycopg2.OperationalError) could not translate host name "postgres" to address: Temporary failure in name resolution

(Background on this error at: https://sqlalche.me/e/14/e3q8)
[2025-07-18T18:51:16.642+0000] {job.py:254} ERROR - Job heartbeat failed with error. Scheduler is in unhealthy state
[2025-07-18T18:51:18.133+0000] {scraper_banks.py:370} INFO - ‚úÖ Bank Popular ÿßŸÑÿ®ŸÜŸÉ ÿßŸÑÿ¥ÿπÿ®Ÿä (agence ÿßŸÑÿ®ŸÜŸÉ ÿßŸÑÿ¥ÿπÿ®Ÿä HCV4+X3J)
[2025-07-18T18:51:19.694+0000] {scraper_banks.py:372} INFO - üö´ Doublon ou donn√©es incompl√®tes : Banque Populaire Hay Sadri
[2025-07-18T18:51:20.634+0000] {scraper_banks.py:372} INFO - üö´ Doublon ou donn√©es incompl√®tes : Bank Al Karam_Si√®ge Social
[2025-07-18T18:51:21.344+0000] {scraper_banks.py:372} INFO - üö´ Doublon ou donn√©es incompl√®tes : Banque Populaire Agence Lalla Yacout
[2025-07-18T18:51:22.962+0000] {scraper_banks.py:370} INFO - ‚úÖ CIH BANK (agence CIH Bank Ang Bd Oqba Bnou Nafii Bd Ibn Tachfine rue 16)
[2025-07-18T18:51:23.196+0000] {job.py:229} INFO - Heartbeat recovered after 45.12 seconds
[2025-07-18T18:51:23.748+0000] {scraper_banks.py:370} INFO - ‚úÖ Attijariwafa Bank Libert√© (agence Attijariwafa Bank 10 Bd de la Libert√©)
[2025-07-18T18:51:24.472+0000] {scraper_banks.py:372} INFO - üö´ Doublon ou donn√©es incompl√®tes : BANK OF AFRICA LALLA YACOUT PART/PRO
[2025-07-18T18:51:25.166+0000] {scraper_banks.py:370} INFO - ‚úÖ Attijari Wafabank (agence Attijari Finances Corp. H947+GVH)
[2025-07-18T18:51:25.665+0000] {scraper_banks.py:372} INFO - üö´ Doublon ou donn√©es incompl√®tes : Banque Populaire Smara
[2025-07-18T18:51:26.088+0000] {scraper_banks.py:370} INFO - ‚úÖ Banque populaire Ibn Tachfine (agence Banque Populaire HCP9+4WP Rue Zineb Ishak)
[2025-07-18T18:51:26.572+0000] {scraper_banks.py:372} INFO - üö´ Doublon ou donn√©es incompl√®tes : Banque Populaire Moulay Youssef
[2025-07-18T18:51:27.018+0000] {scraper_banks.py:370} INFO - ‚úÖ CFG Bank - GAB h√¥tel Kenzi Tower (agence CFG Bank Twin Center Bd Mohammed Zerktouni)
[2025-07-18T18:51:27.645+0000] {scraper_banks.py:372} INFO - üö´ Doublon ou donn√©es incompl√®tes : Societe Generale Maroc (SGMA) - SG Securities Services
[2025-07-18T18:51:28.255+0000] {scraper_banks.py:372} INFO - üö´ Doublon ou donn√©es incompl√®tes : Banque Populaire Hay Masjid
[2025-07-18T18:51:28.852+0000] {scraper_banks.py:370} INFO - ‚úÖ AL BARID BANK Bd Panoramique (AL BARID BANK Bd Panoramique)
[2025-07-18T18:51:29.562+0000] {scraper_banks.py:372} INFO - üö´ Doublon ou donn√©es incompl√®tes : Attijariwafa bank
[2025-07-18T18:51:30.088+0000] {scraper_banks.py:370} INFO - ‚úÖ Al Akhdar Bank (agence Al Akhdar Bank 0520-481726)
[2025-07-18T18:51:30.875+0000] {scraper_banks.py:370} INFO - ‚úÖ Cr√©dit Agricole (agence Cr√©dit Agricole du Maroc 138 Boulevard Aba Chouaib Doukkali El Jadida)
[2025-07-18T18:51:31.476+0000] {scraper_banks.py:372} INFO - üö´ Doublon ou donn√©es incompl√®tes : Bank Of Africa, Agence Al Massira, Maarif.
[2025-07-18T18:51:31.863+0000] {scraper_banks.py:372} INFO - üö´ Doublon ou donn√©es incompl√®tes : Banque Populaire
[2025-07-18T18:51:32.443+0000] {scraper_banks.py:372} INFO - üö´ Doublon ou donn√©es incompl√®tes : Attijariwafa Bank
[2025-07-18T18:51:32.857+0000] {scraper_banks.py:370} INFO - ‚úÖ CIH Bank (Agence Casa Korea) (agence CIH Bank 13 Bd Abou Chouaib Doukkali)
[2025-07-18T18:51:33.163+0000] {scraper_banks.py:370} INFO - ‚úÖ Al Barid Bank (agence Al Barid Bank JC28+7QF Bd Amr Ibnou Ass)
[2025-07-18T18:51:33.520+0000] {scraper_banks.py:370} INFO - ‚úÖ Umnia Bank Casablanca Derb Sultan (agence Umnia Bank Quartier Boujdour Place DAMAS)
[2025-07-18T18:51:33.904+0000] {scraper_banks.py:372} INFO - üö´ Doublon ou donn√©es incompl√®tes : Banque Populaire
[2025-07-18T18:51:34.291+0000] {scraper_banks.py:370} INFO - ‚úÖ BANK OF AFRICA (agence Bank of Africa GCRH+H6W Bd Oued Ad Dahab)
[2025-07-18T18:51:34.576+0000] {scraper_banks.py:370} INFO - ‚úÖ Al Barid Bank, Agence La Gare, Roches Noires. (agence Al Barid Bank Place Prince Sidi Mohamed)
[2025-07-18T18:51:34.894+0000] {scraper_banks.py:372} INFO - üö´ Doublon ou donn√©es incompl√®tes : Banque Populaire Sahraoui
[2025-07-18T18:51:35.217+0000] {scraper_banks.py:370} INFO - ‚úÖ BANK OF AFRICA (agence Bank of Africa H9GF+HJ5)
[2025-07-18T18:51:35.516+0000] {scraper_banks.py:372} INFO - üö´ Doublon ou donn√©es incompl√®tes : Banque Populaire
[2025-07-18T18:51:35.972+0000] {scraper_banks.py:370} INFO - ‚úÖ ATTIJARI WAFABANK (agence Attijari Finances Corp. 129 Av Colonel Driss El Allam)
[2025-07-18T18:51:36.464+0000] {scraper_banks.py:372} INFO - üö´ Doublon ou donn√©es incompl√®tes : Attijariwafa Bank
[2025-07-18T18:51:36.785+0000] {scraper_banks.py:372} INFO - üö´ Doublon ou donn√©es incompl√®tes : Banque Populaire - Al Baida
[2025-07-18T18:51:37.253+0000] {scraper_banks.py:372} INFO - üö´ Doublon ou donn√©es incompl√®tes : CIH BANK
[2025-07-18T18:51:37.793+0000] {scraper_banks.py:372} INFO - üö´ Doublon ou donn√©es incompl√®tes : Banque Populaire Ouled Ziane
[2025-07-18T18:51:38.969+0000] {scraper_banks.py:372} INFO - üö´ Doublon ou donn√©es incompl√®tes : Banque Populaire Ain Borja
[2025-07-18T18:51:39.906+0000] {scraper_banks.py:370} INFO - ‚úÖ banque populaire (agence Banque Populaire HCVJ+J5V Bd Ecchouhada)
[2025-07-18T18:51:41.610+0000] {scraper_banks.py:370} INFO - ‚úÖ Banque populaire (agence Banque Populaire 36 Bd Emile Zola)
[2025-07-18T18:51:42.585+0000] {scraper_banks.py:370} INFO - ‚úÖ Banque Populaire Inara (agence Banque Populaire GCQ2+RJG Bd El Qods)
[2025-07-18T18:51:43.336+0000] {scraper_banks.py:372} INFO - üö´ Doublon ou donn√©es incompl√®tes : Attijariwafa Bank
[2025-07-18T18:51:43.968+0000] {scraper_banks.py:370} INFO - ‚úÖ Attijariwafa Bank (agence Attijariwafa Bank 724 Av du 6 Novembre 1975)
[2025-07-18T18:51:44.967+0000] {scraper_banks.py:370} INFO - ‚úÖ CIH Bank (agence CIH Bank Bd Mohamed VIÿå Rue Florac)
[2025-07-18T18:51:45.496+0000] {scraper_banks.py:370} INFO - ‚úÖ Banque populaire (agence Banque Populaire 58 Bd Moulay Idriss I)
[2025-07-18T18:51:45.872+0000] {scraper_banks.py:370} INFO - ‚úÖ Atijariwafa Bank (agence Bank Al-Maghrib 65 Bd Moulay Ismail Bd Moulay Isma√Øl)
[2025-07-18T18:51:46.225+0000] {scraper_banks.py:370} INFO - ‚úÖ BANK OF AFRICA (agence Bank of Africa 37 Av 2 Mars)
[2025-07-18T18:51:46.696+0000] {scraper_banks.py:370} INFO - ‚úÖ Cr√©dit du Maroc (agence Cr√©dit du Maroc 436 Angle avenue 6 novembre et avenue du Nil Sbata)
[2025-07-18T18:51:47.151+0000] {scraper_banks.py:370} INFO - ‚úÖ CIH (agence CIH Bank Rue Mohamed El Radi Slaoui)
[2025-07-18T18:51:47.153+0000] {scraper_banks.py:378} INFO - [Casablanca] 50 banques enregistr√©es
[2025-07-18T18:51:47.155+0000] {scraper_banks.py:379} INFO - ‚úÖ [Casablanca] Extraction termin√©e
[2025-07-18T18:51:50.177+0000] {logger.py:11} INFO - ====== WebDriver manager ======
[2025-07-18T18:51:51.048+0000] {logger.py:11} INFO - Get LATEST chromedriver version for google-chrome
[2025-07-18T18:51:52.293+0000] {logger.py:11} INFO - Get LATEST chromedriver version for google-chrome
[2025-07-18T18:51:52.720+0000] {logger.py:11} INFO - Driver [/home/***/.wdm/drivers/chromedriver/linux64/138.0.7204.157/chromedriver-linux64/chromedriver] found in cache
[2025-07-18T18:52:05.106+0000] {scraper_banks.py:269} INFO - 
üìç Initialisation pour Casablanca...
[2025-07-18T18:52:10.584+0000] {job.py:239} ERROR - Job heartbeat failed with error
Traceback (most recent call last):
  File "/home/airflow/.local/lib/python3.11/site-packages/sqlalchemy/engine/base.py", line 3371, in _wrap_pool_connect
    return fn()
           ^^^^
  File "/home/airflow/.local/lib/python3.11/site-packages/sqlalchemy/pool/base.py", line 327, in connect
    return _ConnectionFairy._checkout(self)
           ^^^^^^^^^^^^^^^^^^^^^^^^^^^^^^^^
  File "/home/airflow/.local/lib/python3.11/site-packages/sqlalchemy/pool/base.py", line 894, in _checkout
    fairy = _ConnectionRecord.checkout(pool)
            ^^^^^^^^^^^^^^^^^^^^^^^^^^^^^^^^
  File "/home/airflow/.local/lib/python3.11/site-packages/sqlalchemy/pool/base.py", line 493, in checkout
    rec = pool._do_get()
          ^^^^^^^^^^^^^^
  File "/home/airflow/.local/lib/python3.11/site-packages/sqlalchemy/pool/impl.py", line 256, in _do_get
    return self._create_connection()
           ^^^^^^^^^^^^^^^^^^^^^^^^^
  File "/home/airflow/.local/lib/python3.11/site-packages/sqlalchemy/pool/base.py", line 273, in _create_connection
    return _ConnectionRecord(self)
           ^^^^^^^^^^^^^^^^^^^^^^^
  File "/home/airflow/.local/lib/python3.11/site-packages/sqlalchemy/pool/base.py", line 388, in __init__
    self.__connect()
  File "/home/airflow/.local/lib/python3.11/site-packages/sqlalchemy/pool/base.py", line 690, in __connect
    with util.safe_reraise():
  File "/home/airflow/.local/lib/python3.11/site-packages/sqlalchemy/util/langhelpers.py", line 70, in __exit__
    compat.raise_(
  File "/home/airflow/.local/lib/python3.11/site-packages/sqlalchemy/util/compat.py", line 211, in raise_
    raise exception
  File "/home/airflow/.local/lib/python3.11/site-packages/sqlalchemy/pool/base.py", line 686, in __connect
    self.dbapi_connection = connection = pool._invoke_creator(self)
                                         ^^^^^^^^^^^^^^^^^^^^^^^^^^
  File "/home/airflow/.local/lib/python3.11/site-packages/sqlalchemy/engine/create.py", line 574, in connect
    return dialect.connect(*cargs, **cparams)
           ^^^^^^^^^^^^^^^^^^^^^^^^^^^^^^^^^^
  File "/home/airflow/.local/lib/python3.11/site-packages/sqlalchemy/engine/default.py", line 598, in connect
    return self.dbapi.connect(*cargs, **cparams)
           ^^^^^^^^^^^^^^^^^^^^^^^^^^^^^^^^^^^^^
  File "/home/airflow/venv/lib/python3.11/site-packages/psycopg2/__init__.py", line 122, in connect
    conn = _connect(dsn, connection_factory=connection_factory, **kwasync)
           ^^^^^^^^^^^^^^^^^^^^^^^^^^^^^^^^^^^^^^^^^^^^^^^^^^^^^^^^^^^^^^^
psycopg2.OperationalError: could not translate host name "postgres" to address: Temporary failure in name resolution


The above exception was the direct cause of the following exception:

Traceback (most recent call last):
  File "/home/airflow/.local/lib/python3.11/site-packages/airflow/jobs/job.py", line 233, in heartbeat
    heartbeat_callback(session)
  File "/home/airflow/.local/lib/python3.11/site-packages/airflow/utils/session.py", line 94, in wrapper
    return func(*args, **kwargs)
           ^^^^^^^^^^^^^^^^^^^^^
  File "/home/airflow/.local/lib/python3.11/site-packages/airflow/jobs/local_task_job_runner.py", line 284, in heartbeat_callback
    self.task_instance.refresh_from_db()
  File "/home/airflow/.local/lib/python3.11/site-packages/airflow/utils/session.py", line 97, in wrapper
    return func(*args, session=session, **kwargs)
           ^^^^^^^^^^^^^^^^^^^^^^^^^^^^^^^^^^^^^^
  File "/home/airflow/.local/lib/python3.11/site-packages/airflow/models/taskinstance.py", line 2360, in refresh_from_db
    _refresh_from_db(task_instance=self, session=session, lock_for_update=lock_for_update)
  File "/home/airflow/.local/lib/python3.11/site-packages/airflow/models/taskinstance.py", line 873, in _refresh_from_db
    ti = TaskInstance.get_task_instance(
         ^^^^^^^^^^^^^^^^^^^^^^^^^^^^^^^
  File "/home/airflow/.local/lib/python3.11/site-packages/airflow/api_internal/internal_api_call.py", line 166, in wrapper
    return func(*args, **kwargs)
           ^^^^^^^^^^^^^^^^^^^^^
  File "/home/airflow/.local/lib/python3.11/site-packages/airflow/utils/session.py", line 94, in wrapper
    return func(*args, **kwargs)
           ^^^^^^^^^^^^^^^^^^^^^
  File "/home/airflow/.local/lib/python3.11/site-packages/airflow/models/taskinstance.py", line 2346, in get_task_instance
    return query.one_or_none()
           ^^^^^^^^^^^^^^^^^^^
  File "/home/airflow/.local/lib/python3.11/site-packages/sqlalchemy/orm/query.py", line 2850, in one_or_none
    return self._iter().one_or_none()
           ^^^^^^^^^^^^
  File "/home/airflow/.local/lib/python3.11/site-packages/sqlalchemy/orm/query.py", line 2916, in _iter
    result = self.session.execute(
             ^^^^^^^^^^^^^^^^^^^^^
  File "/home/airflow/.local/lib/python3.11/site-packages/sqlalchemy/orm/session.py", line 1716, in execute
    conn = self._connection_for_bind(bind)
           ^^^^^^^^^^^^^^^^^^^^^^^^^^^^^^^
  File "/home/airflow/.local/lib/python3.11/site-packages/sqlalchemy/orm/session.py", line 1555, in _connection_for_bind
    return self._transaction._connection_for_bind(
           ^^^^^^^^^^^^^^^^^^^^^^^^^^^^^^^^^^^^^^^
  File "/home/airflow/.local/lib/python3.11/site-packages/sqlalchemy/orm/session.py", line 750, in _connection_for_bind
    conn = bind.connect()
           ^^^^^^^^^^^^^^
  File "/home/airflow/.local/lib/python3.11/site-packages/sqlalchemy/future/engine.py", line 412, in connect
    return super(Engine, self).connect()
           ^^^^^^^^^^^^^^^^^^^^^^^^^^^^^
  File "/home/airflow/.local/lib/python3.11/site-packages/sqlalchemy/engine/base.py", line 3325, in connect
    return self._connection_cls(self, close_with_result=close_with_result)
           ^^^^^^^^^^^^^^^^^^^^^^^^^^^^^^^^^^^^^^^^^^^^^^^^^^^^^^^^^^^^^^^
  File "/home/airflow/.local/lib/python3.11/site-packages/sqlalchemy/engine/base.py", line 96, in __init__
    else engine.raw_connection()
         ^^^^^^^^^^^^^^^^^^^^^^^
  File "/home/airflow/.local/lib/python3.11/site-packages/sqlalchemy/engine/base.py", line 3404, in raw_connection
    return self._wrap_pool_connect(self.pool.connect, _connection)
           ^^^^^^^^^^^^^^^^^^^^^^^^^^^^^^^^^^^^^^^^^^^^^^^^^^^^^^^
  File "/home/airflow/.local/lib/python3.11/site-packages/sqlalchemy/engine/base.py", line 3374, in _wrap_pool_connect
    Connection._handle_dbapi_exception_noconnection(
  File "/home/airflow/.local/lib/python3.11/site-packages/sqlalchemy/engine/base.py", line 2208, in _handle_dbapi_exception_noconnection
    util.raise_(
  File "/home/airflow/.local/lib/python3.11/site-packages/sqlalchemy/util/compat.py", line 211, in raise_
    raise exception
  File "/home/airflow/.local/lib/python3.11/site-packages/sqlalchemy/engine/base.py", line 3371, in _wrap_pool_connect
    return fn()
           ^^^^
  File "/home/airflow/.local/lib/python3.11/site-packages/sqlalchemy/pool/base.py", line 327, in connect
    return _ConnectionFairy._checkout(self)
           ^^^^^^^^^^^^^^^^^^^^^^^^^^^^^^^^
  File "/home/airflow/.local/lib/python3.11/site-packages/sqlalchemy/pool/base.py", line 894, in _checkout
    fairy = _ConnectionRecord.checkout(pool)
            ^^^^^^^^^^^^^^^^^^^^^^^^^^^^^^^^
  File "/home/airflow/.local/lib/python3.11/site-packages/sqlalchemy/pool/base.py", line 493, in checkout
    rec = pool._do_get()
          ^^^^^^^^^^^^^^
  File "/home/airflow/.local/lib/python3.11/site-packages/sqlalchemy/pool/impl.py", line 256, in _do_get
    return self._create_connection()
           ^^^^^^^^^^^^^^^^^^^^^^^^^
  File "/home/airflow/.local/lib/python3.11/site-packages/sqlalchemy/pool/base.py", line 273, in _create_connection
    return _ConnectionRecord(self)
           ^^^^^^^^^^^^^^^^^^^^^^^
  File "/home/airflow/.local/lib/python3.11/site-packages/sqlalchemy/pool/base.py", line 388, in __init__
    self.__connect()
  File "/home/airflow/.local/lib/python3.11/site-packages/sqlalchemy/pool/base.py", line 690, in __connect
    with util.safe_reraise():
  File "/home/airflow/.local/lib/python3.11/site-packages/sqlalchemy/util/langhelpers.py", line 70, in __exit__
    compat.raise_(
  File "/home/airflow/.local/lib/python3.11/site-packages/sqlalchemy/util/compat.py", line 211, in raise_
    raise exception
  File "/home/airflow/.local/lib/python3.11/site-packages/sqlalchemy/pool/base.py", line 686, in __connect
    self.dbapi_connection = connection = pool._invoke_creator(self)
                                         ^^^^^^^^^^^^^^^^^^^^^^^^^^
  File "/home/airflow/.local/lib/python3.11/site-packages/sqlalchemy/engine/create.py", line 574, in connect
    return dialect.connect(*cargs, **cparams)
           ^^^^^^^^^^^^^^^^^^^^^^^^^^^^^^^^^^
  File "/home/airflow/.local/lib/python3.11/site-packages/sqlalchemy/engine/default.py", line 598, in connect
    return self.dbapi.connect(*cargs, **cparams)
           ^^^^^^^^^^^^^^^^^^^^^^^^^^^^^^^^^^^^^
  File "/home/airflow/venv/lib/python3.11/site-packages/psycopg2/__init__.py", line 122, in connect
    conn = _connect(dsn, connection_factory=connection_factory, **kwasync)
           ^^^^^^^^^^^^^^^^^^^^^^^^^^^^^^^^^^^^^^^^^^^^^^^^^^^^^^^^^^^^^^^
sqlalchemy.exc.OperationalError: (psycopg2.OperationalError) could not translate host name "postgres" to address: Temporary failure in name resolution

(Background on this error at: https://sqlalche.me/e/14/e3q8)
[2025-07-18T18:52:13.493+0000] {job.py:254} ERROR - Job heartbeat failed with error. Scheduler is in unhealthy state
[2025-07-18T18:52:20.296+0000] {job.py:229} INFO - Heartbeat recovered after 19.82 seconds
[2025-07-18T18:52:35.049+0000] {job.py:229} INFO - Heartbeat recovered after 14.79 seconds
[2025-07-18T18:52:57.846+0000] {job.py:239} ERROR - Job heartbeat failed with error
Traceback (most recent call last):
  File "/home/airflow/.local/lib/python3.11/site-packages/sqlalchemy/engine/base.py", line 3371, in _wrap_pool_connect
    return fn()
           ^^^^
  File "/home/airflow/.local/lib/python3.11/site-packages/sqlalchemy/pool/base.py", line 327, in connect
    return _ConnectionFairy._checkout(self)
           ^^^^^^^^^^^^^^^^^^^^^^^^^^^^^^^^
  File "/home/airflow/.local/lib/python3.11/site-packages/sqlalchemy/pool/base.py", line 894, in _checkout
    fairy = _ConnectionRecord.checkout(pool)
            ^^^^^^^^^^^^^^^^^^^^^^^^^^^^^^^^
  File "/home/airflow/.local/lib/python3.11/site-packages/sqlalchemy/pool/base.py", line 493, in checkout
    rec = pool._do_get()
          ^^^^^^^^^^^^^^
  File "/home/airflow/.local/lib/python3.11/site-packages/sqlalchemy/pool/impl.py", line 256, in _do_get
    return self._create_connection()
           ^^^^^^^^^^^^^^^^^^^^^^^^^
  File "/home/airflow/.local/lib/python3.11/site-packages/sqlalchemy/pool/base.py", line 273, in _create_connection
    return _ConnectionRecord(self)
           ^^^^^^^^^^^^^^^^^^^^^^^
  File "/home/airflow/.local/lib/python3.11/site-packages/sqlalchemy/pool/base.py", line 388, in __init__
    self.__connect()
  File "/home/airflow/.local/lib/python3.11/site-packages/sqlalchemy/pool/base.py", line 690, in __connect
    with util.safe_reraise():
  File "/home/airflow/.local/lib/python3.11/site-packages/sqlalchemy/util/langhelpers.py", line 70, in __exit__
    compat.raise_(
  File "/home/airflow/.local/lib/python3.11/site-packages/sqlalchemy/util/compat.py", line 211, in raise_
    raise exception
  File "/home/airflow/.local/lib/python3.11/site-packages/sqlalchemy/pool/base.py", line 686, in __connect
    self.dbapi_connection = connection = pool._invoke_creator(self)
                                         ^^^^^^^^^^^^^^^^^^^^^^^^^^
  File "/home/airflow/.local/lib/python3.11/site-packages/sqlalchemy/engine/create.py", line 574, in connect
    return dialect.connect(*cargs, **cparams)
           ^^^^^^^^^^^^^^^^^^^^^^^^^^^^^^^^^^
  File "/home/airflow/.local/lib/python3.11/site-packages/sqlalchemy/engine/default.py", line 598, in connect
    return self.dbapi.connect(*cargs, **cparams)
           ^^^^^^^^^^^^^^^^^^^^^^^^^^^^^^^^^^^^^
  File "/home/airflow/venv/lib/python3.11/site-packages/psycopg2/__init__.py", line 122, in connect
    conn = _connect(dsn, connection_factory=connection_factory, **kwasync)
           ^^^^^^^^^^^^^^^^^^^^^^^^^^^^^^^^^^^^^^^^^^^^^^^^^^^^^^^^^^^^^^^
psycopg2.OperationalError: could not translate host name "postgres" to address: Temporary failure in name resolution


The above exception was the direct cause of the following exception:

Traceback (most recent call last):
  File "/home/airflow/.local/lib/python3.11/site-packages/airflow/jobs/job.py", line 233, in heartbeat
    heartbeat_callback(session)
  File "/home/airflow/.local/lib/python3.11/site-packages/airflow/utils/session.py", line 94, in wrapper
    return func(*args, **kwargs)
           ^^^^^^^^^^^^^^^^^^^^^
  File "/home/airflow/.local/lib/python3.11/site-packages/airflow/jobs/local_task_job_runner.py", line 284, in heartbeat_callback
    self.task_instance.refresh_from_db()
  File "/home/airflow/.local/lib/python3.11/site-packages/airflow/utils/session.py", line 97, in wrapper
    return func(*args, session=session, **kwargs)
           ^^^^^^^^^^^^^^^^^^^^^^^^^^^^^^^^^^^^^^
  File "/home/airflow/.local/lib/python3.11/site-packages/airflow/models/taskinstance.py", line 2360, in refresh_from_db
    _refresh_from_db(task_instance=self, session=session, lock_for_update=lock_for_update)
  File "/home/airflow/.local/lib/python3.11/site-packages/airflow/models/taskinstance.py", line 873, in _refresh_from_db
    ti = TaskInstance.get_task_instance(
         ^^^^^^^^^^^^^^^^^^^^^^^^^^^^^^^
  File "/home/airflow/.local/lib/python3.11/site-packages/airflow/api_internal/internal_api_call.py", line 166, in wrapper
    return func(*args, **kwargs)
           ^^^^^^^^^^^^^^^^^^^^^
  File "/home/airflow/.local/lib/python3.11/site-packages/airflow/utils/session.py", line 94, in wrapper
    return func(*args, **kwargs)
           ^^^^^^^^^^^^^^^^^^^^^
  File "/home/airflow/.local/lib/python3.11/site-packages/airflow/models/taskinstance.py", line 2346, in get_task_instance
    return query.one_or_none()
           ^^^^^^^^^^^^^^^^^^^
  File "/home/airflow/.local/lib/python3.11/site-packages/sqlalchemy/orm/query.py", line 2850, in one_or_none
    return self._iter().one_or_none()
           ^^^^^^^^^^^^
  File "/home/airflow/.local/lib/python3.11/site-packages/sqlalchemy/orm/query.py", line 2916, in _iter
    result = self.session.execute(
             ^^^^^^^^^^^^^^^^^^^^^
  File "/home/airflow/.local/lib/python3.11/site-packages/sqlalchemy/orm/session.py", line 1716, in execute
    conn = self._connection_for_bind(bind)
           ^^^^^^^^^^^^^^^^^^^^^^^^^^^^^^^
  File "/home/airflow/.local/lib/python3.11/site-packages/sqlalchemy/orm/session.py", line 1555, in _connection_for_bind
    return self._transaction._connection_for_bind(
           ^^^^^^^^^^^^^^^^^^^^^^^^^^^^^^^^^^^^^^^
  File "/home/airflow/.local/lib/python3.11/site-packages/sqlalchemy/orm/session.py", line 750, in _connection_for_bind
    conn = bind.connect()
           ^^^^^^^^^^^^^^
  File "/home/airflow/.local/lib/python3.11/site-packages/sqlalchemy/future/engine.py", line 412, in connect
    return super(Engine, self).connect()
           ^^^^^^^^^^^^^^^^^^^^^^^^^^^^^
  File "/home/airflow/.local/lib/python3.11/site-packages/sqlalchemy/engine/base.py", line 3325, in connect
    return self._connection_cls(self, close_with_result=close_with_result)
           ^^^^^^^^^^^^^^^^^^^^^^^^^^^^^^^^^^^^^^^^^^^^^^^^^^^^^^^^^^^^^^^
  File "/home/airflow/.local/lib/python3.11/site-packages/sqlalchemy/engine/base.py", line 96, in __init__
    else engine.raw_connection()
         ^^^^^^^^^^^^^^^^^^^^^^^
  File "/home/airflow/.local/lib/python3.11/site-packages/sqlalchemy/engine/base.py", line 3404, in raw_connection
    return self._wrap_pool_connect(self.pool.connect, _connection)
           ^^^^^^^^^^^^^^^^^^^^^^^^^^^^^^^^^^^^^^^^^^^^^^^^^^^^^^^
  File "/home/airflow/.local/lib/python3.11/site-packages/sqlalchemy/engine/base.py", line 3374, in _wrap_pool_connect
    Connection._handle_dbapi_exception_noconnection(
  File "/home/airflow/.local/lib/python3.11/site-packages/sqlalchemy/engine/base.py", line 2208, in _handle_dbapi_exception_noconnection
    util.raise_(
  File "/home/airflow/.local/lib/python3.11/site-packages/sqlalchemy/util/compat.py", line 211, in raise_
    raise exception
  File "/home/airflow/.local/lib/python3.11/site-packages/sqlalchemy/engine/base.py", line 3371, in _wrap_pool_connect
    return fn()
           ^^^^
  File "/home/airflow/.local/lib/python3.11/site-packages/sqlalchemy/pool/base.py", line 327, in connect
    return _ConnectionFairy._checkout(self)
           ^^^^^^^^^^^^^^^^^^^^^^^^^^^^^^^^
  File "/home/airflow/.local/lib/python3.11/site-packages/sqlalchemy/pool/base.py", line 894, in _checkout
    fairy = _ConnectionRecord.checkout(pool)
            ^^^^^^^^^^^^^^^^^^^^^^^^^^^^^^^^
  File "/home/airflow/.local/lib/python3.11/site-packages/sqlalchemy/pool/base.py", line 493, in checkout
    rec = pool._do_get()
          ^^^^^^^^^^^^^^
  File "/home/airflow/.local/lib/python3.11/site-packages/sqlalchemy/pool/impl.py", line 256, in _do_get
    return self._create_connection()
           ^^^^^^^^^^^^^^^^^^^^^^^^^
  File "/home/airflow/.local/lib/python3.11/site-packages/sqlalchemy/pool/base.py", line 273, in _create_connection
    return _ConnectionRecord(self)
           ^^^^^^^^^^^^^^^^^^^^^^^
  File "/home/airflow/.local/lib/python3.11/site-packages/sqlalchemy/pool/base.py", line 388, in __init__
    self.__connect()
  File "/home/airflow/.local/lib/python3.11/site-packages/sqlalchemy/pool/base.py", line 690, in __connect
    with util.safe_reraise():
  File "/home/airflow/.local/lib/python3.11/site-packages/sqlalchemy/util/langhelpers.py", line 70, in __exit__
    compat.raise_(
  File "/home/airflow/.local/lib/python3.11/site-packages/sqlalchemy/util/compat.py", line 211, in raise_
    raise exception
  File "/home/airflow/.local/lib/python3.11/site-packages/sqlalchemy/pool/base.py", line 686, in __connect
    self.dbapi_connection = connection = pool._invoke_creator(self)
                                         ^^^^^^^^^^^^^^^^^^^^^^^^^^
  File "/home/airflow/.local/lib/python3.11/site-packages/sqlalchemy/engine/create.py", line 574, in connect
    return dialect.connect(*cargs, **cparams)
           ^^^^^^^^^^^^^^^^^^^^^^^^^^^^^^^^^^
  File "/home/airflow/.local/lib/python3.11/site-packages/sqlalchemy/engine/default.py", line 598, in connect
    return self.dbapi.connect(*cargs, **cparams)
           ^^^^^^^^^^^^^^^^^^^^^^^^^^^^^^^^^^^^^
  File "/home/airflow/venv/lib/python3.11/site-packages/psycopg2/__init__.py", line 122, in connect
    conn = _connect(dsn, connection_factory=connection_factory, **kwasync)
           ^^^^^^^^^^^^^^^^^^^^^^^^^^^^^^^^^^^^^^^^^^^^^^^^^^^^^^^^^^^^^^^
sqlalchemy.exc.OperationalError: (psycopg2.OperationalError) could not translate host name "postgres" to address: Temporary failure in name resolution

(Background on this error at: https://sqlalche.me/e/14/e3q8)
[2025-07-18T18:53:00.044+0000] {job.py:254} ERROR - Job heartbeat failed with error. Scheduler is in unhealthy state
[2025-07-18T18:53:19.646+0000] {job.py:229} INFO - Heartbeat recovered after 32.02 seconds
[2025-07-18T18:53:35.833+0000] {job.py:239} ERROR - Job heartbeat failed with error
Traceback (most recent call last):
  File "/home/airflow/.local/lib/python3.11/site-packages/sqlalchemy/engine/base.py", line 3371, in _wrap_pool_connect
    return fn()
           ^^^^
  File "/home/airflow/.local/lib/python3.11/site-packages/sqlalchemy/pool/base.py", line 327, in connect
    return _ConnectionFairy._checkout(self)
           ^^^^^^^^^^^^^^^^^^^^^^^^^^^^^^^^
  File "/home/airflow/.local/lib/python3.11/site-packages/sqlalchemy/pool/base.py", line 894, in _checkout
    fairy = _ConnectionRecord.checkout(pool)
            ^^^^^^^^^^^^^^^^^^^^^^^^^^^^^^^^
  File "/home/airflow/.local/lib/python3.11/site-packages/sqlalchemy/pool/base.py", line 493, in checkout
    rec = pool._do_get()
          ^^^^^^^^^^^^^^
  File "/home/airflow/.local/lib/python3.11/site-packages/sqlalchemy/pool/impl.py", line 256, in _do_get
    return self._create_connection()
           ^^^^^^^^^^^^^^^^^^^^^^^^^
  File "/home/airflow/.local/lib/python3.11/site-packages/sqlalchemy/pool/base.py", line 273, in _create_connection
    return _ConnectionRecord(self)
           ^^^^^^^^^^^^^^^^^^^^^^^
  File "/home/airflow/.local/lib/python3.11/site-packages/sqlalchemy/pool/base.py", line 388, in __init__
    self.__connect()
  File "/home/airflow/.local/lib/python3.11/site-packages/sqlalchemy/pool/base.py", line 690, in __connect
    with util.safe_reraise():
  File "/home/airflow/.local/lib/python3.11/site-packages/sqlalchemy/util/langhelpers.py", line 70, in __exit__
    compat.raise_(
  File "/home/airflow/.local/lib/python3.11/site-packages/sqlalchemy/util/compat.py", line 211, in raise_
    raise exception
  File "/home/airflow/.local/lib/python3.11/site-packages/sqlalchemy/pool/base.py", line 686, in __connect
    self.dbapi_connection = connection = pool._invoke_creator(self)
                                         ^^^^^^^^^^^^^^^^^^^^^^^^^^
  File "/home/airflow/.local/lib/python3.11/site-packages/sqlalchemy/engine/create.py", line 574, in connect
    return dialect.connect(*cargs, **cparams)
           ^^^^^^^^^^^^^^^^^^^^^^^^^^^^^^^^^^
  File "/home/airflow/.local/lib/python3.11/site-packages/sqlalchemy/engine/default.py", line 598, in connect
    return self.dbapi.connect(*cargs, **cparams)
           ^^^^^^^^^^^^^^^^^^^^^^^^^^^^^^^^^^^^^
  File "/home/airflow/venv/lib/python3.11/site-packages/psycopg2/__init__.py", line 122, in connect
    conn = _connect(dsn, connection_factory=connection_factory, **kwasync)
           ^^^^^^^^^^^^^^^^^^^^^^^^^^^^^^^^^^^^^^^^^^^^^^^^^^^^^^^^^^^^^^^
psycopg2.OperationalError: could not translate host name "postgres" to address: Temporary failure in name resolution


The above exception was the direct cause of the following exception:

Traceback (most recent call last):
  File "/home/airflow/.local/lib/python3.11/site-packages/airflow/jobs/job.py", line 233, in heartbeat
    heartbeat_callback(session)
  File "/home/airflow/.local/lib/python3.11/site-packages/airflow/utils/session.py", line 94, in wrapper
    return func(*args, **kwargs)
           ^^^^^^^^^^^^^^^^^^^^^
  File "/home/airflow/.local/lib/python3.11/site-packages/airflow/jobs/local_task_job_runner.py", line 284, in heartbeat_callback
    self.task_instance.refresh_from_db()
  File "/home/airflow/.local/lib/python3.11/site-packages/airflow/utils/session.py", line 97, in wrapper
    return func(*args, session=session, **kwargs)
           ^^^^^^^^^^^^^^^^^^^^^^^^^^^^^^^^^^^^^^
  File "/home/airflow/.local/lib/python3.11/site-packages/airflow/models/taskinstance.py", line 2360, in refresh_from_db
    _refresh_from_db(task_instance=self, session=session, lock_for_update=lock_for_update)
  File "/home/airflow/.local/lib/python3.11/site-packages/airflow/models/taskinstance.py", line 873, in _refresh_from_db
    ti = TaskInstance.get_task_instance(
         ^^^^^^^^^^^^^^^^^^^^^^^^^^^^^^^
  File "/home/airflow/.local/lib/python3.11/site-packages/airflow/api_internal/internal_api_call.py", line 166, in wrapper
    return func(*args, **kwargs)
           ^^^^^^^^^^^^^^^^^^^^^
  File "/home/airflow/.local/lib/python3.11/site-packages/airflow/utils/session.py", line 94, in wrapper
    return func(*args, **kwargs)
           ^^^^^^^^^^^^^^^^^^^^^
  File "/home/airflow/.local/lib/python3.11/site-packages/airflow/models/taskinstance.py", line 2346, in get_task_instance
    return query.one_or_none()
           ^^^^^^^^^^^^^^^^^^^
  File "/home/airflow/.local/lib/python3.11/site-packages/sqlalchemy/orm/query.py", line 2850, in one_or_none
    return self._iter().one_or_none()
           ^^^^^^^^^^^^
  File "/home/airflow/.local/lib/python3.11/site-packages/sqlalchemy/orm/query.py", line 2916, in _iter
    result = self.session.execute(
             ^^^^^^^^^^^^^^^^^^^^^
  File "/home/airflow/.local/lib/python3.11/site-packages/sqlalchemy/orm/session.py", line 1716, in execute
    conn = self._connection_for_bind(bind)
           ^^^^^^^^^^^^^^^^^^^^^^^^^^^^^^^
  File "/home/airflow/.local/lib/python3.11/site-packages/sqlalchemy/orm/session.py", line 1555, in _connection_for_bind
    return self._transaction._connection_for_bind(
           ^^^^^^^^^^^^^^^^^^^^^^^^^^^^^^^^^^^^^^^
  File "/home/airflow/.local/lib/python3.11/site-packages/sqlalchemy/orm/session.py", line 750, in _connection_for_bind
    conn = bind.connect()
           ^^^^^^^^^^^^^^
  File "/home/airflow/.local/lib/python3.11/site-packages/sqlalchemy/future/engine.py", line 412, in connect
    return super(Engine, self).connect()
           ^^^^^^^^^^^^^^^^^^^^^^^^^^^^^
  File "/home/airflow/.local/lib/python3.11/site-packages/sqlalchemy/engine/base.py", line 3325, in connect
    return self._connection_cls(self, close_with_result=close_with_result)
           ^^^^^^^^^^^^^^^^^^^^^^^^^^^^^^^^^^^^^^^^^^^^^^^^^^^^^^^^^^^^^^^
  File "/home/airflow/.local/lib/python3.11/site-packages/sqlalchemy/engine/base.py", line 96, in __init__
    else engine.raw_connection()
         ^^^^^^^^^^^^^^^^^^^^^^^
  File "/home/airflow/.local/lib/python3.11/site-packages/sqlalchemy/engine/base.py", line 3404, in raw_connection
    return self._wrap_pool_connect(self.pool.connect, _connection)
           ^^^^^^^^^^^^^^^^^^^^^^^^^^^^^^^^^^^^^^^^^^^^^^^^^^^^^^^
  File "/home/airflow/.local/lib/python3.11/site-packages/sqlalchemy/engine/base.py", line 3374, in _wrap_pool_connect
    Connection._handle_dbapi_exception_noconnection(
  File "/home/airflow/.local/lib/python3.11/site-packages/sqlalchemy/engine/base.py", line 2208, in _handle_dbapi_exception_noconnection
    util.raise_(
  File "/home/airflow/.local/lib/python3.11/site-packages/sqlalchemy/util/compat.py", line 211, in raise_
    raise exception
  File "/home/airflow/.local/lib/python3.11/site-packages/sqlalchemy/engine/base.py", line 3371, in _wrap_pool_connect
    return fn()
           ^^^^
  File "/home/airflow/.local/lib/python3.11/site-packages/sqlalchemy/pool/base.py", line 327, in connect
    return _ConnectionFairy._checkout(self)
           ^^^^^^^^^^^^^^^^^^^^^^^^^^^^^^^^
  File "/home/airflow/.local/lib/python3.11/site-packages/sqlalchemy/pool/base.py", line 894, in _checkout
    fairy = _ConnectionRecord.checkout(pool)
            ^^^^^^^^^^^^^^^^^^^^^^^^^^^^^^^^
  File "/home/airflow/.local/lib/python3.11/site-packages/sqlalchemy/pool/base.py", line 493, in checkout
    rec = pool._do_get()
          ^^^^^^^^^^^^^^
  File "/home/airflow/.local/lib/python3.11/site-packages/sqlalchemy/pool/impl.py", line 256, in _do_get
    return self._create_connection()
           ^^^^^^^^^^^^^^^^^^^^^^^^^
  File "/home/airflow/.local/lib/python3.11/site-packages/sqlalchemy/pool/base.py", line 273, in _create_connection
    return _ConnectionRecord(self)
           ^^^^^^^^^^^^^^^^^^^^^^^
  File "/home/airflow/.local/lib/python3.11/site-packages/sqlalchemy/pool/base.py", line 388, in __init__
    self.__connect()
  File "/home/airflow/.local/lib/python3.11/site-packages/sqlalchemy/pool/base.py", line 690, in __connect
    with util.safe_reraise():
  File "/home/airflow/.local/lib/python3.11/site-packages/sqlalchemy/util/langhelpers.py", line 70, in __exit__
    compat.raise_(
  File "/home/airflow/.local/lib/python3.11/site-packages/sqlalchemy/util/compat.py", line 211, in raise_
    raise exception
  File "/home/airflow/.local/lib/python3.11/site-packages/sqlalchemy/pool/base.py", line 686, in __connect
    self.dbapi_connection = connection = pool._invoke_creator(self)
                                         ^^^^^^^^^^^^^^^^^^^^^^^^^^
  File "/home/airflow/.local/lib/python3.11/site-packages/sqlalchemy/engine/create.py", line 574, in connect
    return dialect.connect(*cargs, **cparams)
           ^^^^^^^^^^^^^^^^^^^^^^^^^^^^^^^^^^
  File "/home/airflow/.local/lib/python3.11/site-packages/sqlalchemy/engine/default.py", line 598, in connect
    return self.dbapi.connect(*cargs, **cparams)
           ^^^^^^^^^^^^^^^^^^^^^^^^^^^^^^^^^^^^^
  File "/home/airflow/venv/lib/python3.11/site-packages/psycopg2/__init__.py", line 122, in connect
    conn = _connect(dsn, connection_factory=connection_factory, **kwasync)
           ^^^^^^^^^^^^^^^^^^^^^^^^^^^^^^^^^^^^^^^^^^^^^^^^^^^^^^^^^^^^^^^
sqlalchemy.exc.OperationalError: (psycopg2.OperationalError) could not translate host name "postgres" to address: Temporary failure in name resolution

(Background on this error at: https://sqlalche.me/e/14/e3q8)
[2025-07-18T18:53:35.940+0000] {job.py:245} ERROR - Job heartbeat failed with error. Scheduler may go into unhealthy state
[2025-07-18T18:53:43.798+0000] {job.py:229} INFO - Heartbeat recovered after 18.04 seconds
[2025-07-18T18:54:03.842+0000] {job.py:239} ERROR - Job heartbeat failed with error
Traceback (most recent call last):
  File "/home/airflow/.local/lib/python3.11/site-packages/sqlalchemy/engine/base.py", line 3371, in _wrap_pool_connect
    return fn()
           ^^^^
  File "/home/airflow/.local/lib/python3.11/site-packages/sqlalchemy/pool/base.py", line 327, in connect
    return _ConnectionFairy._checkout(self)
           ^^^^^^^^^^^^^^^^^^^^^^^^^^^^^^^^
  File "/home/airflow/.local/lib/python3.11/site-packages/sqlalchemy/pool/base.py", line 894, in _checkout
    fairy = _ConnectionRecord.checkout(pool)
            ^^^^^^^^^^^^^^^^^^^^^^^^^^^^^^^^
  File "/home/airflow/.local/lib/python3.11/site-packages/sqlalchemy/pool/base.py", line 493, in checkout
    rec = pool._do_get()
          ^^^^^^^^^^^^^^
  File "/home/airflow/.local/lib/python3.11/site-packages/sqlalchemy/pool/impl.py", line 256, in _do_get
    return self._create_connection()
           ^^^^^^^^^^^^^^^^^^^^^^^^^
  File "/home/airflow/.local/lib/python3.11/site-packages/sqlalchemy/pool/base.py", line 273, in _create_connection
    return _ConnectionRecord(self)
           ^^^^^^^^^^^^^^^^^^^^^^^
  File "/home/airflow/.local/lib/python3.11/site-packages/sqlalchemy/pool/base.py", line 388, in __init__
    self.__connect()
  File "/home/airflow/.local/lib/python3.11/site-packages/sqlalchemy/pool/base.py", line 690, in __connect
    with util.safe_reraise():
  File "/home/airflow/.local/lib/python3.11/site-packages/sqlalchemy/util/langhelpers.py", line 70, in __exit__
    compat.raise_(
  File "/home/airflow/.local/lib/python3.11/site-packages/sqlalchemy/util/compat.py", line 211, in raise_
    raise exception
  File "/home/airflow/.local/lib/python3.11/site-packages/sqlalchemy/pool/base.py", line 686, in __connect
    self.dbapi_connection = connection = pool._invoke_creator(self)
                                         ^^^^^^^^^^^^^^^^^^^^^^^^^^
  File "/home/airflow/.local/lib/python3.11/site-packages/sqlalchemy/engine/create.py", line 574, in connect
    return dialect.connect(*cargs, **cparams)
           ^^^^^^^^^^^^^^^^^^^^^^^^^^^^^^^^^^
  File "/home/airflow/.local/lib/python3.11/site-packages/sqlalchemy/engine/default.py", line 598, in connect
    return self.dbapi.connect(*cargs, **cparams)
           ^^^^^^^^^^^^^^^^^^^^^^^^^^^^^^^^^^^^^
  File "/home/airflow/venv/lib/python3.11/site-packages/psycopg2/__init__.py", line 122, in connect
    conn = _connect(dsn, connection_factory=connection_factory, **kwasync)
           ^^^^^^^^^^^^^^^^^^^^^^^^^^^^^^^^^^^^^^^^^^^^^^^^^^^^^^^^^^^^^^^
psycopg2.OperationalError: could not translate host name "postgres" to address: Temporary failure in name resolution


The above exception was the direct cause of the following exception:

Traceback (most recent call last):
  File "/home/airflow/.local/lib/python3.11/site-packages/airflow/jobs/job.py", line 233, in heartbeat
    heartbeat_callback(session)
  File "/home/airflow/.local/lib/python3.11/site-packages/airflow/utils/session.py", line 94, in wrapper
    return func(*args, **kwargs)
           ^^^^^^^^^^^^^^^^^^^^^
  File "/home/airflow/.local/lib/python3.11/site-packages/airflow/jobs/local_task_job_runner.py", line 284, in heartbeat_callback
    self.task_instance.refresh_from_db()
  File "/home/airflow/.local/lib/python3.11/site-packages/airflow/utils/session.py", line 97, in wrapper
    return func(*args, session=session, **kwargs)
           ^^^^^^^^^^^^^^^^^^^^^^^^^^^^^^^^^^^^^^
  File "/home/airflow/.local/lib/python3.11/site-packages/airflow/models/taskinstance.py", line 2360, in refresh_from_db
    _refresh_from_db(task_instance=self, session=session, lock_for_update=lock_for_update)
  File "/home/airflow/.local/lib/python3.11/site-packages/airflow/models/taskinstance.py", line 873, in _refresh_from_db
    ti = TaskInstance.get_task_instance(
         ^^^^^^^^^^^^^^^^^^^^^^^^^^^^^^^
  File "/home/airflow/.local/lib/python3.11/site-packages/airflow/api_internal/internal_api_call.py", line 166, in wrapper
    return func(*args, **kwargs)
           ^^^^^^^^^^^^^^^^^^^^^
  File "/home/airflow/.local/lib/python3.11/site-packages/airflow/utils/session.py", line 94, in wrapper
    return func(*args, **kwargs)
           ^^^^^^^^^^^^^^^^^^^^^
  File "/home/airflow/.local/lib/python3.11/site-packages/airflow/models/taskinstance.py", line 2346, in get_task_instance
    return query.one_or_none()
           ^^^^^^^^^^^^^^^^^^^
  File "/home/airflow/.local/lib/python3.11/site-packages/sqlalchemy/orm/query.py", line 2850, in one_or_none
    return self._iter().one_or_none()
           ^^^^^^^^^^^^
  File "/home/airflow/.local/lib/python3.11/site-packages/sqlalchemy/orm/query.py", line 2916, in _iter
    result = self.session.execute(
             ^^^^^^^^^^^^^^^^^^^^^
  File "/home/airflow/.local/lib/python3.11/site-packages/sqlalchemy/orm/session.py", line 1716, in execute
    conn = self._connection_for_bind(bind)
           ^^^^^^^^^^^^^^^^^^^^^^^^^^^^^^^
  File "/home/airflow/.local/lib/python3.11/site-packages/sqlalchemy/orm/session.py", line 1555, in _connection_for_bind
    return self._transaction._connection_for_bind(
           ^^^^^^^^^^^^^^^^^^^^^^^^^^^^^^^^^^^^^^^
  File "/home/airflow/.local/lib/python3.11/site-packages/sqlalchemy/orm/session.py", line 750, in _connection_for_bind
    conn = bind.connect()
           ^^^^^^^^^^^^^^
  File "/home/airflow/.local/lib/python3.11/site-packages/sqlalchemy/future/engine.py", line 412, in connect
    return super(Engine, self).connect()
           ^^^^^^^^^^^^^^^^^^^^^^^^^^^^^
  File "/home/airflow/.local/lib/python3.11/site-packages/sqlalchemy/engine/base.py", line 3325, in connect
    return self._connection_cls(self, close_with_result=close_with_result)
           ^^^^^^^^^^^^^^^^^^^^^^^^^^^^^^^^^^^^^^^^^^^^^^^^^^^^^^^^^^^^^^^
  File "/home/airflow/.local/lib/python3.11/site-packages/sqlalchemy/engine/base.py", line 96, in __init__
    else engine.raw_connection()
         ^^^^^^^^^^^^^^^^^^^^^^^
  File "/home/airflow/.local/lib/python3.11/site-packages/sqlalchemy/engine/base.py", line 3404, in raw_connection
    return self._wrap_pool_connect(self.pool.connect, _connection)
           ^^^^^^^^^^^^^^^^^^^^^^^^^^^^^^^^^^^^^^^^^^^^^^^^^^^^^^^
  File "/home/airflow/.local/lib/python3.11/site-packages/sqlalchemy/engine/base.py", line 3374, in _wrap_pool_connect
    Connection._handle_dbapi_exception_noconnection(
  File "/home/airflow/.local/lib/python3.11/site-packages/sqlalchemy/engine/base.py", line 2208, in _handle_dbapi_exception_noconnection
    util.raise_(
  File "/home/airflow/.local/lib/python3.11/site-packages/sqlalchemy/util/compat.py", line 211, in raise_
    raise exception
  File "/home/airflow/.local/lib/python3.11/site-packages/sqlalchemy/engine/base.py", line 3371, in _wrap_pool_connect
    return fn()
           ^^^^
  File "/home/airflow/.local/lib/python3.11/site-packages/sqlalchemy/pool/base.py", line 327, in connect
    return _ConnectionFairy._checkout(self)
           ^^^^^^^^^^^^^^^^^^^^^^^^^^^^^^^^
  File "/home/airflow/.local/lib/python3.11/site-packages/sqlalchemy/pool/base.py", line 894, in _checkout
    fairy = _ConnectionRecord.checkout(pool)
            ^^^^^^^^^^^^^^^^^^^^^^^^^^^^^^^^
  File "/home/airflow/.local/lib/python3.11/site-packages/sqlalchemy/pool/base.py", line 493, in checkout
    rec = pool._do_get()
          ^^^^^^^^^^^^^^
  File "/home/airflow/.local/lib/python3.11/site-packages/sqlalchemy/pool/impl.py", line 256, in _do_get
    return self._create_connection()
           ^^^^^^^^^^^^^^^^^^^^^^^^^
  File "/home/airflow/.local/lib/python3.11/site-packages/sqlalchemy/pool/base.py", line 273, in _create_connection
    return _ConnectionRecord(self)
           ^^^^^^^^^^^^^^^^^^^^^^^
  File "/home/airflow/.local/lib/python3.11/site-packages/sqlalchemy/pool/base.py", line 388, in __init__
    self.__connect()
  File "/home/airflow/.local/lib/python3.11/site-packages/sqlalchemy/pool/base.py", line 690, in __connect
    with util.safe_reraise():
  File "/home/airflow/.local/lib/python3.11/site-packages/sqlalchemy/util/langhelpers.py", line 70, in __exit__
    compat.raise_(
  File "/home/airflow/.local/lib/python3.11/site-packages/sqlalchemy/util/compat.py", line 211, in raise_
    raise exception
  File "/home/airflow/.local/lib/python3.11/site-packages/sqlalchemy/pool/base.py", line 686, in __connect
    self.dbapi_connection = connection = pool._invoke_creator(self)
                                         ^^^^^^^^^^^^^^^^^^^^^^^^^^
  File "/home/airflow/.local/lib/python3.11/site-packages/sqlalchemy/engine/create.py", line 574, in connect
    return dialect.connect(*cargs, **cparams)
           ^^^^^^^^^^^^^^^^^^^^^^^^^^^^^^^^^^
  File "/home/airflow/.local/lib/python3.11/site-packages/sqlalchemy/engine/default.py", line 598, in connect
    return self.dbapi.connect(*cargs, **cparams)
           ^^^^^^^^^^^^^^^^^^^^^^^^^^^^^^^^^^^^^
  File "/home/airflow/venv/lib/python3.11/site-packages/psycopg2/__init__.py", line 122, in connect
    conn = _connect(dsn, connection_factory=connection_factory, **kwasync)
           ^^^^^^^^^^^^^^^^^^^^^^^^^^^^^^^^^^^^^^^^^^^^^^^^^^^^^^^^^^^^^^^
sqlalchemy.exc.OperationalError: (psycopg2.OperationalError) could not translate host name "postgres" to address: Temporary failure in name resolution

(Background on this error at: https://sqlalche.me/e/14/e3q8)
[2025-07-18T18:54:04.031+0000] {job.py:254} ERROR - Job heartbeat failed with error. Scheduler is in unhealthy state
[2025-07-18T18:54:40.640+0000] {job.py:254} ERROR - Job heartbeat failed with error. Scheduler is in unhealthy state
[2025-07-18T18:55:17.071+0000] {job.py:254} ERROR - Job heartbeat failed with error. Scheduler is in unhealthy state
[2025-07-18T18:55:53.113+0000] {job.py:254} ERROR - Job heartbeat failed with error. Scheduler is in unhealthy state
[2025-07-18T18:56:28.953+0000] {job.py:254} ERROR - Job heartbeat failed with error. Scheduler is in unhealthy state
[2025-07-18T18:57:05.451+0000] {job.py:254} ERROR - Job heartbeat failed with error. Scheduler is in unhealthy state
[2025-07-18T18:57:15.845+0000] {scraper_banks.py:198} INFO - ‚úÖ Fin du scrolling
[2025-07-18T18:57:18.597+0000] {scraper_banks.py:289} INFO - [Casablanca] 20 r√©sultats trouv√©s
[2025-07-18T18:57:41.906+0000] {job.py:254} ERROR - Job heartbeat failed with error. Scheduler is in unhealthy state
[2025-07-18T18:57:52.321+0000] {scraper_banks.py:372} INFO - üö´ Doublon ou donn√©es incompl√®tes : BANK OF AFRICA
[2025-07-18T18:58:18.554+0000] {job.py:254} ERROR - Job heartbeat failed with error. Scheduler is in unhealthy state
[2025-07-18T18:58:55.953+0000] {job.py:254} ERROR - Job heartbeat failed with error. Scheduler is in unhealthy state
[2025-07-18T18:58:56.036+0000] {local_task_job_runner.py:228} ERROR - Heartbeat time limit exceeded!
[2025-07-18T18:58:56.117+0000] {local_task_job_runner.py:245} INFO - ::endgroup::
[2025-07-18T18:58:56.517+0000] {process_utils.py:132} INFO - Sending 15 to group 76. PIDs of all processes in the group: [109, 399, 812, 818, 827, 828, 852, 853, 922, 933, 850, 405, 414, 415, 499, 491, 514, 522, 433, 115, 119, 120, 149, 158, 214, 222, 146, 76]
[2025-07-18T18:58:56.638+0000] {process_utils.py:87} INFO - Sending the signal 15 to group 76
[2025-07-18T18:58:56.825+0000] {taskinstance.py:3094} ERROR - Received SIGTERM. Terminating subprocesses.
[2025-07-18T18:58:57.292+0000] {process_utils.py:80} INFO - Process psutil.Process(pid=222, status='terminated', started='18:38:50') (222) terminated with exit code None
[2025-07-18T18:58:57.535+0000] {process_utils.py:80} INFO - Process psutil.Process(pid=491, status='terminated', started='18:45:15') (491) terminated with exit code None
[2025-07-18T18:58:57.705+0000] {process_utils.py:80} INFO - Process psutil.Process(pid=522, status='terminated', started='18:45:19') (522) terminated with exit code None
[2025-07-18T18:58:57.764+0000] {process_utils.py:80} INFO - Process psutil.Process(pid=850, status='terminated', started='18:51:54') (850) terminated with exit code None
[2025-07-18T18:58:57.769+0000] {process_utils.py:80} INFO - Process psutil.Process(pid=514, status='terminated', started='18:45:18') (514) terminated with exit code None
[2025-07-18T18:58:57.826+0000] {process_utils.py:80} INFO - Process psutil.Process(pid=433, status='terminated', started='18:44:42') (433) terminated with exit code None
[2025-07-18T18:58:57.886+0000] {process_utils.py:80} INFO - Process psutil.Process(pid=933, status='terminated', started='18:52:08') (933) terminated with exit code None
[2025-07-18T18:58:57.894+0000] {process_utils.py:80} INFO - Process psutil.Process(pid=214, status='terminated', started='18:38:49') (214) terminated with exit code None
[2025-07-18T18:58:57.953+0000] {process_utils.py:80} INFO - Process psutil.Process(pid=922, status='terminated', started='18:52:03') (922) terminated with exit code None
[2025-07-18T18:58:58.175+0000] {process_utils.py:80} INFO - Process psutil.Process(pid=853, status='terminated', started='18:51:54') (853) terminated with exit code None
[2025-07-18T18:58:58.181+0000] {process_utils.py:80} INFO - Process psutil.Process(pid=146, status='terminated', started='18:38:39') (146) terminated with exit code None
[2025-07-18T18:58:58.291+0000] {process_utils.py:80} INFO - Process psutil.Process(pid=158, status='terminated', started='18:38:40') (158) terminated with exit code None
[2025-07-18T18:59:00.652+0000] {taskinstance.py:3095} ERROR - Stacktrace: 
  File "/home/***/.local/bin/***", line 8, in <module>
    sys.exit(main())
  File "/home/***/.local/lib/python3.11/site-packages/***/__main__.py", line 62, in main
    args.func(args)
  File "/home/***/.local/lib/python3.11/site-packages/***/cli/cli_config.py", line 49, in command
    return func(*args, **kwargs)
  File "/home/***/.local/lib/python3.11/site-packages/***/utils/cli.py", line 116, in wrapper
    return f(*args, **kwargs)
  File "/home/***/.local/lib/python3.11/site-packages/***/providers/celery/cli/celery_command.py", line 64, in wrapper
    providers_configuration_loaded(func)(*args, **kwargs)
  File "/home/***/.local/lib/python3.11/site-packages/***/utils/providers_configuration_loader.py", line 55, in wrapped_function
    return func(*args, **kwargs)
  File "/home/***/.local/lib/python3.11/site-packages/***/providers/celery/cli/celery_command.py", line 237, in worker
    _run_command_with_daemon_option(
  File "/home/***/.local/lib/python3.11/site-packages/***/providers/celery/cli/celery_command.py", line 50, in _run_command_with_daemon_option
    run_command_with_daemon_option(*args, **kwargs)
  File "/home/***/.local/lib/python3.11/site-packages/***/cli/commands/daemon_utils.py", line 86, in run_command_with_daemon_option
    callback()
  File "/home/***/.local/lib/python3.11/site-packages/***/providers/celery/cli/celery_command.py", line 230, in run_celery_worker
    celery_app.worker_main(options)
  File "/home/***/.local/lib/python3.11/site-packages/celery/app/base.py", line 391, in worker_main
    self.start(argv=argv)
  File "/home/***/.local/lib/python3.11/site-packages/celery/app/base.py", line 371, in start
    celery.main(args=argv, standalone_mode=False)
  File "/home/***/venv/lib/python3.11/site-packages/click/core.py", line 1363, in main
    rv = self.invoke(ctx)
  File "/home/***/venv/lib/python3.11/site-packages/click/core.py", line 1830, in invoke
    return _process_result(sub_ctx.command.invoke(sub_ctx))
  File "/home/***/venv/lib/python3.11/site-packages/click/core.py", line 1226, in invoke
    return ctx.invoke(self.callback, **ctx.params)
  File "/home/***/venv/lib/python3.11/site-packages/click/core.py", line 794, in invoke
    return callback(*args, **kwargs)
  File "/home/***/venv/lib/python3.11/site-packages/click/decorators.py", line 34, in new_func
    return f(get_current_context(), *args, **kwargs)
  File "/home/***/.local/lib/python3.11/site-packages/celery/bin/base.py", line 135, in caller
    return f(ctx, *args, **kwargs)
  File "/home/***/.local/lib/python3.11/site-packages/celery/bin/worker.py", line 356, in worker
    worker.start()
  File "/home/***/.local/lib/python3.11/site-packages/celery/worker/worker.py", line 202, in start
    self.blueprint.start(self)
  File "/home/***/.local/lib/python3.11/site-packages/celery/bootsteps.py", line 116, in start
    step.start(parent)
  File "/home/***/.local/lib/python3.11/site-packages/celery/bootsteps.py", line 365, in start
    return self.obj.start()
  File "/home/***/.local/lib/python3.11/site-packages/celery/concurrency/base.py", line 130, in start
    self.on_start()
  File "/home/***/.local/lib/python3.11/site-packages/celery/concurrency/prefork.py", line 109, in on_start
    P = self._pool = Pool(processes=self.limit,
  File "/home/***/.local/lib/python3.11/site-packages/celery/concurrency/asynpool.py", line 464, in __init__
    super().__init__(processes, *args, **kwargs)
  File "/home/***/.local/lib/python3.11/site-packages/billiard/pool.py", line 1046, in __init__
    self._create_worker_process(i)
  File "/home/***/.local/lib/python3.11/site-packages/celery/concurrency/asynpool.py", line 482, in _create_worker_process
    return super()._create_worker_process(i)
  File "/home/***/.local/lib/python3.11/site-packages/billiard/pool.py", line 1158, in _create_worker_process
    w.start()
  File "/home/***/.local/lib/python3.11/site-packages/billiard/process.py", line 120, in start
    self._popen = self._Popen(self)
  File "/home/***/.local/lib/python3.11/site-packages/billiard/context.py", line 331, in _Popen
    return Popen(process_obj)
  File "/home/***/.local/lib/python3.11/site-packages/billiard/popen_fork.py", line 22, in __init__
    self._launch(process_obj)
  File "/home/***/.local/lib/python3.11/site-packages/billiard/popen_fork.py", line 77, in _launch
    code = process_obj._bootstrap()
  File "/home/***/.local/lib/python3.11/site-packages/billiard/process.py", line 323, in _bootstrap
    self.run()
  File "/home/***/.local/lib/python3.11/site-packages/billiard/process.py", line 110, in run
    self._target(*self._args, **self._kwargs)
  File "/home/***/.local/lib/python3.11/site-packages/billiard/pool.py", line 292, in __call__
    sys.exit(self.workloop(pid=pid))
  File "/home/***/.local/lib/python3.11/site-packages/billiard/pool.py", line 362, in workloop
    result = (True, prepare_result(fun(*args, **kwargs)))
  File "/home/***/.local/lib/python3.11/site-packages/celery/app/trace.py", line 651, in fast_trace_task
    R, I, T, Rstr = tasks[task].__trace__(
  File "/home/***/.local/lib/python3.11/site-packages/celery/app/trace.py", line 453, in trace_task
    R = retval = fun(*args, **kwargs)
  File "/home/***/.local/lib/python3.11/site-packages/celery/app/trace.py", line 736, in __protected_call__
    return self.run(*args, **kwargs)
  File "/home/***/.local/lib/python3.11/site-packages/***/providers/celery/executors/celery_executor_utils.py", line 139, in execute_command
    _execute_in_fork(command_to_exec, celery_task_id)
  File "/home/***/.local/lib/python3.11/site-packages/***/providers/celery/executors/celery_executor_utils.py", line 171, in _execute_in_fork
    args.func(args)
  File "/home/***/.local/lib/python3.11/site-packages/***/cli/cli_config.py", line 49, in command
    return func(*args, **kwargs)
  File "/home/***/.local/lib/python3.11/site-packages/***/utils/cli.py", line 116, in wrapper
    return f(*args, **kwargs)
  File "/home/***/.local/lib/python3.11/site-packages/***/cli/commands/task_command.py", line 483, in task_run
    task_return_code = _run_task_by_selected_method(args, _dag, ti)
  File "/home/***/.local/lib/python3.11/site-packages/***/cli/commands/task_command.py", line 254, in _run_task_by_selected_method
    return _run_task_by_local_task_job(args, ti)
  File "/home/***/.local/lib/python3.11/site-packages/***/cli/commands/task_command.py", line 322, in _run_task_by_local_task_job
    ret = run_job(job=job_runner.job, execute_callable=job_runner._execute)
  File "/home/***/.local/lib/python3.11/site-packages/***/utils/session.py", line 97, in wrapper
    return func(*args, session=session, **kwargs)
  File "/home/***/.local/lib/python3.11/site-packages/***/jobs/job.py", line 421, in run_job
    return execute_job(job, execute_callable=execute_callable)
  File "/home/***/.local/lib/python3.11/site-packages/***/jobs/job.py", line 450, in execute_job
    ret = execute_callable()
  File "/home/***/.local/lib/python3.11/site-packages/***/jobs/local_task_job_runner.py", line 171, in _execute
    self.task_runner.start()
  File "/home/***/.local/lib/python3.11/site-packages/***/task/task_runner/standard_task_runner.py", line 55, in start
    self.process = self._start_by_fork()
  File "/home/***/.local/lib/python3.11/site-packages/***/task/task_runner/standard_task_runner.py", line 117, in _start_by_fork
    ret = args.func(args, dag=self.dag)
  File "/home/***/.local/lib/python3.11/site-packages/***/cli/cli_config.py", line 49, in command
    return func(*args, **kwargs)
  File "/home/***/.local/lib/python3.11/site-packages/***/utils/cli.py", line 116, in wrapper
    return f(*args, **kwargs)
  File "/home/***/.local/lib/python3.11/site-packages/***/cli/commands/task_command.py", line 483, in task_run
    task_return_code = _run_task_by_selected_method(args, _dag, ti)
  File "/home/***/.local/lib/python3.11/site-packages/***/cli/commands/task_command.py", line 256, in _run_task_by_selected_method
    return _run_raw_task(args, ti)
  File "/home/***/.local/lib/python3.11/site-packages/***/cli/commands/task_command.py", line 341, in _run_raw_task
    return ti._run_raw_task(
  File "/home/***/.local/lib/python3.11/site-packages/***/utils/session.py", line 97, in wrapper
    return func(*args, session=session, **kwargs)
  File "/home/***/.local/lib/python3.11/site-packages/***/models/taskinstance.py", line 3006, in _run_raw_task
    return _run_raw_task(
  File "/home/***/.local/lib/python3.11/site-packages/***/models/taskinstance.py", line 274, in _run_raw_task
    TaskInstance._execute_task_with_callbacks(
  File "/home/***/.local/lib/python3.11/site-packages/***/models/taskinstance.py", line 3161, in _execute_task_with_callbacks
    result = self._execute_task(context, task_orig)
  File "/home/***/.local/lib/python3.11/site-packages/***/models/taskinstance.py", line 3185, in _execute_task
    return _execute_task(self, context, task_orig)
  File "/home/***/.local/lib/python3.11/site-packages/***/models/taskinstance.py", line 768, in _execute_task
    result = _execute_callable(context=context, **execute_callable_kwargs)
  File "/home/***/.local/lib/python3.11/site-packages/***/models/taskinstance.py", line 734, in _execute_callable
    return ExecutionCallableRunner(
  File "/home/***/.local/lib/python3.11/site-packages/***/utils/operator_helpers.py", line 252, in run
    return self.func(*args, **kwargs)
  File "/home/***/.local/lib/python3.11/site-packages/***/models/baseoperator.py", line 424, in wrapper
    return func(self, *args, **kwargs)
  File "/home/***/.local/lib/python3.11/site-packages/***/operators/python.py", line 238, in execute
    return_value = self.execute_callable()
  File "/home/***/.local/lib/python3.11/site-packages/***/operators/python.py", line 256, in execute_callable
    return runner.run(*self.op_args, **self.op_kwargs)
  File "/home/***/.local/lib/python3.11/site-packages/***/utils/operator_helpers.py", line 252, in run
    return self.func(*args, **kwargs)
  File "/opt/***/scripts/insert_data_to_json.py", line 14, in insert_data_to_json
    extraire_banques()
  File "/opt/***/scripts/scraper_banks.py", line 403, in extraire_banques
    extraire_banques()  # Cette fonction remplit une variable `banques`, suppos√©e globale
  File "/opt/***/scripts/scraper_banks.py", line 403, in extraire_banques
    extraire_banques()  # Cette fonction remplit une variable `banques`, suppos√©e globale
  File "/opt/***/scripts/scraper_banks.py", line 338, in extraire_banques
    url = resultat.find_element(By.XPATH, ".//a").get_attribute("href")
  File "/home/***/venv/lib/python3.11/site-packages/selenium/webdriver/remote/webelement.py", line 178, in get_attribute
    attribute_value = self.parent.execute_script(
  File "/home/***/venv/lib/python3.11/site-packages/selenium/webdriver/remote/webdriver.py", line 500, in execute_script
    return self.execute(command, {"script": script, "args": converted_args})["value"]
  File "/home/***/venv/lib/python3.11/site-packages/selenium/webdriver/remote/webdriver.py", line 438, in execute
    response = self.command_executor.execute(driver_command, params)
  File "/home/***/venv/lib/python3.11/site-packages/selenium/webdriver/remote/remote_connection.py", line 290, in execute
    return self._request(command_info[0], url, body=data)
  File "/home/***/venv/lib/python3.11/site-packages/selenium/webdriver/remote/remote_connection.py", line 311, in _request
    response = self._conn.request(method, url, body=body, headers=headers)
  File "/home/***/venv/lib/python3.11/site-packages/urllib3/_request_methods.py", line 143, in request
    return self.request_encode_body(
  File "/home/***/venv/lib/python3.11/site-packages/urllib3/_request_methods.py", line 278, in request_encode_body
    return self.urlopen(method, url, **extra_kw)
  File "/home/***/venv/lib/python3.11/site-packages/urllib3/poolmanager.py", line 459, in urlopen
    response = conn.urlopen(method, u.request_uri, **kw)
  File "/home/***/venv/lib/python3.11/site-packages/urllib3/connectionpool.py", line 787, in urlopen
    response = self._make_request(
  File "/home/***/venv/lib/python3.11/site-packages/urllib3/connectionpool.py", line 534, in _make_request
    response = conn.getresponse()
  File "/home/***/venv/lib/python3.11/site-packages/urllib3/connection.py", line 565, in getresponse
    httplib_response = super().getresponse()
  File "/usr/local/lib/python3.11/http/client.py", line 1395, in getresponse
    response.begin()
  File "/usr/local/lib/python3.11/http/client.py", line 325, in begin
    version, status, reason = self._read_status()
  File "/usr/local/lib/python3.11/http/client.py", line 286, in _read_status
    line = str(self.fp.readline(_MAXLINE + 1), "iso-8859-1")
  File "/usr/local/lib/python3.11/socket.py", line 718, in readinto
    return self._sock.recv_into(b)
  File "/home/***/.local/lib/python3.11/site-packages/***/models/taskinstance.py", line 3095, in signal_handler
    self.log.error("Stacktrace: \n%s", "".join(traceback.format_stack()))

[2025-07-18T18:59:01.085+0000] {connectionpool.py:868} WARNING - Retrying (Retry(total=2, connect=None, read=None, redirect=None, status=None)) after connection broken by 'NewConnectionError('<urllib3.connection.HTTPConnection object at 0x7f597e4e9490>: Failed to establish a new connection: [Errno 111] Connection refused')': /session/adbc9b2656366f8075dd2dfd417cec33/element/f.DBEF3F4D3E74B534EE0ED772DF0E149C.d.BF26D41974FF003E9D85C996B9DC9E15.e.58/element
[2025-07-18T18:59:01.122+0000] {connectionpool.py:868} WARNING - Retrying (Retry(total=1, connect=None, read=None, redirect=None, status=None)) after connection broken by 'NewConnectionError('<urllib3.connection.HTTPConnection object at 0x7f597e4ea390>: Failed to establish a new connection: [Errno 111] Connection refused')': /session/adbc9b2656366f8075dd2dfd417cec33/element/f.DBEF3F4D3E74B534EE0ED772DF0E149C.d.BF26D41974FF003E9D85C996B9DC9E15.e.58/element
[2025-07-18T18:59:01.129+0000] {connectionpool.py:868} WARNING - Retrying (Retry(total=0, connect=None, read=None, redirect=None, status=None)) after connection broken by 'NewConnectionError('<urllib3.connection.HTTPConnection object at 0x7f597e4ead90>: Failed to establish a new connection: [Errno 111] Connection refused')': /session/adbc9b2656366f8075dd2dfd417cec33/element/f.DBEF3F4D3E74B534EE0ED772DF0E149C.d.BF26D41974FF003E9D85C996B9DC9E15.e.58/element
[2025-07-18T18:59:01.153+0000] {scraper_banks.py:372} INFO - üö´ Doublon ou donn√©es incompl√®tes : Bank Al Maghrib
[2025-07-18T18:59:01.162+0000] {connectionpool.py:868} WARNING - Retrying (Retry(total=2, connect=None, read=None, redirect=None, status=None)) after connection broken by 'NewConnectionError('<urllib3.connection.HTTPConnection object at 0x7f597e4f8210>: Failed to establish a new connection: [Errno 111] Connection refused')': /session/adbc9b2656366f8075dd2dfd417cec33/element/f.DBEF3F4D3E74B534EE0ED772DF0E149C.d.BF26D41974FF003E9D85C996B9DC9E15.e.59/element
[2025-07-18T18:59:01.173+0000] {connectionpool.py:868} WARNING - Retrying (Retry(total=1, connect=None, read=None, redirect=None, status=None)) after connection broken by 'NewConnectionError('<urllib3.connection.HTTPConnection object at 0x7f597e4f8d10>: Failed to establish a new connection: [Errno 111] Connection refused')': /session/adbc9b2656366f8075dd2dfd417cec33/element/f.DBEF3F4D3E74B534EE0ED772DF0E149C.d.BF26D41974FF003E9D85C996B9DC9E15.e.59/element
[2025-07-18T18:59:01.185+0000] {connectionpool.py:868} WARNING - Retrying (Retry(total=0, connect=None, read=None, redirect=None, status=None)) after connection broken by 'NewConnectionError('<urllib3.connection.HTTPConnection object at 0x7f597e4f9790>: Failed to establish a new connection: [Errno 111] Connection refused')': /session/adbc9b2656366f8075dd2dfd417cec33/element/f.DBEF3F4D3E74B534EE0ED772DF0E149C.d.BF26D41974FF003E9D85C996B9DC9E15.e.59/element
[2025-07-18T18:59:01.237+0000] {connectionpool.py:868} WARNING - Retrying (Retry(total=2, connect=None, read=None, redirect=None, status=None)) after connection broken by 'NewConnectionError('<urllib3.connection.HTTPConnection object at 0x7f597e4eab90>: Failed to establish a new connection: [Errno 111] Connection refused')': /session/adbc9b2656366f8075dd2dfd417cec33/execute/sync
[2025-07-18T18:59:01.241+0000] {connectionpool.py:868} WARNING - Retrying (Retry(total=1, connect=None, read=None, redirect=None, status=None)) after connection broken by 'NewConnectionError('<urllib3.connection.HTTPConnection object at 0x7f597e4eb510>: Failed to establish a new connection: [Errno 111] Connection refused')': /session/adbc9b2656366f8075dd2dfd417cec33/execute/sync
[2025-07-18T18:59:01.261+0000] {connectionpool.py:868} WARNING - Retrying (Retry(total=0, connect=None, read=None, redirect=None, status=None)) after connection broken by 'NewConnectionError('<urllib3.connection.HTTPConnection object at 0x7f597e4e9510>: Failed to establish a new connection: [Errno 111] Connection refused')': /session/adbc9b2656366f8075dd2dfd417cec33/execute/sync
[2025-07-18T18:59:01.290+0000] {connectionpool.py:868} WARNING - Retrying (Retry(total=2, connect=None, read=None, redirect=None, status=None)) after connection broken by 'NewConnectionError('<urllib3.connection.HTTPConnection object at 0x7f597e876410>: Failed to establish a new connection: [Errno 111] Connection refused')': /session/adbc9b2656366f8075dd2dfd417cec33/element/f.DBEF3F4D3E74B534EE0ED772DF0E149C.d.BF26D41974FF003E9D85C996B9DC9E15.e.60/element
[2025-07-18T18:59:01.295+0000] {connectionpool.py:868} WARNING - Retrying (Retry(total=1, connect=None, read=None, redirect=None, status=None)) after connection broken by 'NewConnectionError('<urllib3.connection.HTTPConnection object at 0x7f597e4fb350>: Failed to establish a new connection: [Errno 111] Connection refused')': /session/adbc9b2656366f8075dd2dfd417cec33/element/f.DBEF3F4D3E74B534EE0ED772DF0E149C.d.BF26D41974FF003E9D85C996B9DC9E15.e.60/element
[2025-07-18T18:59:01.302+0000] {connectionpool.py:868} WARNING - Retrying (Retry(total=0, connect=None, read=None, redirect=None, status=None)) after connection broken by 'NewConnectionError('<urllib3.connection.HTTPConnection object at 0x7f597e4fbd50>: Failed to establish a new connection: [Errno 111] Connection refused')': /session/adbc9b2656366f8075dd2dfd417cec33/element/f.DBEF3F4D3E74B534EE0ED772DF0E149C.d.BF26D41974FF003E9D85C996B9DC9E15.e.60/element
[2025-07-18T18:59:01.324+0000] {connectionpool.py:868} WARNING - Retrying (Retry(total=2, connect=None, read=None, redirect=None, status=None)) after connection broken by 'NewConnectionError('<urllib3.connection.HTTPConnection object at 0x7f597e509790>: Failed to establish a new connection: [Errno 111] Connection refused')': /session/adbc9b2656366f8075dd2dfd417cec33/execute/sync
[2025-07-18T18:59:01.349+0000] {connectionpool.py:868} WARNING - Retrying (Retry(total=1, connect=None, read=None, redirect=None, status=None)) after connection broken by 'NewConnectionError('<urllib3.connection.HTTPConnection object at 0x7f597e50a290>: Failed to establish a new connection: [Errno 111] Connection refused')': /session/adbc9b2656366f8075dd2dfd417cec33/execute/sync
[2025-07-18T18:59:01.367+0000] {connectionpool.py:868} WARNING - Retrying (Retry(total=0, connect=None, read=None, redirect=None, status=None)) after connection broken by 'NewConnectionError('<urllib3.connection.HTTPConnection object at 0x7f597e50ac50>: Failed to establish a new connection: [Errno 111] Connection refused')': /session/adbc9b2656366f8075dd2dfd417cec33/execute/sync
[2025-07-18T18:59:01.385+0000] {connectionpool.py:868} WARNING - Retrying (Retry(total=2, connect=None, read=None, redirect=None, status=None)) after connection broken by 'NewConnectionError('<urllib3.connection.HTTPConnection object at 0x7f597e50c350>: Failed to establish a new connection: [Errno 111] Connection refused')': /session/adbc9b2656366f8075dd2dfd417cec33/element/f.DBEF3F4D3E74B534EE0ED772DF0E149C.d.BF26D41974FF003E9D85C996B9DC9E15.e.61/element
[2025-07-18T18:59:01.392+0000] {connectionpool.py:868} WARNING - Retrying (Retry(total=1, connect=None, read=None, redirect=None, status=None)) after connection broken by 'NewConnectionError('<urllib3.connection.HTTPConnection object at 0x7f597e50d190>: Failed to establish a new connection: [Errno 111] Connection refused')': /session/adbc9b2656366f8075dd2dfd417cec33/element/f.DBEF3F4D3E74B534EE0ED772DF0E149C.d.BF26D41974FF003E9D85C996B9DC9E15.e.61/element
[2025-07-18T18:59:01.401+0000] {connectionpool.py:868} WARNING - Retrying (Retry(total=0, connect=None, read=None, redirect=None, status=None)) after connection broken by 'NewConnectionError('<urllib3.connection.HTTPConnection object at 0x7f597e50dcd0>: Failed to establish a new connection: [Errno 111] Connection refused')': /session/adbc9b2656366f8075dd2dfd417cec33/element/f.DBEF3F4D3E74B534EE0ED772DF0E149C.d.BF26D41974FF003E9D85C996B9DC9E15.e.61/element
[2025-07-18T18:59:01.409+0000] {connectionpool.py:868} WARNING - Retrying (Retry(total=2, connect=None, read=None, redirect=None, status=None)) after connection broken by 'NewConnectionError('<urllib3.connection.HTTPConnection object at 0x7f597e50a790>: Failed to establish a new connection: [Errno 111] Connection refused')': /session/adbc9b2656366f8075dd2dfd417cec33/execute/sync
[2025-07-18T18:59:01.414+0000] {connectionpool.py:868} WARNING - Retrying (Retry(total=1, connect=None, read=None, redirect=None, status=None)) after connection broken by 'NewConnectionError('<urllib3.connection.HTTPConnection object at 0x7f597e508a50>: Failed to establish a new connection: [Errno 111] Connection refused')': /session/adbc9b2656366f8075dd2dfd417cec33/execute/sync
[2025-07-18T18:59:01.419+0000] {connectionpool.py:868} WARNING - Retrying (Retry(total=0, connect=None, read=None, redirect=None, status=None)) after connection broken by 'NewConnectionError('<urllib3.connection.HTTPConnection object at 0x7f597e508650>: Failed to establish a new connection: [Errno 111] Connection refused')': /session/adbc9b2656366f8075dd2dfd417cec33/execute/sync
[2025-07-18T18:59:01.427+0000] {connectionpool.py:868} WARNING - Retrying (Retry(total=2, connect=None, read=None, redirect=None, status=None)) after connection broken by 'NewConnectionError('<urllib3.connection.HTTPConnection object at 0x7f597e4fbe50>: Failed to establish a new connection: [Errno 111] Connection refused')': /session/adbc9b2656366f8075dd2dfd417cec33/element/f.DBEF3F4D3E74B534EE0ED772DF0E149C.d.BF26D41974FF003E9D85C996B9DC9E15.e.62/element
[2025-07-18T18:59:01.432+0000] {connectionpool.py:868} WARNING - Retrying (Retry(total=1, connect=None, read=None, redirect=None, status=None)) after connection broken by 'NewConnectionError('<urllib3.connection.HTTPConnection object at 0x7f597e4facd0>: Failed to establish a new connection: [Errno 111] Connection refused')': /session/adbc9b2656366f8075dd2dfd417cec33/element/f.DBEF3F4D3E74B534EE0ED772DF0E149C.d.BF26D41974FF003E9D85C996B9DC9E15.e.62/element
[2025-07-18T18:59:01.442+0000] {connectionpool.py:868} WARNING - Retrying (Retry(total=0, connect=None, read=None, redirect=None, status=None)) after connection broken by 'NewConnectionError('<urllib3.connection.HTTPConnection object at 0x7f597d9e5410>: Failed to establish a new connection: [Errno 111] Connection refused')': /session/adbc9b2656366f8075dd2dfd417cec33/element/f.DBEF3F4D3E74B534EE0ED772DF0E149C.d.BF26D41974FF003E9D85C996B9DC9E15.e.62/element
[2025-07-18T18:59:01.461+0000] {connectionpool.py:868} WARNING - Retrying (Retry(total=2, connect=None, read=None, redirect=None, status=None)) after connection broken by 'NewConnectionError('<urllib3.connection.HTTPConnection object at 0x7f597e4ea250>: Failed to establish a new connection: [Errno 111] Connection refused')': /session/adbc9b2656366f8075dd2dfd417cec33/execute/sync
[2025-07-18T18:59:01.469+0000] {connectionpool.py:868} WARNING - Retrying (Retry(total=1, connect=None, read=None, redirect=None, status=None)) after connection broken by 'NewConnectionError('<urllib3.connection.HTTPConnection object at 0x7f597e4eb850>: Failed to establish a new connection: [Errno 111] Connection refused')': /session/adbc9b2656366f8075dd2dfd417cec33/execute/sync
[2025-07-18T18:59:01.473+0000] {connectionpool.py:868} WARNING - Retrying (Retry(total=0, connect=None, read=None, redirect=None, status=None)) after connection broken by 'NewConnectionError('<urllib3.connection.HTTPConnection object at 0x7f597e50e850>: Failed to establish a new connection: [Errno 111] Connection refused')': /session/adbc9b2656366f8075dd2dfd417cec33/execute/sync
[2025-07-18T18:59:01.503+0000] {connectionpool.py:868} WARNING - Retrying (Retry(total=2, connect=None, read=None, redirect=None, status=None)) after connection broken by 'NewConnectionError('<urllib3.connection.HTTPConnection object at 0x7f597e50fd10>: Failed to establish a new connection: [Errno 111] Connection refused')': /session/adbc9b2656366f8075dd2dfd417cec33/element/f.DBEF3F4D3E74B534EE0ED772DF0E149C.d.BF26D41974FF003E9D85C996B9DC9E15.e.63/element
[2025-07-18T18:59:01.515+0000] {connectionpool.py:868} WARNING - Retrying (Retry(total=1, connect=None, read=None, redirect=None, status=None)) after connection broken by 'NewConnectionError('<urllib3.connection.HTTPConnection object at 0x7f597e520850>: Failed to establish a new connection: [Errno 111] Connection refused')': /session/adbc9b2656366f8075dd2dfd417cec33/element/f.DBEF3F4D3E74B534EE0ED772DF0E149C.d.BF26D41974FF003E9D85C996B9DC9E15.e.63/element
[2025-07-18T18:59:01.521+0000] {connectionpool.py:868} WARNING - Retrying (Retry(total=0, connect=None, read=None, redirect=None, status=None)) after connection broken by 'NewConnectionError('<urllib3.connection.HTTPConnection object at 0x7f597e4ebcd0>: Failed to establish a new connection: [Errno 111] Connection refused')': /session/adbc9b2656366f8075dd2dfd417cec33/element/f.DBEF3F4D3E74B534EE0ED772DF0E149C.d.BF26D41974FF003E9D85C996B9DC9E15.e.63/element
[2025-07-18T18:59:01.537+0000] {connectionpool.py:868} WARNING - Retrying (Retry(total=2, connect=None, read=None, redirect=None, status=None)) after connection broken by 'NewConnectionError('<urllib3.connection.HTTPConnection object at 0x7f597e875f90>: Failed to establish a new connection: [Errno 111] Connection refused')': /session/adbc9b2656366f8075dd2dfd417cec33/execute/sync
[2025-07-18T18:59:01.542+0000] {connectionpool.py:868} WARNING - Retrying (Retry(total=1, connect=None, read=None, redirect=None, status=None)) after connection broken by 'NewConnectionError('<urllib3.connection.HTTPConnection object at 0x7f597e4faad0>: Failed to establish a new connection: [Errno 111] Connection refused')': /session/adbc9b2656366f8075dd2dfd417cec33/execute/sync
[2025-07-18T18:59:01.547+0000] {connectionpool.py:868} WARNING - Retrying (Retry(total=0, connect=None, read=None, redirect=None, status=None)) after connection broken by 'NewConnectionError('<urllib3.connection.HTTPConnection object at 0x7f597e4fbe90>: Failed to establish a new connection: [Errno 111] Connection refused')': /session/adbc9b2656366f8075dd2dfd417cec33/execute/sync
[2025-07-18T18:59:01.554+0000] {connectionpool.py:868} WARNING - Retrying (Retry(total=2, connect=None, read=None, redirect=None, status=None)) after connection broken by 'NewConnectionError('<urllib3.connection.HTTPConnection object at 0x7f597d921c90>: Failed to establish a new connection: [Errno 111] Connection refused')': /session/adbc9b2656366f8075dd2dfd417cec33/element/f.DBEF3F4D3E74B534EE0ED772DF0E149C.d.BF26D41974FF003E9D85C996B9DC9E15.e.64/element
[2025-07-18T18:59:01.559+0000] {connectionpool.py:868} WARNING - Retrying (Retry(total=1, connect=None, read=None, redirect=None, status=None)) after connection broken by 'NewConnectionError('<urllib3.connection.HTTPConnection object at 0x7f597e50ef90>: Failed to establish a new connection: [Errno 111] Connection refused')': /session/adbc9b2656366f8075dd2dfd417cec33/element/f.DBEF3F4D3E74B534EE0ED772DF0E149C.d.BF26D41974FF003E9D85C996B9DC9E15.e.64/element
[2025-07-18T18:59:01.563+0000] {connectionpool.py:868} WARNING - Retrying (Retry(total=0, connect=None, read=None, redirect=None, status=None)) after connection broken by 'NewConnectionError('<urllib3.connection.HTTPConnection object at 0x7f597e50e090>: Failed to establish a new connection: [Errno 111] Connection refused')': /session/adbc9b2656366f8075dd2dfd417cec33/element/f.DBEF3F4D3E74B534EE0ED772DF0E149C.d.BF26D41974FF003E9D85C996B9DC9E15.e.64/element
[2025-07-18T18:59:01.578+0000] {connectionpool.py:868} WARNING - Retrying (Retry(total=2, connect=None, read=None, redirect=None, status=None)) after connection broken by 'NewConnectionError('<urllib3.connection.HTTPConnection object at 0x7f597e50a650>: Failed to establish a new connection: [Errno 111] Connection refused')': /session/adbc9b2656366f8075dd2dfd417cec33/execute/sync
[2025-07-18T18:59:01.595+0000] {connectionpool.py:868} WARNING - Retrying (Retry(total=1, connect=None, read=None, redirect=None, status=None)) after connection broken by 'NewConnectionError('<urllib3.connection.HTTPConnection object at 0x7f597e50b350>: Failed to establish a new connection: [Errno 111] Connection refused')': /session/adbc9b2656366f8075dd2dfd417cec33/execute/sync
[2025-07-18T18:59:01.602+0000] {connectionpool.py:868} WARNING - Retrying (Retry(total=0, connect=None, read=None, redirect=None, status=None)) after connection broken by 'NewConnectionError('<urllib3.connection.HTTPConnection object at 0x7f597e5212d0>: Failed to establish a new connection: [Errno 111] Connection refused')': /session/adbc9b2656366f8075dd2dfd417cec33/execute/sync
[2025-07-18T18:59:01.616+0000] {connectionpool.py:868} WARNING - Retrying (Retry(total=2, connect=None, read=None, redirect=None, status=None)) after connection broken by 'NewConnectionError('<urllib3.connection.HTTPConnection object at 0x7f597e5227d0>: Failed to establish a new connection: [Errno 111] Connection refused')': /session/adbc9b2656366f8075dd2dfd417cec33/element/f.DBEF3F4D3E74B534EE0ED772DF0E149C.d.BF26D41974FF003E9D85C996B9DC9E15.e.65/element
[2025-07-18T18:59:01.622+0000] {connectionpool.py:868} WARNING - Retrying (Retry(total=1, connect=None, read=None, redirect=None, status=None)) after connection broken by 'NewConnectionError('<urllib3.connection.HTTPConnection object at 0x7f597e50af90>: Failed to establish a new connection: [Errno 111] Connection refused')': /session/adbc9b2656366f8075dd2dfd417cec33/element/f.DBEF3F4D3E74B534EE0ED772DF0E149C.d.BF26D41974FF003E9D85C996B9DC9E15.e.65/element
[2025-07-18T18:59:01.628+0000] {connectionpool.py:868} WARNING - Retrying (Retry(total=0, connect=None, read=None, redirect=None, status=None)) after connection broken by 'NewConnectionError('<urllib3.connection.HTTPConnection object at 0x7f597e50a250>: Failed to establish a new connection: [Errno 111] Connection refused')': /session/adbc9b2656366f8075dd2dfd417cec33/element/f.DBEF3F4D3E74B534EE0ED772DF0E149C.d.BF26D41974FF003E9D85C996B9DC9E15.e.65/element
[2025-07-18T18:59:01.642+0000] {connectionpool.py:868} WARNING - Retrying (Retry(total=2, connect=None, read=None, redirect=None, status=None)) after connection broken by 'NewConnectionError('<urllib3.connection.HTTPConnection object at 0x7f597eab8f90>: Failed to establish a new connection: [Errno 111] Connection refused')': /session/adbc9b2656366f8075dd2dfd417cec33/execute/sync
[2025-07-18T18:59:01.646+0000] {connectionpool.py:868} WARNING - Retrying (Retry(total=1, connect=None, read=None, redirect=None, status=None)) after connection broken by 'NewConnectionError('<urllib3.connection.HTTPConnection object at 0x7f597d908410>: Failed to establish a new connection: [Errno 111] Connection refused')': /session/adbc9b2656366f8075dd2dfd417cec33/execute/sync
[2025-07-18T18:59:01.653+0000] {connectionpool.py:868} WARNING - Retrying (Retry(total=0, connect=None, read=None, redirect=None, status=None)) after connection broken by 'NewConnectionError('<urllib3.connection.HTTPConnection object at 0x7f597e4fb390>: Failed to establish a new connection: [Errno 111] Connection refused')': /session/adbc9b2656366f8075dd2dfd417cec33/execute/sync
[2025-07-18T18:59:01.967+0000] {connectionpool.py:868} WARNING - Retrying (Retry(total=2, connect=None, read=None, redirect=None, status=None)) after connection broken by 'NewConnectionError('<urllib3.connection.HTTPConnection object at 0x7f597e50f0d0>: Failed to establish a new connection: [Errno 111] Connection refused')': /session/adbc9b2656366f8075dd2dfd417cec33/element/f.DBEF3F4D3E74B534EE0ED772DF0E149C.d.BF26D41974FF003E9D85C996B9DC9E15.e.66/element
[2025-07-18T18:59:01.975+0000] {connectionpool.py:868} WARNING - Retrying (Retry(total=1, connect=None, read=None, redirect=None, status=None)) after connection broken by 'NewConnectionError('<urllib3.connection.HTTPConnection object at 0x7f597e877d10>: Failed to establish a new connection: [Errno 111] Connection refused')': /session/adbc9b2656366f8075dd2dfd417cec33/element/f.DBEF3F4D3E74B534EE0ED772DF0E149C.d.BF26D41974FF003E9D85C996B9DC9E15.e.66/element
[2025-07-18T18:59:01.983+0000] {connectionpool.py:868} WARNING - Retrying (Retry(total=0, connect=None, read=None, redirect=None, status=None)) after connection broken by 'NewConnectionError('<urllib3.connection.HTTPConnection object at 0x7f597e4ea810>: Failed to establish a new connection: [Errno 111] Connection refused')': /session/adbc9b2656366f8075dd2dfd417cec33/element/f.DBEF3F4D3E74B534EE0ED772DF0E149C.d.BF26D41974FF003E9D85C996B9DC9E15.e.66/element
[2025-07-18T18:59:01.997+0000] {connectionpool.py:868} WARNING - Retrying (Retry(total=2, connect=None, read=None, redirect=None, status=None)) after connection broken by 'NewConnectionError('<urllib3.connection.HTTPConnection object at 0x7f597e521250>: Failed to establish a new connection: [Errno 111] Connection refused')': /session/adbc9b2656366f8075dd2dfd417cec33/execute/sync
[2025-07-18T18:59:02.003+0000] {connectionpool.py:868} WARNING - Retrying (Retry(total=1, connect=None, read=None, redirect=None, status=None)) after connection broken by 'NewConnectionError('<urllib3.connection.HTTPConnection object at 0x7f597e5217d0>: Failed to establish a new connection: [Errno 111] Connection refused')': /session/adbc9b2656366f8075dd2dfd417cec33/execute/sync
[2025-07-18T18:59:02.016+0000] {connectionpool.py:868} WARNING - Retrying (Retry(total=0, connect=None, read=None, redirect=None, status=None)) after connection broken by 'NewConnectionError('<urllib3.connection.HTTPConnection object at 0x7f597e523210>: Failed to establish a new connection: [Errno 111] Connection refused')': /session/adbc9b2656366f8075dd2dfd417cec33/execute/sync
[2025-07-18T18:59:02.034+0000] {connectionpool.py:868} WARNING - Retrying (Retry(total=2, connect=None, read=None, redirect=None, status=None)) after connection broken by 'NewConnectionError('<urllib3.connection.HTTPConnection object at 0x7f597e4fbd90>: Failed to establish a new connection: [Errno 111] Connection refused')': /session/adbc9b2656366f8075dd2dfd417cec33/element/f.DBEF3F4D3E74B534EE0ED772DF0E149C.d.BF26D41974FF003E9D85C996B9DC9E15.e.67/element
[2025-07-18T18:59:02.041+0000] {connectionpool.py:868} WARNING - Retrying (Retry(total=1, connect=None, read=None, redirect=None, status=None)) after connection broken by 'NewConnectionError('<urllib3.connection.HTTPConnection object at 0x7f597d909f50>: Failed to establish a new connection: [Errno 111] Connection refused')': /session/adbc9b2656366f8075dd2dfd417cec33/element/f.DBEF3F4D3E74B534EE0ED772DF0E149C.d.BF26D41974FF003E9D85C996B9DC9E15.e.67/element
[2025-07-18T18:59:02.049+0000] {connectionpool.py:868} WARNING - Retrying (Retry(total=0, connect=None, read=None, redirect=None, status=None)) after connection broken by 'NewConnectionError('<urllib3.connection.HTTPConnection object at 0x7f597eabb150>: Failed to establish a new connection: [Errno 111] Connection refused')': /session/adbc9b2656366f8075dd2dfd417cec33/element/f.DBEF3F4D3E74B534EE0ED772DF0E149C.d.BF26D41974FF003E9D85C996B9DC9E15.e.67/element
[2025-07-18T18:59:02.048+0000] {process_utils.py:80} INFO - Process psutil.Process(pid=120, status='terminated', started='18:38:32') (120) terminated with exit code None
[2025-07-18T18:59:02.062+0000] {connectionpool.py:868} WARNING - Retrying (Retry(total=2, connect=None, read=None, redirect=None, status=None)) after connection broken by 'NewConnectionError('<urllib3.connection.HTTPConnection object at 0x7f597e50ad10>: Failed to establish a new connection: [Errno 111] Connection refused')': /session/adbc9b2656366f8075dd2dfd417cec33/execute/sync
[2025-07-18T18:59:02.065+0000] {connectionpool.py:868} WARNING - Retrying (Retry(total=1, connect=None, read=None, redirect=None, status=None)) after connection broken by 'NewConnectionError('<urllib3.connection.HTTPConnection object at 0x7f597e50b910>: Failed to establish a new connection: [Errno 111] Connection refused')': /session/adbc9b2656366f8075dd2dfd417cec33/execute/sync
[2025-07-18T18:59:02.069+0000] {connectionpool.py:868} WARNING - Retrying (Retry(total=0, connect=None, read=None, redirect=None, status=None)) after connection broken by 'NewConnectionError('<urllib3.connection.HTTPConnection object at 0x7f597e50a110>: Failed to establish a new connection: [Errno 111] Connection refused')': /session/adbc9b2656366f8075dd2dfd417cec33/execute/sync
[2025-07-18T18:59:02.078+0000] {connectionpool.py:868} WARNING - Retrying (Retry(total=2, connect=None, read=None, redirect=None, status=None)) after connection broken by 'NewConnectionError('<urllib3.connection.HTTPConnection object at 0x7f597e52d890>: Failed to establish a new connection: [Errno 111] Connection refused')': /session/adbc9b2656366f8075dd2dfd417cec33/element/f.DBEF3F4D3E74B534EE0ED772DF0E149C.d.BF26D41974FF003E9D85C996B9DC9E15.e.68/element
[2025-07-18T18:59:02.083+0000] {connectionpool.py:868} WARNING - Retrying (Retry(total=1, connect=None, read=None, redirect=None, status=None)) after connection broken by 'NewConnectionError('<urllib3.connection.HTTPConnection object at 0x7f597e52e550>: Failed to establish a new connection: [Errno 111] Connection refused')': /session/adbc9b2656366f8075dd2dfd417cec33/element/f.DBEF3F4D3E74B534EE0ED772DF0E149C.d.BF26D41974FF003E9D85C996B9DC9E15.e.68/element
[2025-07-18T18:59:02.087+0000] {connectionpool.py:868} WARNING - Retrying (Retry(total=0, connect=None, read=None, redirect=None, status=None)) after connection broken by 'NewConnectionError('<urllib3.connection.HTTPConnection object at 0x7f597e52f110>: Failed to establish a new connection: [Errno 111] Connection refused')': /session/adbc9b2656366f8075dd2dfd417cec33/element/f.DBEF3F4D3E74B534EE0ED772DF0E149C.d.BF26D41974FF003E9D85C996B9DC9E15.e.68/element
[2025-07-18T18:59:02.119+0000] {connectionpool.py:868} WARNING - Retrying (Retry(total=2, connect=None, read=None, redirect=None, status=None)) after connection broken by 'NewConnectionError('<urllib3.connection.HTTPConnection object at 0x7f597e538d50>: Failed to establish a new connection: [Errno 111] Connection refused')': /session/adbc9b2656366f8075dd2dfd417cec33/execute/sync
[2025-07-18T18:59:02.134+0000] {connectionpool.py:868} WARNING - Retrying (Retry(total=1, connect=None, read=None, redirect=None, status=None)) after connection broken by 'NewConnectionError('<urllib3.connection.HTTPConnection object at 0x7f597e539910>: Failed to establish a new connection: [Errno 111] Connection refused')': /session/adbc9b2656366f8075dd2dfd417cec33/execute/sync
[2025-07-18T18:59:02.139+0000] {connectionpool.py:868} WARNING - Retrying (Retry(total=0, connect=None, read=None, redirect=None, status=None)) after connection broken by 'NewConnectionError('<urllib3.connection.HTTPConnection object at 0x7f597e52c410>: Failed to establish a new connection: [Errno 111] Connection refused')': /session/adbc9b2656366f8075dd2dfd417cec33/execute/sync
[2025-07-18T18:59:02.148+0000] {connectionpool.py:868} WARNING - Retrying (Retry(total=2, connect=None, read=None, redirect=None, status=None)) after connection broken by 'NewConnectionError('<urllib3.connection.HTTPConnection object at 0x7f597e50a350>: Failed to establish a new connection: [Errno 111] Connection refused')': /session/adbc9b2656366f8075dd2dfd417cec33/element/f.DBEF3F4D3E74B534EE0ED772DF0E149C.d.BF26D41974FF003E9D85C996B9DC9E15.e.69/element
[2025-07-18T18:59:02.153+0000] {connectionpool.py:868} WARNING - Retrying (Retry(total=1, connect=None, read=None, redirect=None, status=None)) after connection broken by 'NewConnectionError('<urllib3.connection.HTTPConnection object at 0x7f597e50b9d0>: Failed to establish a new connection: [Errno 111] Connection refused')': /session/adbc9b2656366f8075dd2dfd417cec33/element/f.DBEF3F4D3E74B534EE0ED772DF0E149C.d.BF26D41974FF003E9D85C996B9DC9E15.e.69/element
[2025-07-18T18:59:02.159+0000] {connectionpool.py:868} WARNING - Retrying (Retry(total=0, connect=None, read=None, redirect=None, status=None)) after connection broken by 'NewConnectionError('<urllib3.connection.HTTPConnection object at 0x7f597e940e90>: Failed to establish a new connection: [Errno 111] Connection refused')': /session/adbc9b2656366f8075dd2dfd417cec33/element/f.DBEF3F4D3E74B534EE0ED772DF0E149C.d.BF26D41974FF003E9D85C996B9DC9E15.e.69/element
[2025-07-18T18:59:02.170+0000] {connectionpool.py:868} WARNING - Retrying (Retry(total=2, connect=None, read=None, redirect=None, status=None)) after connection broken by 'NewConnectionError('<urllib3.connection.HTTPConnection object at 0x7f597e4fbb90>: Failed to establish a new connection: [Errno 111] Connection refused')': /session/adbc9b2656366f8075dd2dfd417cec33/execute/sync
[2025-07-18T18:59:02.176+0000] {connectionpool.py:868} WARNING - Retrying (Retry(total=1, connect=None, read=None, redirect=None, status=None)) after connection broken by 'NewConnectionError('<urllib3.connection.HTTPConnection object at 0x7f597e5394d0>: Failed to establish a new connection: [Errno 111] Connection refused')': /session/adbc9b2656366f8075dd2dfd417cec33/execute/sync
[2025-07-18T18:59:02.191+0000] {connectionpool.py:868} WARNING - Retrying (Retry(total=0, connect=None, read=None, redirect=None, status=None)) after connection broken by 'NewConnectionError('<urllib3.connection.HTTPConnection object at 0x7f597e53aa50>: Failed to establish a new connection: [Errno 111] Connection refused')': /session/adbc9b2656366f8075dd2dfd417cec33/execute/sync
[2025-07-18T18:59:02.214+0000] {connectionpool.py:868} WARNING - Retrying (Retry(total=2, connect=None, read=None, redirect=None, status=None)) after connection broken by 'NewConnectionError('<urllib3.connection.HTTPConnection object at 0x7f597e544090>: Failed to establish a new connection: [Errno 111] Connection refused')': /session/adbc9b2656366f8075dd2dfd417cec33/element/f.DBEF3F4D3E74B534EE0ED772DF0E149C.d.BF26D41974FF003E9D85C996B9DC9E15.e.70/element
[2025-07-18T18:59:02.218+0000] {connectionpool.py:868} WARNING - Retrying (Retry(total=1, connect=None, read=None, redirect=None, status=None)) after connection broken by 'NewConnectionError('<urllib3.connection.HTTPConnection object at 0x7f597e544d90>: Failed to establish a new connection: [Errno 111] Connection refused')': /session/adbc9b2656366f8075dd2dfd417cec33/element/f.DBEF3F4D3E74B534EE0ED772DF0E149C.d.BF26D41974FF003E9D85C996B9DC9E15.e.70/element
[2025-07-18T18:59:02.221+0000] {connectionpool.py:868} WARNING - Retrying (Retry(total=0, connect=None, read=None, redirect=None, status=None)) after connection broken by 'NewConnectionError('<urllib3.connection.HTTPConnection object at 0x7f597e5459d0>: Failed to establish a new connection: [Errno 111] Connection refused')': /session/adbc9b2656366f8075dd2dfd417cec33/element/f.DBEF3F4D3E74B534EE0ED772DF0E149C.d.BF26D41974FF003E9D85C996B9DC9E15.e.70/element
[2025-07-18T18:59:02.229+0000] {connectionpool.py:868} WARNING - Retrying (Retry(total=2, connect=None, read=None, redirect=None, status=None)) after connection broken by 'NewConnectionError('<urllib3.connection.HTTPConnection object at 0x7f597d9da8d0>: Failed to establish a new connection: [Errno 111] Connection refused')': /session/adbc9b2656366f8075dd2dfd417cec33/execute/sync
[2025-07-18T18:59:02.234+0000] {connectionpool.py:868} WARNING - Retrying (Retry(total=1, connect=None, read=None, redirect=None, status=None)) after connection broken by 'NewConnectionError('<urllib3.connection.HTTPConnection object at 0x7f597d90bb50>: Failed to establish a new connection: [Errno 111] Connection refused')': /session/adbc9b2656366f8075dd2dfd417cec33/execute/sync
[2025-07-18T18:59:02.237+0000] {connectionpool.py:868} WARNING - Retrying (Retry(total=0, connect=None, read=None, redirect=None, status=None)) after connection broken by 'NewConnectionError('<urllib3.connection.HTTPConnection object at 0x7f597e940bd0>: Failed to establish a new connection: [Errno 111] Connection refused')': /session/adbc9b2656366f8075dd2dfd417cec33/execute/sync
[2025-07-18T18:59:02.244+0000] {process_utils.py:80} INFO - Process psutil.Process(pid=414, status='terminated', started='18:44:41') (414) terminated with exit code None
[2025-07-18T18:59:02.245+0000] {connectionpool.py:868} WARNING - Retrying (Retry(total=2, connect=None, read=None, redirect=None, status=None)) after connection broken by 'NewConnectionError('<urllib3.connection.HTTPConnection object at 0x7f597e508710>: Failed to establish a new connection: [Errno 111] Connection refused')': /session/adbc9b2656366f8075dd2dfd417cec33/element/f.DBEF3F4D3E74B534EE0ED772DF0E149C.d.BF26D41974FF003E9D85C996B9DC9E15.e.71/element
[2025-07-18T18:59:02.251+0000] {process_utils.py:80} INFO - Process psutil.Process(pid=119, status='terminated', started='18:38:32') (119) terminated with exit code None
[2025-07-18T18:59:02.253+0000] {connectionpool.py:868} WARNING - Retrying (Retry(total=1, connect=None, read=None, redirect=None, status=None)) after connection broken by 'NewConnectionError('<urllib3.connection.HTTPConnection object at 0x7f597e50bb10>: Failed to establish a new connection: [Errno 111] Connection refused')': /session/adbc9b2656366f8075dd2dfd417cec33/element/f.DBEF3F4D3E74B534EE0ED772DF0E149C.d.BF26D41974FF003E9D85C996B9DC9E15.e.71/element
[2025-07-18T18:59:02.258+0000] {connectionpool.py:868} WARNING - Retrying (Retry(total=0, connect=None, read=None, redirect=None, status=None)) after connection broken by 'NewConnectionError('<urllib3.connection.HTTPConnection object at 0x7f597e53b750>: Failed to establish a new connection: [Errno 111] Connection refused')': /session/adbc9b2656366f8075dd2dfd417cec33/element/f.DBEF3F4D3E74B534EE0ED772DF0E149C.d.BF26D41974FF003E9D85C996B9DC9E15.e.71/element
[2025-07-18T18:59:02.271+0000] {connectionpool.py:868} WARNING - Retrying (Retry(total=2, connect=None, read=None, redirect=None, status=None)) after connection broken by 'NewConnectionError('<urllib3.connection.HTTPConnection object at 0x7f597e52c6d0>: Failed to establish a new connection: [Errno 111] Connection refused')': /session/adbc9b2656366f8075dd2dfd417cec33/execute/sync
[2025-07-18T18:59:02.284+0000] {connectionpool.py:868} WARNING - Retrying (Retry(total=1, connect=None, read=None, redirect=None, status=None)) after connection broken by 'NewConnectionError('<urllib3.connection.HTTPConnection object at 0x7f597e547510>: Failed to establish a new connection: [Errno 111] Connection refused')': /session/adbc9b2656366f8075dd2dfd417cec33/execute/sync
[2025-07-18T18:59:02.296+0000] {connectionpool.py:868} WARNING - Retrying (Retry(total=0, connect=None, read=None, redirect=None, status=None)) after connection broken by 'NewConnectionError('<urllib3.connection.HTTPConnection object at 0x7f597e547fd0>: Failed to establish a new connection: [Errno 111] Connection refused')': /session/adbc9b2656366f8075dd2dfd417cec33/execute/sync
[2025-07-18T18:59:02.309+0000] {connectionpool.py:868} WARNING - Retrying (Retry(total=2, connect=None, read=None, redirect=None, status=None)) after connection broken by 'NewConnectionError('<urllib3.connection.HTTPConnection object at 0x7f597e54d850>: Failed to establish a new connection: [Errno 111] Connection refused')': /session/adbc9b2656366f8075dd2dfd417cec33/element/f.DBEF3F4D3E74B534EE0ED772DF0E149C.d.BF26D41974FF003E9D85C996B9DC9E15.e.72/element
[2025-07-18T18:59:02.313+0000] {connectionpool.py:868} WARNING - Retrying (Retry(total=1, connect=None, read=None, redirect=None, status=None)) after connection broken by 'NewConnectionError('<urllib3.connection.HTTPConnection object at 0x7f597e54e510>: Failed to establish a new connection: [Errno 111] Connection refused')': /session/adbc9b2656366f8075dd2dfd417cec33/element/f.DBEF3F4D3E74B534EE0ED772DF0E149C.d.BF26D41974FF003E9D85C996B9DC9E15.e.72/element
[2025-07-18T18:59:02.317+0000] {connectionpool.py:868} WARNING - Retrying (Retry(total=0, connect=None, read=None, redirect=None, status=None)) after connection broken by 'NewConnectionError('<urllib3.connection.HTTPConnection object at 0x7f597e52c450>: Failed to establish a new connection: [Errno 111] Connection refused')': /session/adbc9b2656366f8075dd2dfd417cec33/element/f.DBEF3F4D3E74B534EE0ED772DF0E149C.d.BF26D41974FF003E9D85C996B9DC9E15.e.72/element
[2025-07-18T18:59:02.324+0000] {connectionpool.py:868} WARNING - Retrying (Retry(total=2, connect=None, read=None, redirect=None, status=None)) after connection broken by 'NewConnectionError('<urllib3.connection.HTTPConnection object at 0x7f597e53b150>: Failed to establish a new connection: [Errno 111] Connection refused')': /session/adbc9b2656366f8075dd2dfd417cec33/execute/sync
[2025-07-18T18:59:02.327+0000] {connectionpool.py:868} WARNING - Retrying (Retry(total=1, connect=None, read=None, redirect=None, status=None)) after connection broken by 'NewConnectionError('<urllib3.connection.HTTPConnection object at 0x7f597e50b510>: Failed to establish a new connection: [Errno 111] Connection refused')': /session/adbc9b2656366f8075dd2dfd417cec33/execute/sync
[2025-07-18T18:59:02.330+0000] {connectionpool.py:868} WARNING - Retrying (Retry(total=0, connect=None, read=None, redirect=None, status=None)) after connection broken by 'NewConnectionError('<urllib3.connection.HTTPConnection object at 0x7f597e50a910>: Failed to establish a new connection: [Errno 111] Connection refused')': /session/adbc9b2656366f8075dd2dfd417cec33/execute/sync
[2025-07-18T18:59:02.340+0000] {connectionpool.py:868} WARNING - Retrying (Retry(total=2, connect=None, read=None, redirect=None, status=None)) after connection broken by 'NewConnectionError('<urllib3.connection.HTTPConnection object at 0x7f597d9089d0>: Failed to establish a new connection: [Errno 111] Connection refused')': /session/adbc9b2656366f8075dd2dfd417cec33/element/f.DBEF3F4D3E74B534EE0ED772DF0E149C.d.BF26D41974FF003E9D85C996B9DC9E15.e.73/element
[2025-07-18T18:59:02.344+0000] {connectionpool.py:868} WARNING - Retrying (Retry(total=1, connect=None, read=None, redirect=None, status=None)) after connection broken by 'NewConnectionError('<urllib3.connection.HTTPConnection object at 0x7f597e4fb110>: Failed to establish a new connection: [Errno 111] Connection refused')': /session/adbc9b2656366f8075dd2dfd417cec33/element/f.DBEF3F4D3E74B534EE0ED772DF0E149C.d.BF26D41974FF003E9D85C996B9DC9E15.e.73/element
[2025-07-18T18:59:02.347+0000] {connectionpool.py:868} WARNING - Retrying (Retry(total=0, connect=None, read=None, redirect=None, status=None)) after connection broken by 'NewConnectionError('<urllib3.connection.HTTPConnection object at 0x7f597e522950>: Failed to establish a new connection: [Errno 111] Connection refused')': /session/adbc9b2656366f8075dd2dfd417cec33/element/f.DBEF3F4D3E74B534EE0ED772DF0E149C.d.BF26D41974FF003E9D85C996B9DC9E15.e.73/element
[2025-07-18T18:59:02.349+0000] {process_utils.py:80} INFO - Process psutil.Process(pid=415, status='terminated', started='18:44:41') (415) terminated with exit code None
[2025-07-18T18:59:02.353+0000] {connectionpool.py:868} WARNING - Retrying (Retry(total=2, connect=None, read=None, redirect=None, status=None)) after connection broken by 'NewConnectionError('<urllib3.connection.HTTPConnection object at 0x7f597e54ce50>: Failed to establish a new connection: [Errno 111] Connection refused')': /session/adbc9b2656366f8075dd2dfd417cec33/execute/sync
[2025-07-18T18:59:02.353+0000] {process_utils.py:80} INFO - Process psutil.Process(pid=405, status='terminated', started='18:44:40') (405) terminated with exit code None
[2025-07-18T18:59:02.357+0000] {connectionpool.py:868} WARNING - Retrying (Retry(total=1, connect=None, read=None, redirect=None, status=None)) after connection broken by 'NewConnectionError('<urllib3.connection.HTTPConnection object at 0x7f597e54c0d0>: Failed to establish a new connection: [Errno 111] Connection refused')': /session/adbc9b2656366f8075dd2dfd417cec33/execute/sync
[2025-07-18T18:59:02.356+0000] {process_utils.py:80} INFO - Process psutil.Process(pid=499, status='terminated', started='18:45:15') (499) terminated with exit code None
[2025-07-18T18:59:02.360+0000] {connectionpool.py:868} WARNING - Retrying (Retry(total=0, connect=None, read=None, redirect=None, status=None)) after connection broken by 'NewConnectionError('<urllib3.connection.HTTPConnection object at 0x7f597e54f810>: Failed to establish a new connection: [Errno 111] Connection refused')': /session/adbc9b2656366f8075dd2dfd417cec33/execute/sync
[2025-07-18T18:59:02.366+0000] {connectionpool.py:868} WARNING - Retrying (Retry(total=2, connect=None, read=None, redirect=None, status=None)) after connection broken by 'NewConnectionError('<urllib3.connection.HTTPConnection object at 0x7f597e55ce10>: Failed to establish a new connection: [Errno 111] Connection refused')': /session/adbc9b2656366f8075dd2dfd417cec33/element/f.DBEF3F4D3E74B534EE0ED772DF0E149C.d.BF26D41974FF003E9D85C996B9DC9E15.e.74/element
[2025-07-18T18:59:02.374+0000] {connectionpool.py:868} WARNING - Retrying (Retry(total=1, connect=None, read=None, redirect=None, status=None)) after connection broken by 'NewConnectionError('<urllib3.connection.HTTPConnection object at 0x7f597e5468d0>: Failed to establish a new connection: [Errno 111] Connection refused')': /session/adbc9b2656366f8075dd2dfd417cec33/element/f.DBEF3F4D3E74B534EE0ED772DF0E149C.d.BF26D41974FF003E9D85C996B9DC9E15.e.74/element
[2025-07-18T18:59:02.379+0000] {connectionpool.py:868} WARNING - Retrying (Retry(total=0, connect=None, read=None, redirect=None, status=None)) after connection broken by 'NewConnectionError('<urllib3.connection.HTTPConnection object at 0x7f597e547bd0>: Failed to establish a new connection: [Errno 111] Connection refused')': /session/adbc9b2656366f8075dd2dfd417cec33/element/f.DBEF3F4D3E74B534EE0ED772DF0E149C.d.BF26D41974FF003E9D85C996B9DC9E15.e.74/element
[2025-07-18T18:59:02.386+0000] {connectionpool.py:868} WARNING - Retrying (Retry(total=2, connect=None, read=None, redirect=None, status=None)) after connection broken by 'NewConnectionError('<urllib3.connection.HTTPConnection object at 0x7f597e940ad0>: Failed to establish a new connection: [Errno 111] Connection refused')': /session/adbc9b2656366f8075dd2dfd417cec33/execute/sync
[2025-07-18T18:59:02.391+0000] {connectionpool.py:868} WARNING - Retrying (Retry(total=1, connect=None, read=None, redirect=None, status=None)) after connection broken by 'NewConnectionError('<urllib3.connection.HTTPConnection object at 0x7f597e509ed0>: Failed to establish a new connection: [Errno 111] Connection refused')': /session/adbc9b2656366f8075dd2dfd417cec33/execute/sync
[2025-07-18T18:59:02.394+0000] {connectionpool.py:868} WARNING - Retrying (Retry(total=0, connect=None, read=None, redirect=None, status=None)) after connection broken by 'NewConnectionError('<urllib3.connection.HTTPConnection object at 0x7f597e50bb10>: Failed to establish a new connection: [Errno 111] Connection refused')': /session/adbc9b2656366f8075dd2dfd417cec33/execute/sync
[2025-07-18T18:59:02.400+0000] {connectionpool.py:868} WARNING - Retrying (Retry(total=2, connect=None, read=None, redirect=None, status=None)) after connection broken by 'NewConnectionError('<urllib3.connection.HTTPConnection object at 0x7f597e53b350>: Failed to establish a new connection: [Errno 111] Connection refused')': /session/adbc9b2656366f8075dd2dfd417cec33/element/f.DBEF3F4D3E74B534EE0ED772DF0E149C.d.BF26D41974FF003E9D85C996B9DC9E15.e.75/element
[2025-07-18T18:59:02.405+0000] {connectionpool.py:868} WARNING - Retrying (Retry(total=1, connect=None, read=None, redirect=None, status=None)) after connection broken by 'NewConnectionError('<urllib3.connection.HTTPConnection object at 0x7f59843e9b50>: Failed to establish a new connection: [Errno 111] Connection refused')': /session/adbc9b2656366f8075dd2dfd417cec33/element/f.DBEF3F4D3E74B534EE0ED772DF0E149C.d.BF26D41974FF003E9D85C996B9DC9E15.e.75/element
[2025-07-18T18:59:02.409+0000] {connectionpool.py:868} WARNING - Retrying (Retry(total=0, connect=None, read=None, redirect=None, status=None)) after connection broken by 'NewConnectionError('<urllib3.connection.HTTPConnection object at 0x7f597e54ff90>: Failed to establish a new connection: [Errno 111] Connection refused')': /session/adbc9b2656366f8075dd2dfd417cec33/element/f.DBEF3F4D3E74B534EE0ED772DF0E149C.d.BF26D41974FF003E9D85C996B9DC9E15.e.75/element
[2025-07-18T18:59:02.415+0000] {connectionpool.py:868} WARNING - Retrying (Retry(total=2, connect=None, read=None, redirect=None, status=None)) after connection broken by 'NewConnectionError('<urllib3.connection.HTTPConnection object at 0x7f597e54e710>: Failed to establish a new connection: [Errno 111] Connection refused')': /session/adbc9b2656366f8075dd2dfd417cec33/execute/sync
[2025-07-18T18:59:02.419+0000] {connectionpool.py:868} WARNING - Retrying (Retry(total=1, connect=None, read=None, redirect=None, status=None)) after connection broken by 'NewConnectionError('<urllib3.connection.HTTPConnection object at 0x7f597e55c310>: Failed to establish a new connection: [Errno 111] Connection refused')': /session/adbc9b2656366f8075dd2dfd417cec33/execute/sync
[2025-07-18T18:59:02.422+0000] {connectionpool.py:868} WARNING - Retrying (Retry(total=0, connect=None, read=None, redirect=None, status=None)) after connection broken by 'NewConnectionError('<urllib3.connection.HTTPConnection object at 0x7f597e55d950>: Failed to establish a new connection: [Errno 111] Connection refused')': /session/adbc9b2656366f8075dd2dfd417cec33/execute/sync
[2025-07-18T18:59:02.433+0000] {connectionpool.py:868} WARNING - Retrying (Retry(total=2, connect=None, read=None, redirect=None, status=None)) after connection broken by 'NewConnectionError('<urllib3.connection.HTTPConnection object at 0x7f597e54e490>: Failed to establish a new connection: [Errno 111] Connection refused')': /session/adbc9b2656366f8075dd2dfd417cec33/element/f.DBEF3F4D3E74B534EE0ED772DF0E149C.d.BF26D41974FF003E9D85C996B9DC9E15.e.76/element
[2025-07-18T18:59:02.437+0000] {connectionpool.py:868} WARNING - Retrying (Retry(total=1, connect=None, read=None, redirect=None, status=None)) after connection broken by 'NewConnectionError('<urllib3.connection.HTTPConnection object at 0x7f597e54d610>: Failed to establish a new connection: [Errno 111] Connection refused')': /session/adbc9b2656366f8075dd2dfd417cec33/element/f.DBEF3F4D3E74B534EE0ED772DF0E149C.d.BF26D41974FF003E9D85C996B9DC9E15.e.76/element
[2025-07-18T18:59:02.443+0000] {connectionpool.py:868} WARNING - Retrying (Retry(total=0, connect=None, read=None, redirect=None, status=None)) after connection broken by 'NewConnectionError('<urllib3.connection.HTTPConnection object at 0x7f597e5475d0>: Failed to establish a new connection: [Errno 111] Connection refused')': /session/adbc9b2656366f8075dd2dfd417cec33/element/f.DBEF3F4D3E74B534EE0ED772DF0E149C.d.BF26D41974FF003E9D85C996B9DC9E15.e.76/element
[2025-07-18T18:59:02.452+0000] {connectionpool.py:868} WARNING - Retrying (Retry(total=2, connect=None, read=None, redirect=None, status=None)) after connection broken by 'NewConnectionError('<urllib3.connection.HTTPConnection object at 0x7f597e545890>: Failed to establish a new connection: [Errno 111] Connection refused')': /session/adbc9b2656366f8075dd2dfd417cec33/execute/sync
[2025-07-18T18:59:02.456+0000] {connectionpool.py:868} WARNING - Retrying (Retry(total=1, connect=None, read=None, redirect=None, status=None)) after connection broken by 'NewConnectionError('<urllib3.connection.HTTPConnection object at 0x7f597e546a50>: Failed to establish a new connection: [Errno 111] Connection refused')': /session/adbc9b2656366f8075dd2dfd417cec33/execute/sync
[2025-07-18T18:59:02.460+0000] {connectionpool.py:868} WARNING - Retrying (Retry(total=0, connect=None, read=None, redirect=None, status=None)) after connection broken by 'NewConnectionError('<urllib3.connection.HTTPConnection object at 0x7f597e53b7d0>: Failed to establish a new connection: [Errno 111] Connection refused')': /session/adbc9b2656366f8075dd2dfd417cec33/execute/sync
[2025-07-18T18:59:02.466+0000] {scraper_banks.py:378} INFO - [Casablanca] Aucune banque enregistr√©e
[2025-07-18T18:59:02.469+0000] {scraper_banks.py:379} INFO - ‚úÖ [Casablanca] Extraction termin√©e
[2025-07-18T18:59:02.546+0000] {process_utils.py:80} INFO - Process psutil.Process(pid=149, status='terminated', started='18:38:39') (149) terminated with exit code None
[2025-07-18T18:59:02.735+0000] {process_utils.py:80} INFO - Process psutil.Process(pid=115, status='terminated', started='18:38:29') (115) terminated with exit code None
[2025-07-18T18:59:03.022+0000] {process_utils.py:80} INFO - Process psutil.Process(pid=852, status='terminated', started='18:51:54') (852) terminated with exit code None
[2025-07-18T18:59:03.202+0000] {process_utils.py:80} INFO - Process psutil.Process(pid=827, status='terminated', started='18:51:53') (827) terminated with exit code None
[2025-07-18T18:59:03.205+0000] {process_utils.py:80} INFO - Process psutil.Process(pid=828, status='terminated', started='18:51:53') (828) terminated with exit code None
[2025-07-18T18:59:03.211+0000] {process_utils.py:80} INFO - Process psutil.Process(pid=818, status='terminated', started='18:51:53') (818) terminated with exit code None
[2025-07-18T18:59:04.020+0000] {logger.py:11} INFO - ====== WebDriver manager ======
[2025-07-18T18:59:14.675+0000] {logger.py:11} INFO - Get LATEST chromedriver version for google-chrome
[2025-07-18T18:59:21.551+0000] {logger.py:11} INFO - Get LATEST chromedriver version for google-chrome
[2025-07-18T18:59:21.894+0000] {logger.py:11} INFO - Driver [/home/***/.wdm/drivers/chromedriver/linux64/138.0.7204.157/chromedriver-linux64/chromedriver] found in cache
[2025-07-18T18:59:44.585+0000] {scraper_banks.py:269} INFO - 
üìç Initialisation pour Casablanca...
[2025-07-18T18:59:56.863+0000] {process_utils.py:150} WARNING - process psutil.Process(pid=109, name='chromedriver', status='zombie', started='18:38:28') did not respond to SIGTERM. Trying SIGKILL
[2025-07-18T18:59:57.197+0000] {process_utils.py:150} WARNING - process psutil.Process(pid=399, name='chromedriver', status='zombie', started='18:44:39') did not respond to SIGTERM. Trying SIGKILL
[2025-07-18T18:59:57.220+0000] {process_utils.py:150} WARNING - process psutil.Process(pid=812, name='chromedriver', status='zombie', started='18:51:52') did not respond to SIGTERM. Trying SIGKILL
[2025-07-18T18:59:57.235+0000] {process_utils.py:150} WARNING - process psutil.Process(pid=76, name='airflow task ru', status='sleeping', started='18:38:02') did not respond to SIGTERM. Trying SIGKILL
[2025-07-18T18:59:57.261+0000] {process_utils.py:87} INFO - Sending the signal 9 to group 76
[2025-07-18T18:59:57.435+0000] {process_utils.py:80} INFO - Process psutil.Process(pid=399, name='chromedriver', status='terminated', started='18:44:39') (399) terminated with exit code None
[2025-07-18T18:59:57.439+0000] {process_utils.py:80} INFO - Process psutil.Process(pid=812, name='chromedriver', status='terminated', started='18:51:52') (812) terminated with exit code None
[2025-07-18T18:59:57.450+0000] {process_utils.py:80} INFO - Process psutil.Process(pid=76, name='airflow task ru', status='terminated', exitcode=<Negsignal.SIGKILL: -9>, started='18:38:02') (76) terminated with exit code -9
[2025-07-18T18:59:57.456+0000] {process_utils.py:80} INFO - Process psutil.Process(pid=109, name='chromedriver', status='terminated', started='18:38:28') (109) terminated with exit code None
[2025-07-18T18:59:57.470+0000] {standard_task_runner.py:190} ERROR - ('Job 124 was killed before it finished (likely due to running out of memory)', 'For more information, see https://***.apache.org/docs/apache-***/stable/troubleshooting.html#LocalTaskJob-killed')
