[2025-07-16T18:07:13.314+0000] {local_task_job_runner.py:123} INFO - ::group::Pre task execution logs
[2025-07-16T18:07:13.370+0000] {taskinstance.py:2614} INFO - Dependencies all met for dep_context=non-requeueable deps ti=<TaskInstance: bank_reviews_etl_and_analysis_pipeline.dbt_run_transactional scheduled__2025-06-08T00:00:00+00:00 [queued]>
[2025-07-16T18:07:13.397+0000] {taskinstance.py:2614} INFO - Dependencies all met for dep_context=requeueable deps ti=<TaskInstance: bank_reviews_etl_and_analysis_pipeline.dbt_run_transactional scheduled__2025-06-08T00:00:00+00:00 [queued]>
[2025-07-16T18:07:13.399+0000] {taskinstance.py:2867} INFO - Starting attempt 1 of 2
[2025-07-16T18:07:13.435+0000] {taskinstance.py:2890} INFO - Executing <Task(BashOperator): dbt_run_transactional> on 2025-06-08 00:00:00+00:00
[2025-07-16T18:07:13.455+0000] {standard_task_runner.py:72} INFO - Started process 983 to run task
[2025-07-16T18:07:13.463+0000] {standard_task_runner.py:104} INFO - Running: ['***', 'tasks', 'run', 'bank_reviews_etl_and_analysis_pipeline', 'dbt_run_transactional', 'scheduled__2025-06-08T00:00:00+00:00', '--job-id', '27', '--raw', '--subdir', 'DAGS_FOLDER/dag_load_reviews.py', '--cfg-path', '/tmp/tmp6ubg7976']
[2025-07-16T18:07:13.466+0000] {standard_task_runner.py:105} INFO - Job 27: Subtask dbt_run_transactional
[2025-07-16T18:07:13.571+0000] {task_command.py:467} INFO - Running <TaskInstance: bank_reviews_etl_and_analysis_pipeline.dbt_run_transactional scheduled__2025-06-08T00:00:00+00:00 [running]> on host 569ba507bc01
[2025-07-16T18:07:13.779+0000] {taskinstance.py:3134} INFO - Exporting env vars: AIRFLOW_CTX_DAG_OWNER='mohammed' AIRFLOW_CTX_DAG_ID='bank_reviews_etl_and_analysis_pipeline' AIRFLOW_CTX_TASK_ID='dbt_run_transactional' AIRFLOW_CTX_EXECUTION_DATE='2025-06-08T00:00:00+00:00' AIRFLOW_CTX_TRY_NUMBER='1' AIRFLOW_CTX_DAG_RUN_ID='scheduled__2025-06-08T00:00:00+00:00'
[2025-07-16T18:07:13.783+0000] {logging_mixin.py:190} INFO - Task instance is in running state
[2025-07-16T18:07:13.785+0000] {logging_mixin.py:190} INFO -  Previous state of the Task instance: queued
[2025-07-16T18:07:13.788+0000] {logging_mixin.py:190} INFO - Current task name:dbt_run_transactional state:running start_date:2025-07-16 18:07:13.373410+00:00
[2025-07-16T18:07:13.791+0000] {logging_mixin.py:190} INFO - Dag name:bank_reviews_etl_and_analysis_pipeline and current dag run status:running
[2025-07-16T18:07:13.793+0000] {taskinstance.py:732} INFO - ::endgroup::
[2025-07-16T18:07:13.798+0000] {subprocess.py:78} INFO - Tmp dir root location: /tmp
[2025-07-16T18:07:13.808+0000] {subprocess.py:88} INFO - Running command: ['/usr/bin/bash', '-c', 'cd /opt/.dbt/dbt_projects/bank_reviews_transactional && dbt run']
[2025-07-16T18:07:13.852+0000] {subprocess.py:99} INFO - Output:
[2025-07-16T18:07:21.270+0000] {subprocess.py:106} INFO - [0m18:07:21  Running with dbt=1.10.4
[2025-07-16T18:07:22.698+0000] {subprocess.py:106} INFO - [0m18:07:22  Registered adapter: postgres=1.9.0
[2025-07-16T18:07:23.898+0000] {subprocess.py:106} INFO - [0m18:07:23  Unable to do partial parsing because of a version mismatch
[2025-07-16T18:07:29.578+0000] {subprocess.py:106} INFO - [0m18:07:29  [[33mWARNING[0m]: Configuration paths exist in your dbt_project.yml file which do not apply to any resources.
[2025-07-16T18:07:29.581+0000] {subprocess.py:106} INFO - There are 1 unused configuration paths:
[2025-07-16T18:07:29.583+0000] {subprocess.py:106} INFO - - models.bank_reviews_transactional.transactional
[2025-07-16T18:07:30.234+0000] {subprocess.py:106} INFO - [0m18:07:30  Found 1 model, 1 source, 433 macros
[2025-07-16T18:07:30.251+0000] {subprocess.py:106} INFO - [0m18:07:30
[2025-07-16T18:07:30.255+0000] {subprocess.py:106} INFO - [0m18:07:30  Concurrency: 4 threads (target='dev')
[2025-07-16T18:07:30.258+0000] {subprocess.py:106} INFO - [0m18:07:30
[2025-07-16T18:07:45.170+0000] {job.py:239} ERROR - Job heartbeat failed with error
Traceback (most recent call last):
  File "/home/airflow/.local/lib/python3.11/site-packages/sqlalchemy/engine/base.py", line 3371, in _wrap_pool_connect
    return fn()
           ^^^^
  File "/home/airflow/.local/lib/python3.11/site-packages/sqlalchemy/pool/base.py", line 327, in connect
    return _ConnectionFairy._checkout(self)
           ^^^^^^^^^^^^^^^^^^^^^^^^^^^^^^^^
  File "/home/airflow/.local/lib/python3.11/site-packages/sqlalchemy/pool/base.py", line 894, in _checkout
    fairy = _ConnectionRecord.checkout(pool)
            ^^^^^^^^^^^^^^^^^^^^^^^^^^^^^^^^
  File "/home/airflow/.local/lib/python3.11/site-packages/sqlalchemy/pool/base.py", line 493, in checkout
    rec = pool._do_get()
          ^^^^^^^^^^^^^^
  File "/home/airflow/.local/lib/python3.11/site-packages/sqlalchemy/pool/impl.py", line 256, in _do_get
    return self._create_connection()
           ^^^^^^^^^^^^^^^^^^^^^^^^^
  File "/home/airflow/.local/lib/python3.11/site-packages/sqlalchemy/pool/base.py", line 273, in _create_connection
    return _ConnectionRecord(self)
           ^^^^^^^^^^^^^^^^^^^^^^^
  File "/home/airflow/.local/lib/python3.11/site-packages/sqlalchemy/pool/base.py", line 388, in __init__
    self.__connect()
  File "/home/airflow/.local/lib/python3.11/site-packages/sqlalchemy/pool/base.py", line 690, in __connect
    with util.safe_reraise():
  File "/home/airflow/.local/lib/python3.11/site-packages/sqlalchemy/util/langhelpers.py", line 70, in __exit__
    compat.raise_(
  File "/home/airflow/.local/lib/python3.11/site-packages/sqlalchemy/util/compat.py", line 211, in raise_
    raise exception
  File "/home/airflow/.local/lib/python3.11/site-packages/sqlalchemy/pool/base.py", line 686, in __connect
    self.dbapi_connection = connection = pool._invoke_creator(self)
                                         ^^^^^^^^^^^^^^^^^^^^^^^^^^
  File "/home/airflow/.local/lib/python3.11/site-packages/sqlalchemy/engine/create.py", line 574, in connect
    return dialect.connect(*cargs, **cparams)
           ^^^^^^^^^^^^^^^^^^^^^^^^^^^^^^^^^^
  File "/home/airflow/.local/lib/python3.11/site-packages/sqlalchemy/engine/default.py", line 598, in connect
    return self.dbapi.connect(*cargs, **cparams)
           ^^^^^^^^^^^^^^^^^^^^^^^^^^^^^^^^^^^^^
  File "/home/airflow/venv/lib/python3.11/site-packages/psycopg2/__init__.py", line 122, in connect
    conn = _connect(dsn, connection_factory=connection_factory, **kwasync)
           ^^^^^^^^^^^^^^^^^^^^^^^^^^^^^^^^^^^^^^^^^^^^^^^^^^^^^^^^^^^^^^^
psycopg2.OperationalError: could not translate host name "postgres" to address: Temporary failure in name resolution


The above exception was the direct cause of the following exception:

Traceback (most recent call last):
  File "/home/airflow/.local/lib/python3.11/site-packages/airflow/jobs/job.py", line 233, in heartbeat
    heartbeat_callback(session)
  File "/home/airflow/.local/lib/python3.11/site-packages/airflow/utils/session.py", line 94, in wrapper
    return func(*args, **kwargs)
           ^^^^^^^^^^^^^^^^^^^^^
  File "/home/airflow/.local/lib/python3.11/site-packages/airflow/jobs/local_task_job_runner.py", line 284, in heartbeat_callback
    self.task_instance.refresh_from_db()
  File "/home/airflow/.local/lib/python3.11/site-packages/airflow/utils/session.py", line 97, in wrapper
    return func(*args, session=session, **kwargs)
           ^^^^^^^^^^^^^^^^^^^^^^^^^^^^^^^^^^^^^^
  File "/home/airflow/.local/lib/python3.11/site-packages/airflow/models/taskinstance.py", line 2360, in refresh_from_db
    _refresh_from_db(task_instance=self, session=session, lock_for_update=lock_for_update)
  File "/home/airflow/.local/lib/python3.11/site-packages/airflow/models/taskinstance.py", line 873, in _refresh_from_db
    ti = TaskInstance.get_task_instance(
         ^^^^^^^^^^^^^^^^^^^^^^^^^^^^^^^
  File "/home/airflow/.local/lib/python3.11/site-packages/airflow/api_internal/internal_api_call.py", line 166, in wrapper
    return func(*args, **kwargs)
           ^^^^^^^^^^^^^^^^^^^^^
  File "/home/airflow/.local/lib/python3.11/site-packages/airflow/utils/session.py", line 94, in wrapper
    return func(*args, **kwargs)
           ^^^^^^^^^^^^^^^^^^^^^
  File "/home/airflow/.local/lib/python3.11/site-packages/airflow/models/taskinstance.py", line 2346, in get_task_instance
    return query.one_or_none()
           ^^^^^^^^^^^^^^^^^^^
  File "/home/airflow/.local/lib/python3.11/site-packages/sqlalchemy/orm/query.py", line 2850, in one_or_none
    return self._iter().one_or_none()
           ^^^^^^^^^^^^
  File "/home/airflow/.local/lib/python3.11/site-packages/sqlalchemy/orm/query.py", line 2916, in _iter
    result = self.session.execute(
             ^^^^^^^^^^^^^^^^^^^^^
  File "/home/airflow/.local/lib/python3.11/site-packages/sqlalchemy/orm/session.py", line 1716, in execute
    conn = self._connection_for_bind(bind)
           ^^^^^^^^^^^^^^^^^^^^^^^^^^^^^^^
  File "/home/airflow/.local/lib/python3.11/site-packages/sqlalchemy/orm/session.py", line 1555, in _connection_for_bind
    return self._transaction._connection_for_bind(
           ^^^^^^^^^^^^^^^^^^^^^^^^^^^^^^^^^^^^^^^
  File "/home/airflow/.local/lib/python3.11/site-packages/sqlalchemy/orm/session.py", line 750, in _connection_for_bind
    conn = bind.connect()
           ^^^^^^^^^^^^^^
  File "/home/airflow/.local/lib/python3.11/site-packages/sqlalchemy/future/engine.py", line 412, in connect
    return super(Engine, self).connect()
           ^^^^^^^^^^^^^^^^^^^^^^^^^^^^^
  File "/home/airflow/.local/lib/python3.11/site-packages/sqlalchemy/engine/base.py", line 3325, in connect
    return self._connection_cls(self, close_with_result=close_with_result)
           ^^^^^^^^^^^^^^^^^^^^^^^^^^^^^^^^^^^^^^^^^^^^^^^^^^^^^^^^^^^^^^^
  File "/home/airflow/.local/lib/python3.11/site-packages/sqlalchemy/engine/base.py", line 96, in __init__
    else engine.raw_connection()
         ^^^^^^^^^^^^^^^^^^^^^^^
  File "/home/airflow/.local/lib/python3.11/site-packages/sqlalchemy/engine/base.py", line 3404, in raw_connection
    return self._wrap_pool_connect(self.pool.connect, _connection)
           ^^^^^^^^^^^^^^^^^^^^^^^^^^^^^^^^^^^^^^^^^^^^^^^^^^^^^^^
  File "/home/airflow/.local/lib/python3.11/site-packages/sqlalchemy/engine/base.py", line 3374, in _wrap_pool_connect
    Connection._handle_dbapi_exception_noconnection(
  File "/home/airflow/.local/lib/python3.11/site-packages/sqlalchemy/engine/base.py", line 2208, in _handle_dbapi_exception_noconnection
    util.raise_(
  File "/home/airflow/.local/lib/python3.11/site-packages/sqlalchemy/util/compat.py", line 211, in raise_
    raise exception
  File "/home/airflow/.local/lib/python3.11/site-packages/sqlalchemy/engine/base.py", line 3371, in _wrap_pool_connect
    return fn()
           ^^^^
  File "/home/airflow/.local/lib/python3.11/site-packages/sqlalchemy/pool/base.py", line 327, in connect
    return _ConnectionFairy._checkout(self)
           ^^^^^^^^^^^^^^^^^^^^^^^^^^^^^^^^
  File "/home/airflow/.local/lib/python3.11/site-packages/sqlalchemy/pool/base.py", line 894, in _checkout
    fairy = _ConnectionRecord.checkout(pool)
            ^^^^^^^^^^^^^^^^^^^^^^^^^^^^^^^^
  File "/home/airflow/.local/lib/python3.11/site-packages/sqlalchemy/pool/base.py", line 493, in checkout
    rec = pool._do_get()
          ^^^^^^^^^^^^^^
  File "/home/airflow/.local/lib/python3.11/site-packages/sqlalchemy/pool/impl.py", line 256, in _do_get
    return self._create_connection()
           ^^^^^^^^^^^^^^^^^^^^^^^^^
  File "/home/airflow/.local/lib/python3.11/site-packages/sqlalchemy/pool/base.py", line 273, in _create_connection
    return _ConnectionRecord(self)
           ^^^^^^^^^^^^^^^^^^^^^^^
  File "/home/airflow/.local/lib/python3.11/site-packages/sqlalchemy/pool/base.py", line 388, in __init__
    self.__connect()
  File "/home/airflow/.local/lib/python3.11/site-packages/sqlalchemy/pool/base.py", line 690, in __connect
    with util.safe_reraise():
  File "/home/airflow/.local/lib/python3.11/site-packages/sqlalchemy/util/langhelpers.py", line 70, in __exit__
    compat.raise_(
  File "/home/airflow/.local/lib/python3.11/site-packages/sqlalchemy/util/compat.py", line 211, in raise_
    raise exception
  File "/home/airflow/.local/lib/python3.11/site-packages/sqlalchemy/pool/base.py", line 686, in __connect
    self.dbapi_connection = connection = pool._invoke_creator(self)
                                         ^^^^^^^^^^^^^^^^^^^^^^^^^^
  File "/home/airflow/.local/lib/python3.11/site-packages/sqlalchemy/engine/create.py", line 574, in connect
    return dialect.connect(*cargs, **cparams)
           ^^^^^^^^^^^^^^^^^^^^^^^^^^^^^^^^^^
  File "/home/airflow/.local/lib/python3.11/site-packages/sqlalchemy/engine/default.py", line 598, in connect
    return self.dbapi.connect(*cargs, **cparams)
           ^^^^^^^^^^^^^^^^^^^^^^^^^^^^^^^^^^^^^
  File "/home/airflow/venv/lib/python3.11/site-packages/psycopg2/__init__.py", line 122, in connect
    conn = _connect(dsn, connection_factory=connection_factory, **kwasync)
           ^^^^^^^^^^^^^^^^^^^^^^^^^^^^^^^^^^^^^^^^^^^^^^^^^^^^^^^^^^^^^^^
sqlalchemy.exc.OperationalError: (psycopg2.OperationalError) could not translate host name "postgres" to address: Temporary failure in name resolution

(Background on this error at: https://sqlalche.me/e/14/e3q8)
[2025-07-16T18:08:11.529+0000] {job.py:254} ERROR - Job heartbeat failed with error. Scheduler is in unhealthy state
[2025-07-16T18:08:16.560+0000] {job.py:229} INFO - Heartbeat recovered after 47.28 seconds
[2025-07-16T18:08:17.641+0000] {subprocess.py:106} INFO - [0m18:08:17  1 of 1 START sql table model transactional.clean_reviews ....................... [RUN]
[2025-07-16T18:08:23.783+0000] {subprocess.py:106} INFO - [0m18:08:23  1 of 1 OK created sql table model transactional.clean_reviews .................. [[32mSELECT 10613[0m in 6.11s]
[2025-07-16T18:08:26.265+0000] {subprocess.py:106} INFO - [0m18:08:26
[2025-07-16T18:08:26.293+0000] {subprocess.py:106} INFO - [0m18:08:26  Finished running 1 table model in 0 hours 0 minutes and 56.00 seconds (56.00s).
[2025-07-16T18:08:26.698+0000] {subprocess.py:106} INFO - [0m18:08:26
[2025-07-16T18:08:26.704+0000] {subprocess.py:106} INFO - [0m18:08:26  [32mCompleted successfully[0m
[2025-07-16T18:08:26.707+0000] {subprocess.py:106} INFO - [0m18:08:26
[2025-07-16T18:08:26.719+0000] {subprocess.py:106} INFO - [0m18:08:26  Done. PASS=1 WARN=0 ERROR=0 SKIP=0 NO-OP=0 TOTAL=1
[2025-07-16T18:08:28.766+0000] {subprocess.py:110} INFO - Command exited with return code 0
[2025-07-16T18:08:28.934+0000] {taskinstance.py:341} INFO - ::group::Post task execution logs
[2025-07-16T18:08:28.939+0000] {taskinstance.py:353} INFO - Marking task as SUCCESS. dag_id=bank_reviews_etl_and_analysis_pipeline, task_id=dbt_run_transactional, run_id=scheduled__2025-06-08T00:00:00+00:00, execution_date=20250608T000000, start_date=20250716T180713, end_date=20250716T180828
[2025-07-16T18:08:29.089+0000] {logging_mixin.py:190} INFO - Task instance in success state
[2025-07-16T18:08:29.104+0000] {logging_mixin.py:190} INFO -  Previous state of the Task instance: running
[2025-07-16T18:08:29.110+0000] {logging_mixin.py:190} INFO - Dag name:bank_reviews_etl_and_analysis_pipeline queued_at:2025-07-16 17:28:09.980560+00:00
[2025-07-16T18:08:29.120+0000] {logging_mixin.py:190} INFO - Task hostname:569ba507bc01 operator:BashOperator
[2025-07-16T18:08:29.223+0000] {local_task_job_runner.py:266} INFO - Task exited with return code 0
[2025-07-16T18:08:29.379+0000] {taskinstance.py:3901} INFO - 1 downstream tasks scheduled from follow-on schedule check
[2025-07-16T18:08:29.392+0000] {local_task_job_runner.py:245} INFO - ::endgroup::
