[2025-07-16T19:33:44.044+0000] {local_task_job_runner.py:123} INFO - ::group::Pre task execution logs
[2025-07-16T19:33:44.439+0000] {taskinstance.py:2614} INFO - Dependencies all met for dep_context=non-requeueable deps ti=<TaskInstance: bank_reviews_etl_and_analysis_pipeline.dbt_run_transactional manual__2025-07-16T19:04:56.908458+00:00 [queued]>
[2025-07-16T19:33:44.460+0000] {taskinstance.py:2614} INFO - Dependencies all met for dep_context=requeueable deps ti=<TaskInstance: bank_reviews_etl_and_analysis_pipeline.dbt_run_transactional manual__2025-07-16T19:04:56.908458+00:00 [queued]>
[2025-07-16T19:33:44.462+0000] {taskinstance.py:2867} INFO - Starting attempt 1 of 2
[2025-07-16T19:33:44.977+0000] {taskinstance.py:2890} INFO - Executing <Task(BashOperator): dbt_run_transactional> on 2025-07-16 19:04:56.908458+00:00
[2025-07-16T19:33:45.177+0000] {standard_task_runner.py:72} INFO - Started process 862 to run task
[2025-07-16T19:33:45.186+0000] {standard_task_runner.py:104} INFO - Running: ['***', 'tasks', 'run', 'bank_reviews_etl_and_analysis_pipeline', 'dbt_run_transactional', 'manual__2025-07-16T19:04:56.908458+00:00', '--job-id', '43', '--raw', '--subdir', 'DAGS_FOLDER/dag_load_reviews.py', '--cfg-path', '/tmp/tmpayw_bvw0']
[2025-07-16T19:33:45.190+0000] {standard_task_runner.py:105} INFO - Job 43: Subtask dbt_run_transactional
[2025-07-16T19:33:45.608+0000] {task_command.py:467} INFO - Running <TaskInstance: bank_reviews_etl_and_analysis_pipeline.dbt_run_transactional manual__2025-07-16T19:04:56.908458+00:00 [running]> on host 569ba507bc01
[2025-07-16T19:33:49.561+0000] {taskinstance.py:3134} INFO - Exporting env vars: AIRFLOW_CTX_DAG_OWNER='mohammed' AIRFLOW_CTX_DAG_ID='bank_reviews_etl_and_analysis_pipeline' AIRFLOW_CTX_TASK_ID='dbt_run_transactional' AIRFLOW_CTX_EXECUTION_DATE='2025-07-16T19:04:56.908458+00:00' AIRFLOW_CTX_TRY_NUMBER='1' AIRFLOW_CTX_DAG_RUN_ID='manual__2025-07-16T19:04:56.908458+00:00'
[2025-07-16T19:33:49.583+0000] {logging_mixin.py:190} INFO - Task instance is in running state
[2025-07-16T19:33:49.586+0000] {logging_mixin.py:190} INFO -  Previous state of the Task instance: queued
[2025-07-16T19:33:49.589+0000] {logging_mixin.py:190} INFO - Current task name:dbt_run_transactional state:running start_date:2025-07-16 19:33:44.441666+00:00
[2025-07-16T19:33:49.592+0000] {logging_mixin.py:190} INFO - Dag name:bank_reviews_etl_and_analysis_pipeline and current dag run status:running
[2025-07-16T19:33:49.594+0000] {taskinstance.py:732} INFO - ::endgroup::
[2025-07-16T19:33:49.601+0000] {subprocess.py:78} INFO - Tmp dir root location: /tmp
[2025-07-16T19:33:49.609+0000] {subprocess.py:88} INFO - Running command: ['/usr/bin/bash', '-c', 'cd /opt/.dbt/dbt_projects/bank_reviews_transactional && dbt run']
[2025-07-16T19:33:49.709+0000] {subprocess.py:99} INFO - Output:
[2025-07-16T19:34:01.481+0000] {subprocess.py:106} INFO - [0m19:34:01  Running with dbt=1.10.4
[2025-07-16T19:34:02.670+0000] {subprocess.py:106} INFO - [0m19:34:02  Registered adapter: postgres=1.9.0
[2025-07-16T19:34:04.017+0000] {subprocess.py:106} INFO - [0m19:34:04  [[33mWARNING[0m]: Configuration paths exist in your dbt_project.yml file which do not apply to any resources.
[2025-07-16T19:34:04.021+0000] {subprocess.py:106} INFO - There are 1 unused configuration paths:
[2025-07-16T19:34:04.024+0000] {subprocess.py:106} INFO - - models.bank_reviews_transactional.transactional
[2025-07-16T19:34:04.632+0000] {subprocess.py:106} INFO - [0m19:34:04  Found 1 model, 1 source, 433 macros
[2025-07-16T19:34:04.648+0000] {subprocess.py:106} INFO - [0m19:34:04
[2025-07-16T19:34:04.658+0000] {subprocess.py:106} INFO - [0m19:34:04  Concurrency: 4 threads (target='dev')
[2025-07-16T19:34:04.663+0000] {subprocess.py:106} INFO - [0m19:34:04
[2025-07-16T19:34:04.970+0000] {subprocess.py:106} INFO - [0m19:34:04
[2025-07-16T19:34:04.974+0000] {subprocess.py:106} INFO - [0m19:34:04  Finished running  in 0 hours 0 minutes and 0.30 seconds (0.30s).
[2025-07-16T19:34:04.980+0000] {subprocess.py:106} INFO - [0m19:34:04  Encountered an error:
[2025-07-16T19:34:04.985+0000] {subprocess.py:106} INFO - Database Error
[2025-07-16T19:34:04.988+0000] {subprocess.py:106} INFO -   could not translate host name "pg-365fb9de-mmohxx20-ac9b.j.aivencloud.com" to address: Name or service not known
[2025-07-16T19:34:04.991+0000] {subprocess.py:106} INFO - 
[2025-07-16T19:34:05.904+0000] {subprocess.py:110} INFO - Command exited with return code 2
[2025-07-16T19:34:05.932+0000] {taskinstance.py:3313} ERROR - Task failed with exception
Traceback (most recent call last):
  File "/home/airflow/.local/lib/python3.11/site-packages/airflow/models/taskinstance.py", line 768, in _execute_task
    result = _execute_callable(context=context, **execute_callable_kwargs)
             ^^^^^^^^^^^^^^^^^^^^^^^^^^^^^^^^^^^^^^^^^^^^^^^^^^^^^^^^^^^^^
  File "/home/airflow/.local/lib/python3.11/site-packages/airflow/models/taskinstance.py", line 734, in _execute_callable
    return ExecutionCallableRunner(
           ^^^^^^^^^^^^^^^^^^^^^^^^
  File "/home/airflow/.local/lib/python3.11/site-packages/airflow/utils/operator_helpers.py", line 252, in run
    return self.func(*args, **kwargs)
           ^^^^^^^^^^^^^^^^^^^^^^^^^^
  File "/home/airflow/.local/lib/python3.11/site-packages/airflow/models/baseoperator.py", line 424, in wrapper
    return func(self, *args, **kwargs)
           ^^^^^^^^^^^^^^^^^^^^^^^^^^^
  File "/home/airflow/.local/lib/python3.11/site-packages/airflow/operators/bash.py", line 276, in execute
    raise AirflowException(
airflow.exceptions.AirflowException: Bash command failed. The command returned a non-zero exit code 2.
[2025-07-16T19:34:05.957+0000] {logging_mixin.py:190} INFO - Task instance in failure state
[2025-07-16T19:34:05.960+0000] {logging_mixin.py:190} INFO - Task start:2025-07-16 19:33:44.441666+00:00 end:2025-07-16 19:34:05.955972+00:00 duration:21.514306
[2025-07-16T19:34:05.963+0000] {logging_mixin.py:190} INFO - Task:<Task(BashOperator): dbt_run_transactional> dag:<DAG: bank_reviews_etl_and_analysis_pipeline> dagrun:<DagRun bank_reviews_etl_and_analysis_pipeline @ 2025-07-16 19:04:56.908458+00:00: manual__2025-07-16T19:04:56.908458+00:00, state:running, queued_at: 2025-07-16 19:04:57.102792+00:00. externally triggered: True>
[2025-07-16T19:34:05.965+0000] {logging_mixin.py:190} INFO - Failure caused by Bash command failed. The command returned a non-zero exit code 2.
[2025-07-16T19:34:05.967+0000] {taskinstance.py:1226} INFO - Marking task as UP_FOR_RETRY. dag_id=bank_reviews_etl_and_analysis_pipeline, task_id=dbt_run_transactional, run_id=manual__2025-07-16T19:04:56.908458+00:00, execution_date=20250716T190456, start_date=20250716T193344, end_date=20250716T193405
[2025-07-16T19:34:06.048+0000] {taskinstance.py:341} INFO - ::group::Post task execution logs
[2025-07-16T19:34:06.050+0000] {standard_task_runner.py:124} ERROR - Failed to execute job 43 for task dbt_run_transactional (Bash command failed. The command returned a non-zero exit code 2.; 862)
Traceback (most recent call last):
  File "/home/airflow/.local/lib/python3.11/site-packages/airflow/task/task_runner/standard_task_runner.py", line 117, in _start_by_fork
    ret = args.func(args, dag=self.dag)
          ^^^^^^^^^^^^^^^^^^^^^^^^^^^^^
  File "/home/airflow/.local/lib/python3.11/site-packages/airflow/cli/cli_config.py", line 49, in command
    return func(*args, **kwargs)
           ^^^^^^^^^^^^^^^^^^^^^
  File "/home/airflow/.local/lib/python3.11/site-packages/airflow/utils/cli.py", line 116, in wrapper
    return f(*args, **kwargs)
           ^^^^^^^^^^^^^^^^^^
  File "/home/airflow/.local/lib/python3.11/site-packages/airflow/cli/commands/task_command.py", line 483, in task_run
    task_return_code = _run_task_by_selected_method(args, _dag, ti)
                       ^^^^^^^^^^^^^^^^^^^^^^^^^^^^^^^^^^^^^^^^^^^^
  File "/home/airflow/.local/lib/python3.11/site-packages/airflow/cli/commands/task_command.py", line 256, in _run_task_by_selected_method
    return _run_raw_task(args, ti)
           ^^^^^^^^^^^^^^^^^^^^^^^
  File "/home/airflow/.local/lib/python3.11/site-packages/airflow/cli/commands/task_command.py", line 341, in _run_raw_task
    return ti._run_raw_task(
           ^^^^^^^^^^^^^^^^^
  File "/home/airflow/.local/lib/python3.11/site-packages/airflow/utils/session.py", line 97, in wrapper
    return func(*args, session=session, **kwargs)
           ^^^^^^^^^^^^^^^^^^^^^^^^^^^^^^^^^^^^^^
  File "/home/airflow/.local/lib/python3.11/site-packages/airflow/models/taskinstance.py", line 3006, in _run_raw_task
    return _run_raw_task(
           ^^^^^^^^^^^^^^
  File "/home/airflow/.local/lib/python3.11/site-packages/airflow/models/taskinstance.py", line 274, in _run_raw_task
    TaskInstance._execute_task_with_callbacks(
  File "/home/airflow/.local/lib/python3.11/site-packages/airflow/models/taskinstance.py", line 3161, in _execute_task_with_callbacks
    result = self._execute_task(context, task_orig)
             ^^^^^^^^^^^^^^^^^^^^^^^^^^^^^^^^^^^^^^
  File "/home/airflow/.local/lib/python3.11/site-packages/airflow/models/taskinstance.py", line 3185, in _execute_task
    return _execute_task(self, context, task_orig)
           ^^^^^^^^^^^^^^^^^^^^^^^^^^^^^^^^^^^^^^^
  File "/home/airflow/.local/lib/python3.11/site-packages/airflow/models/taskinstance.py", line 768, in _execute_task
    result = _execute_callable(context=context, **execute_callable_kwargs)
             ^^^^^^^^^^^^^^^^^^^^^^^^^^^^^^^^^^^^^^^^^^^^^^^^^^^^^^^^^^^^^
  File "/home/airflow/.local/lib/python3.11/site-packages/airflow/models/taskinstance.py", line 734, in _execute_callable
    return ExecutionCallableRunner(
           ^^^^^^^^^^^^^^^^^^^^^^^^
  File "/home/airflow/.local/lib/python3.11/site-packages/airflow/utils/operator_helpers.py", line 252, in run
    return self.func(*args, **kwargs)
           ^^^^^^^^^^^^^^^^^^^^^^^^^^
  File "/home/airflow/.local/lib/python3.11/site-packages/airflow/models/baseoperator.py", line 424, in wrapper
    return func(self, *args, **kwargs)
           ^^^^^^^^^^^^^^^^^^^^^^^^^^^
  File "/home/airflow/.local/lib/python3.11/site-packages/airflow/operators/bash.py", line 276, in execute
    raise AirflowException(
airflow.exceptions.AirflowException: Bash command failed. The command returned a non-zero exit code 2.
[2025-07-16T19:34:06.103+0000] {local_task_job_runner.py:266} INFO - Task exited with return code 1
[2025-07-16T19:34:06.180+0000] {taskinstance.py:3901} INFO - 0 downstream tasks scheduled from follow-on schedule check
[2025-07-16T19:34:06.189+0000] {local_task_job_runner.py:245} INFO - ::endgroup::
