[2025-07-17T10:46:57.423+0000] {local_task_job_runner.py:123} INFO - ::group::Pre task execution logs
[2025-07-17T10:46:57.817+0000] {taskinstance.py:2614} INFO - Dependencies all met for dep_context=non-requeueable deps ti=<TaskInstance: bank_reviews_etl_and_analysis_pipeline.convertir_date_relative manual__2025-07-17T00:17:54.106541+00:00 [queued]>
[2025-07-17T10:46:57.851+0000] {taskinstance.py:2614} INFO - Dependencies all met for dep_context=requeueable deps ti=<TaskInstance: bank_reviews_etl_and_analysis_pipeline.convertir_date_relative manual__2025-07-17T00:17:54.106541+00:00 [queued]>
[2025-07-17T10:46:57.856+0000] {taskinstance.py:2867} INFO - Starting attempt 2 of 2
[2025-07-17T10:46:57.907+0000] {taskinstance.py:2890} INFO - Executing <Task(BashOperator): convertir_date_relative> on 2025-07-17 00:17:54.106541+00:00
[2025-07-17T10:46:57.931+0000] {standard_task_runner.py:72} INFO - Started process 1024 to run task
[2025-07-17T10:46:57.940+0000] {standard_task_runner.py:104} INFO - Running: ['***', 'tasks', 'run', 'bank_reviews_etl_and_analysis_pipeline', 'convertir_date_relative', 'manual__2025-07-17T00:17:54.106541+00:00', '--job-id', '55', '--raw', '--subdir', 'DAGS_FOLDER/dag_load_reviews.py', '--cfg-path', '/tmp/tmpq_0kmrsg']
[2025-07-17T10:46:57.948+0000] {standard_task_runner.py:105} INFO - Job 55: Subtask convertir_date_relative
[2025-07-17T10:46:58.105+0000] {task_command.py:467} INFO - Running <TaskInstance: bank_reviews_etl_and_analysis_pipeline.convertir_date_relative manual__2025-07-17T00:17:54.106541+00:00 [running]> on host 569ba507bc01
[2025-07-17T10:46:58.704+0000] {taskinstance.py:3134} INFO - Exporting env vars: AIRFLOW_CTX_DAG_OWNER='mohammed' AIRFLOW_CTX_DAG_ID='bank_reviews_etl_and_analysis_pipeline' AIRFLOW_CTX_TASK_ID='convertir_date_relative' AIRFLOW_CTX_EXECUTION_DATE='2025-07-17T00:17:54.106541+00:00' AIRFLOW_CTX_TRY_NUMBER='2' AIRFLOW_CTX_DAG_RUN_ID='manual__2025-07-17T00:17:54.106541+00:00'
[2025-07-17T10:46:58.715+0000] {logging_mixin.py:190} INFO - Task instance is in running state
[2025-07-17T10:46:58.721+0000] {logging_mixin.py:190} INFO -  Previous state of the Task instance: queued
[2025-07-17T10:46:58.726+0000] {logging_mixin.py:190} INFO - Current task name:convertir_date_relative state:running start_date:2025-07-17 10:46:57.821464+00:00
[2025-07-17T10:46:58.732+0000] {logging_mixin.py:190} INFO - Dag name:bank_reviews_etl_and_analysis_pipeline and current dag run status:running
[2025-07-17T10:46:58.738+0000] {taskinstance.py:732} INFO - ::endgroup::
[2025-07-17T10:46:58.747+0000] {subprocess.py:78} INFO - Tmp dir root location: /tmp
[2025-07-17T10:46:58.773+0000] {subprocess.py:88} INFO - Running command: ['/usr/bin/bash', '-c', 'python3 /opt/***/scripts/convertir_date_relative.py']
[2025-07-17T10:46:58.849+0000] {subprocess.py:99} INFO - Output:
[2025-07-17T10:46:59.328+0000] {subprocess.py:106} INFO - ❌ Échec de la connexion : connection to server at "localhost" (::1), port 5432 failed: Connection refused
[2025-07-17T10:46:59.330+0000] {subprocess.py:106} INFO - 	Is the server running on that host and accepting TCP/IP connections?
[2025-07-17T10:46:59.332+0000] {subprocess.py:106} INFO - connection to server at "localhost" (127.0.0.1), port 5432 failed: Connection refused
[2025-07-17T10:46:59.335+0000] {subprocess.py:106} INFO - 	Is the server running on that host and accepting TCP/IP connections?
[2025-07-17T10:46:59.337+0000] {subprocess.py:106} INFO - 
[2025-07-17T10:46:59.340+0000] {subprocess.py:106} INFO - ❌ Erreur : Échec de la connexion à la base de données.
[2025-07-17T10:46:59.343+0000] {subprocess.py:106} INFO - Traceback (most recent call last):
[2025-07-17T10:46:59.346+0000] {subprocess.py:106} INFO -   File "/opt/***/scripts/convertir_date_relative.py", line 143, in <module>
[2025-07-17T10:46:59.348+0000] {subprocess.py:106} INFO -     if cur:
[2025-07-17T10:46:59.351+0000] {subprocess.py:106} INFO -        ^^^
[2025-07-17T10:46:59.353+0000] {subprocess.py:106} INFO - NameError: name 'cur' is not defined. Did you mean: 'chr'?
[2025-07-17T10:46:59.373+0000] {subprocess.py:110} INFO - Command exited with return code 1
[2025-07-17T10:46:59.405+0000] {taskinstance.py:3313} ERROR - Task failed with exception
Traceback (most recent call last):
  File "/home/airflow/.local/lib/python3.11/site-packages/airflow/models/taskinstance.py", line 768, in _execute_task
    result = _execute_callable(context=context, **execute_callable_kwargs)
             ^^^^^^^^^^^^^^^^^^^^^^^^^^^^^^^^^^^^^^^^^^^^^^^^^^^^^^^^^^^^^
  File "/home/airflow/.local/lib/python3.11/site-packages/airflow/models/taskinstance.py", line 734, in _execute_callable
    return ExecutionCallableRunner(
           ^^^^^^^^^^^^^^^^^^^^^^^^
  File "/home/airflow/.local/lib/python3.11/site-packages/airflow/utils/operator_helpers.py", line 252, in run
    return self.func(*args, **kwargs)
           ^^^^^^^^^^^^^^^^^^^^^^^^^^
  File "/home/airflow/.local/lib/python3.11/site-packages/airflow/models/baseoperator.py", line 424, in wrapper
    return func(self, *args, **kwargs)
           ^^^^^^^^^^^^^^^^^^^^^^^^^^^
  File "/home/airflow/.local/lib/python3.11/site-packages/airflow/operators/bash.py", line 276, in execute
    raise AirflowException(
airflow.exceptions.AirflowException: Bash command failed. The command returned a non-zero exit code 1.
[2025-07-17T10:46:59.430+0000] {logging_mixin.py:190} INFO - Task instance in failure state
[2025-07-17T10:46:59.432+0000] {logging_mixin.py:190} INFO - Task start:2025-07-17 10:46:57.821464+00:00 end:2025-07-17 10:46:59.428856+00:00 duration:1.607392
[2025-07-17T10:46:59.435+0000] {logging_mixin.py:190} INFO - Task:<Task(BashOperator): convertir_date_relative> dag:<DAG: bank_reviews_etl_and_analysis_pipeline> dagrun:<DagRun bank_reviews_etl_and_analysis_pipeline @ 2025-07-17 00:17:54.106541+00:00: manual__2025-07-17T00:17:54.106541+00:00, state:running, queued_at: 2025-07-17 00:17:54.887499+00:00. externally triggered: True>
[2025-07-17T10:46:59.437+0000] {logging_mixin.py:190} INFO - Failure caused by Bash command failed. The command returned a non-zero exit code 1.
[2025-07-17T10:46:59.439+0000] {taskinstance.py:1226} INFO - Marking task as FAILED. dag_id=bank_reviews_etl_and_analysis_pipeline, task_id=convertir_date_relative, run_id=manual__2025-07-17T00:17:54.106541+00:00, execution_date=20250717T001754, start_date=20250717T104657, end_date=20250717T104659
[2025-07-17T10:46:59.550+0000] {taskinstance.py:341} INFO - ::group::Post task execution logs
[2025-07-17T10:46:59.553+0000] {standard_task_runner.py:124} ERROR - Failed to execute job 55 for task convertir_date_relative (Bash command failed. The command returned a non-zero exit code 1.; 1024)
Traceback (most recent call last):
  File "/home/airflow/.local/lib/python3.11/site-packages/airflow/task/task_runner/standard_task_runner.py", line 117, in _start_by_fork
    ret = args.func(args, dag=self.dag)
          ^^^^^^^^^^^^^^^^^^^^^^^^^^^^^
  File "/home/airflow/.local/lib/python3.11/site-packages/airflow/cli/cli_config.py", line 49, in command
    return func(*args, **kwargs)
           ^^^^^^^^^^^^^^^^^^^^^
  File "/home/airflow/.local/lib/python3.11/site-packages/airflow/utils/cli.py", line 116, in wrapper
    return f(*args, **kwargs)
           ^^^^^^^^^^^^^^^^^^
  File "/home/airflow/.local/lib/python3.11/site-packages/airflow/cli/commands/task_command.py", line 483, in task_run
    task_return_code = _run_task_by_selected_method(args, _dag, ti)
                       ^^^^^^^^^^^^^^^^^^^^^^^^^^^^^^^^^^^^^^^^^^^^
  File "/home/airflow/.local/lib/python3.11/site-packages/airflow/cli/commands/task_command.py", line 256, in _run_task_by_selected_method
    return _run_raw_task(args, ti)
           ^^^^^^^^^^^^^^^^^^^^^^^
  File "/home/airflow/.local/lib/python3.11/site-packages/airflow/cli/commands/task_command.py", line 341, in _run_raw_task
    return ti._run_raw_task(
           ^^^^^^^^^^^^^^^^^
  File "/home/airflow/.local/lib/python3.11/site-packages/airflow/utils/session.py", line 97, in wrapper
    return func(*args, session=session, **kwargs)
           ^^^^^^^^^^^^^^^^^^^^^^^^^^^^^^^^^^^^^^
  File "/home/airflow/.local/lib/python3.11/site-packages/airflow/models/taskinstance.py", line 3006, in _run_raw_task
    return _run_raw_task(
           ^^^^^^^^^^^^^^
  File "/home/airflow/.local/lib/python3.11/site-packages/airflow/models/taskinstance.py", line 274, in _run_raw_task
    TaskInstance._execute_task_with_callbacks(
  File "/home/airflow/.local/lib/python3.11/site-packages/airflow/models/taskinstance.py", line 3161, in _execute_task_with_callbacks
    result = self._execute_task(context, task_orig)
             ^^^^^^^^^^^^^^^^^^^^^^^^^^^^^^^^^^^^^^
  File "/home/airflow/.local/lib/python3.11/site-packages/airflow/models/taskinstance.py", line 3185, in _execute_task
    return _execute_task(self, context, task_orig)
           ^^^^^^^^^^^^^^^^^^^^^^^^^^^^^^^^^^^^^^^
  File "/home/airflow/.local/lib/python3.11/site-packages/airflow/models/taskinstance.py", line 768, in _execute_task
    result = _execute_callable(context=context, **execute_callable_kwargs)
             ^^^^^^^^^^^^^^^^^^^^^^^^^^^^^^^^^^^^^^^^^^^^^^^^^^^^^^^^^^^^^
  File "/home/airflow/.local/lib/python3.11/site-packages/airflow/models/taskinstance.py", line 734, in _execute_callable
    return ExecutionCallableRunner(
           ^^^^^^^^^^^^^^^^^^^^^^^^
  File "/home/airflow/.local/lib/python3.11/site-packages/airflow/utils/operator_helpers.py", line 252, in run
    return self.func(*args, **kwargs)
           ^^^^^^^^^^^^^^^^^^^^^^^^^^
  File "/home/airflow/.local/lib/python3.11/site-packages/airflow/models/baseoperator.py", line 424, in wrapper
    return func(self, *args, **kwargs)
           ^^^^^^^^^^^^^^^^^^^^^^^^^^^
  File "/home/airflow/.local/lib/python3.11/site-packages/airflow/operators/bash.py", line 276, in execute
    raise AirflowException(
airflow.exceptions.AirflowException: Bash command failed. The command returned a non-zero exit code 1.
[2025-07-17T10:46:59.640+0000] {local_task_job_runner.py:266} INFO - Task exited with return code 1
[2025-07-17T10:46:59.733+0000] {taskinstance.py:3901} INFO - 0 downstream tasks scheduled from follow-on schedule check
[2025-07-17T10:46:59.758+0000] {local_task_job_runner.py:245} INFO - ::endgroup::
